File: MvsH/2021-10-25_EROI_34P8MG_MVSH_60P0K.DAT
Time Stamp (sec),Temperature (K),Magnetic Field (Oe),Moment (emu),M. Std. Err. (emu)
3844471374.843,59.9300667173524,0.24889200925827,,
3844471470.8685,59.9604625701904,-4849.3046875,-0.06282628815691,2.04529537015051E-5
3844471490.905,59.9635543823242,-4548.61254882812,-0.0589263211782697,2.07570315147351E-5
3844471510.841,59.9672241210937,-4249.57202148438,-0.0550422111459076,1.99505248352957E-5
3844471530.8475,59.9700946807861,-3949.90087890625,-0.0511628351972694,2.0760323452096E-5
3844471550.9475,59.9745903015137,-3648.00207519531,-0.0472896512433746,1.99738651126939E-5
3844471570.947,59.976167678833,-3348.10998535156,-0.0434133379102979,2.01669095293933E-5
3844471590.831,59.9782733917236,-3050.24291992188,-0.0395271478328028,2.01061114835669E-5
3844471610.78,59.9815063476563,-2750.42468261719,-0.0356624450141624,2.04328173713009E-5
3844471630.7605,59.9832096099854,-2451.08374023438,-0.0317922618445728,2.04540774822348E-5
3844471650.7445,59.9843425750732,-2152.07983398438,-0.0279222205891763,1.9793562520685E-5
3844471670.7215,59.9861564636231,-1851.91333007813,-0.0240572908317875,1.98749745718859E-5
3844471690.7285,59.9875946044922,-1551.99310302734,-0.0201881893609482,1.97526381824011E-5
3844471710.803,59.9890003204346,-1251.06530761719,-0.016333135114599,1.96723416599778E-5
3844471730.6945,59.9894981384277,-952.736999511719,-0.012476159376894,1.97154192766553E-5
3844471750.738,59.9903430938721,-652.993438720703,-0.00861528453766581,1.97286780317977E-5
3844471770.6955,59.9922161102295,-353.725036621094,-0.00475362262723174,1.9751252145033E-5
3844471795.69,59.9922199249268,21.7728743553162,7.78104328071254E-5,1.77452156557549E-5
3844471815.6835,59.993537902832,320.821716308594,0.00394983727252321,1.97598357664225E-5
3844471835.644,59.9939041137695,620.930541992188,0.00782164294682378,1.98155130064226E-5
3844471860.8795,59.9941711425781,999.567321777344,0.0126647956688003,1.98406604021983E-5
3844471880.5795,59.9951305389404,1294.77410888672,0.0165324790185468,1.97266238832868E-5
3844471900.647,59.9961357116699,1595.09918212891,0.0203995107823841,1.97397035699145E-5
3844471920.541,59.9973182678223,1893.52368164062,0.0242720266377275,1.96802646046558E-5
3844471940.69,59.9961814880371,2195.25476074219,0.0281505647683473,1.9917571790625E-5
3844471960.556,59.9971656799316,2493.61364746094,0.0320172063169795,2.01349169912293E-5
3844471980.506,59.9980926513672,2792.90490722656,0.0358887432416614,2.03804336980592E-5
3844472000.499,59.9973392486572,3093.44580078125,0.0397522228697132,2.02683669147567E-5
3844472020.476,59.9981307983398,3392.90490722656,0.0436125706865227,2.03954230952023E-5
3844472040.445,59.9979438781738,3692.02783203125,0.0474788210279133,1.99627229624778E-5
3844472060.51,59.9988307952881,3993.18273925781,0.0513333172990819,2.0448604071255E-5
3844472080.5265,59.9982795715332,4293.07763671875,0.0551872765543721,1.98832855559307E-5
3844472100.484,59.9983501434326,4592.580078125,0.0590542927667187,2.00542678934186E-5
3844472120.4655,59.9992733001709,4892.39404296875,0.0629249505279502,2.1146092335096E-5
3844472140.4865,59.999626159668,5192.359375,0.0667721505037852,2.05783011327097E-5
3844472160.513,59.9987602233887,5493.12744140625,0.0706407763398994,2.12504372846384E-5
3844472180.359,60.0001907348633,5789.986328125,0.0744916262732011,2.14058719823332E-5
3844472200.4205,59.9999256134033,6091.70434570312,0.0783756626148128,2.21527102234234E-5
3844472220.34,59.9997463226318,6390.17919921875,0.082202344087064,2.17625863327388E-5
3844472240.3695,59.999641418457,6690.43408203125,0.0860574942977313,2.10346426687621E-5
3844472260.3595,60.0000915527344,6990.27221679688,0.0898930960588705,2.19113350904037E-5
3844472280.3865,60.0010070800781,7291.287109375,0.0937458566910863,2.08638599123926E-5
3844472305.7505,59.9983768463135,7670.50952148438,0.0986156900428471,2.20482696647833E-5
3844472325.2655,60.0006656646729,7964.56665039063,0.102455216794406,2.28115853177321E-5
3844472345.257,59.9999179840088,8263.6240234375,0.106318172287213,2.26873748297374E-5
3844472365.2285,60.0004596710205,8563.806640625,0.110167720269271,2.22921785786479E-5
3844472385.2185,60.0005207061768,8863.78466796875,0.113999095809302,2.4534247746219E-5
3844472405.306,60.0009727478027,9164.09375,0.117862916032101,2.24068556367512E-5
3844472425.2425,60.0006294250488,9463.21728515625,0.121705883703775,2.29541990297217E-5
3844472445.1515,60.0011405944824,9761.71533203125,0.125537743862027,2.36742768479251E-5
3844472465.2805,60.0008735656738,10063.2880859375,0.129389686023186,2.34176685976044E-5
3844472485.1305,59.9993782043457,10361.6279296875,0.133240982090677,2.44398701145503E-5
3844472505.131,59.9998073577881,10661.8413085938,0.137111801218498,2.33848556152901E-5
3844472525.1125,60.000904083252,10962.462890625,0.140949816209784,2.35099554449744E-5
3844472545.161,60.0001029968262,11262.5434570312,0.1448105889202,2.52579347593465E-5
3844472565.0495,59.9996795654297,11560.9584960938,0.148637202525798,2.58997538708719E-5
3844472585.1195,60.0005187988281,11861.9541015625,0.15249886305707,2.56156535478798E-5
3844472605.077,60.0009078979492,12161.1655273437,0.156330235901879,2.64988725704696E-5
3844472625.127,60.000280380249,12462.0854492187,0.160189353599367,2.55933629478761E-5
3844472645.1945,60.0008945465088,12762.6064453125,0.164034686295953,2.48242572362976E-5
3844472665.0785,59.9994812011719,13060.5014648438,0.167857338540543,2.51848666190764E-5
3844472684.9905,60.0011672973633,13359.6162109375,0.171701056532176,2.51482812206162E-5
3844472705.1735,59.9998321533203,13662.73828125,0.175557774507798,2.50397382152958E-5
3844472725.0495,60.0007038116455,13960.4721679688,0.17937791648465,2.65467444839489E-5
3844472744.929,60.0005035400391,14258.61328125,0.183264882909928,2.66512893983578E-5
3844472764.9165,60.0003967285156,14557.6430664062,0.18707941285033,2.77832344185889E-5
3844472784.882,59.9997329711914,14857.7177734375,0.190929211873944,2.68658180449949E-5
3844472804.8935,60.0004596710205,15158.34765625,0.194766258405112,2.71022284341176E-5
3844472825.0395,60.0011959075928,15459.7490234375,0.198621080523831,2.72057079028787E-5
3844472844.8455,60.0006866455078,15756.9248046875,0.202445060676195,2.64038665068063E-5
3844472864.8945,59.9999504089356,16057.626953125,0.206332029240637,2.67065528121125E-5
3844472884.8515,59.9998645782471,16357.9077148438,0.210145773809559,2.84219749162045E-5
3844472904.8525,60.0011291503906,16657.6982421875,0.213988865916254,3.10248363711009E-5
3844472924.82,59.9999713897705,16956.6318359375,0.217789780178942,2.72163933306937E-5
3844472944.8015,60.0003604888916,17256.4072265625,0.221624976502125,3.02186431732912E-5
3844472964.763,59.9995784759522,17555.75390625,0.225405706169621,2.90021615504312E-5
3844472984.745,60.000789642334,17854.890625,0.229273922519583,2.99532302462484E-5
3844473004.7855,59.9999122619629,18156.3154296875,0.233136486985769,2.84007770726291E-5
3844473024.7185,60.0010585784912,18454.962890625,0.236969089096375,2.92540495452843E-5
3844473044.875,60.000545501709,18757.0888671875,0.240800888332544,3.14716352148454E-5
3844473064.7555,60.0001773834228,19055.8525390625,0.244596236739767,3.06205770973367E-5
3844473084.838,60.0011367797852,19357.2919921875,0.248520648444455,2.96946300082116E-5
3844473104.8115,60.0005054473877,19655.345703125,0.252350475034657,2.99172690489126E-5
3844473124.699,60.0012283325195,19954.59765625,0.256120296170126,3.16073322618547E-5
3844473144.7185,60.0002593994141,20254.6796875,0.259929272529495,3.05543681618186E-5
3844473164.6145,60.0003261566162,20553.0087890625,0.26377917893172,3.24611268152253E-5
3844473184.711,60.0015621185303,20854.384765625,0.267573485346987,3.08352457081995E-5
3844473204.74,60.0008316040039,21155.0185546875,0.271408454325511,3.10515023683343E-5
3844473224.6245,60.0001544952393,21453.5693359375,0.275235403449696,2.96456193233468E-5
3844473244.6145,60.0000839233398,21752.8466796875,0.279044584989227,3.15408931878556E-5
3844473264.57,60.0016212463379,22052.00390625,0.282939034658567,3.48384348079806E-5
3844473284.538,60.0003776550293,22352.310546875,0.28670731784962,3.51274495004854E-5
3844473304.612,60.0000534057617,22652.9716796875,0.29050347207274,3.45116579609826E-5
3844473324.551,60.000509262085,22951.6767578125,0.294389542997397,3.44959047874449E-5
3844473344.5995,60.0002975463867,23252.3818359375,0.298191080232687,3.25347619115642E-5
3844473364.5545,59.9995365142822,23552.4248046875,0.302080619748238,3.67886117643328E-5
3844473384.5595,60.0002098083496,23851.5380859375,0.305856605230958,3.28274068960905E-5
3844473404.4445,60.000883102417,24151.037109375,0.309611747395789,3.26557684176373E-5
3844473424.595,60.0001335144043,24452.490234375,0.31341574153496,3.31562749739009E-5
3844473444.4285,59.9994411468506,24750.013671875,0.317226282316269,3.73905794070129E-5
3844473464.401,60.0004482269287,25049.80859375,0.321086993567317,3.67919018393825E-5
3844473484.4695,60.0001716613769,25350.6435546875,0.324805860910199,3.46802830522027E-5
3844473504.4385,59.9995746612549,25650.0078125,0.328675907599389,3.47795920579829E-5
3844473524.384,60.0007286071777,25949.13671875,0.33239090148536,3.53950130815274E-5
3844473544.4805,60.0007190704346,26250.6787109375,0.336331624355649,3.85755999500799E-5
3844473564.475,59.9991416931152,26551.3662109375,0.340063591098255,4.16379904247469E-5
3844473584.2985,60.0002517700195,26848.439453125,0.343938763563397,4.22590810556926E-5
3844473604.279,60.0004291534424,27147.6162109375,0.347664506539178,3.69172538547252E-5
3844473624.277,60.0002765655518,27448.1337890625,0.351410619259066,3.25988559840353E-5
3844473644.361,60.0007457733154,27748.72265625,0.355257611690811,3.78455876432172E-5
3844473664.4055,60.0004901885986,28049.5556640625,0.35904795002145,4.05271677292586E-5
3844473684.3525,60.000322341919,28348.6025390625,0.36284568213005,3.61153399429773E-5
3844473704.3615,60.0006275177002,28648.6552734375,0.366664428712446,3.78650159077444E-5
3844473724.2195,60.0003452301025,28946.3896484375,0.370436810397612,3.90805043175041E-5
3844473744.29,60.0007076263428,29247.7099609375,0.374234572131556,4.28467548454281E-5
3844473764.206,60.0000190734863,29545.5224609375,0.378042387959917,4.12834510149871E-5
3844473784.2395,60.0004978179932,29846.9091796875,0.381822902039274,4.43445335191962E-5
3844473804.1815,60.0001392364502,30145.900390625,0.385757114376998,4.40829745226763E-5
3844473824.1985,60.0009956359863,30445.69140625,0.389367911532624,4.15691593266328E-5
3844473844.2325,59.9999694824219,30746.748046875,0.393150290264215,4.26450644340085E-5
3844473864.0995,60.0004501342773,31045.0546875,0.397011281376328,4.12370166112881E-5
3844473884.2685,59.9993801116943,31348.3740234375,0.400748320179345,3.9443540726254E-5
3844473904.143,60.0008373260498,31645.96484375,0.404515105220286,4.22121305181017E-5
3844473924.124,60.0012664794922,31946.1044921875,0.408259286134705,3.6936582697631E-5
3844473944.038,59.9996738433838,32244.57421875,0.412161311893709,3.9688759181947E-5
3844473964.088,59.9996929168701,32545.8779296875,0.415840004104335,4.38075332499318E-5
3844473984.023,60.0005207061768,32844.0625,0.419651096439102,4.36627375837307E-5
3844474004.012,60.0003929138184,33144.05859375,0.423377491976349,4.15722234692416E-5
3844474024.1145,60.0004291534424,33445.779296875,0.427130622645253,4.48924974329944E-5
3844474044.0525,59.9990558624268,33744.6796875,0.430996670456829,4.70390814744466E-5
3844474063.9655,60.0000705718994,34043.412109375,0.434695963628063,4.69600497147119E-5
3844474084.03,60.0010070800781,34343.88671875,0.438398320028054,4.48056427565678E-5
3844474103.9915,60.0007152557373,34644.162109375,0.442152448859351,4.97427371521738E-5
3844474123.9045,59.997859954834,34942.6015625,0.446022639301588,4.79771140711192E-5
3844474143.9615,60.000129699707,35242.22265625,0.449770085273479,4.08075795888341E-5
3844474163.9285,59.9999351501465,35542.1328125,0.453423653590764,4.91476328746692E-5
3844474183.8555,59.9996204376221,35841.56640625,0.457244095088404,4.33960253246966E-5
3844474203.8805,60.000431060791,36142.216796875,0.460989834483724,5.04187437978911E-5
3844474223.875,60.0000534057617,36441.609375,0.464742051159186,5.06304791195767E-5
3844474243.97,60.000825881958,36743.96484375,0.468491920030678,4.67013118676601E-5
3844474263.8285,60.0006217956543,37040.90234375,0.472090360707918,4.64063920956757E-5
3844474283.9115,59.9989013671875,37342.400390625,0.475890162578533,4.83333274842529E-5
3844474303.8505,59.999719619751,37641.568359375,0.479705271483681,4.78399600047225E-5
3844474323.805,60.0001335144043,37941.091796875,0.483424442506527,4.26131748646813E-5
3844474343.882,60.0013275146484,38241.740234375,0.48712627482397,5.15647393680523E-5
3844474363.877,60.0020198822022,38541.9296875,0.490832832341492,4.90989304827259E-5
3844474383.7795,59.9995670318604,38839.609375,0.494607686305856,4.7472062017709E-5
3844474403.89,60.0003032684326,39142.0703125,0.498385462389009,5.15254946010172E-5
3844474423.7695,60.0000782012939,39440.30078125,0.501996536654899,5.02065756464226E-5
3844474443.734,60.0003185272217,39739.603515625,0.5058222289934,5.22888276206694E-5
3844474463.647,59.9996700286865,40038.234375,0.509531650371324,4.98568683213725E-5
3844474483.6525,60.0002899169922,40337.986328125,0.5132370370053,5.08590960238691E-5
3844474503.6285,59.9997673034668,40637.7890625,0.517021624787977,5.55399906248587E-5
3844474523.7795,60.0003051757812,40939.27734375,0.520743063371138,4.8026461996712E-5
3844474543.6465,60.000804901123,41238.080078125,0.524409802792474,5.14482667690346E-5
3844474563.615,60.0006275177002,41537.455078125,0.528109139321042,5.45903515280731E-5
3844474583.6775,60.000057220459,41838.18359375,0.531862764446085,5.35787584758264E-5
3844474603.6245,60.0008506774902,42137.41796875,0.535554039113876,5.04201522540365E-5
3844474623.599,60.0009212493896,42437.703125,0.539271715023562,5.08543833687166E-5
3844474643.548,60.0003662109375,42737.806640625,0.542961982005938,5.65576433867516E-5
3844474663.5785,60.0004901885986,43037.349609375,0.546746203992496,5.12469006001526E-5
3844474683.513,60.0002174377441,43336.607421875,0.550409515810783,5.74008168950247E-5
3844474703.483,59.9995174407959,43635.947265625,0.554093284066191,5.53555474790808E-5
3844474723.4975,60.0005893707275,43936.751953125,0.557757497587378,5.27443628663636E-5
3844474743.4285,59.9985752105713,44236,0.561408540783422,5.69762196952211E-5
3844474763.555,60.000150680542,44536.859375,0.5651379441721,5.23786349181581E-5
3844474783.416,59.9992904663086,44835.080078125,0.568773533563233,4.8420870563693E-5
3844474803.4275,59.9979686737061,45135.412109375,0.572645115153857,6.18620527312467E-5
3844474823.531,59.9997653961182,45437.66015625,0.576131298297154,5.05786525507308E-5
3844474843.4075,59.9996166229248,45734.814453125,0.579914775038978,5.9591016777358E-5
3844474863.499,59.9992008209229,46036.318359375,0.583584860827064,6.07293131668945E-5
3844474883.3665,60.000186920166,46334.19140625,0.587141552908796,5.19851782539811E-5
3844474903.403,60.0000762939453,46635.060546875,0.590850761697603,5.34867943403308E-5
3844474923.327,59.9999580383301,46934.2109375,0.594537329439572,6.13633495338711E-5
3844474943.289,60.0005264282227,47232.6953125,0.598186892435348,5.48647102525302E-5
3844474963.423,60.0002250671387,47535.724609375,0.601805134529436,5.41830050414089E-5
3844474983.3305,60.0001201629639,47833.447265625,0.605467364565327,5.25809043871751E-5
3844475003.2445,60.0003318786621,48132.669921875,0.609168293288793,5.54471184125255E-5
3844475023.378,60.0006217956543,48434.48046875,0.612762633739871,6.32782641699317E-5
3844475043.224,60.0003318786621,48732.166015625,0.616406474711549,5.90966507096151E-5
3844475063.21,59.9995098114014,49032.314453125,0.620039175979817,5.37462451828451E-5
3844475083.378,60.0003967285156,49334.498046875,0.6236274479908,5.81017541215106E-5
3844475103.2015,60.0010433197021,49630.88671875,0.627255074952813,5.52630801599152E-5
3844475123.149,60.0000057220459,49930.69140625,0.630965096414331,5.79480126033739E-5
3844475143.306,60.0005702972412,50233.138671875,0.634687361683977,6.43319457078449E-5
3844475163.2275,59.9998302459717,50532.111328125,0.638200428727882,5.66715177912207E-5
3844475183.108,60.0011386871338,50830.30078125,0.641980225547034,6.65678454721907E-5
3844475203.238,60.0000152587891,51131.7265625,0.645527032024337,6.41163214079427E-5
3844475223.2455,59.9996089935303,51431.013671875,0.649263959428465,6.60725149339316E-5
3844475243.144,59.9999103546143,51730.5546875,0.652771015075299,6.51064804451915E-5
3844475263.0675,59.9997844696045,52029.892578125,0.656470534420286,5.91730093425816E-5
3844475283.1715,60.0001583099365,52332.59765625,0.660149810914357,5.60215875330906E-5
3844475303.1715,60.000581741333,52632.6328125,0.663732310713793,6.24098335325189E-5
3844475323.065,59.9998455047607,52931.423828125,0.667419103412498,5.68689722660943E-5
3844475342.997,59.9992904663086,53230.732421875,0.670963181286174,5.46998113247325E-5
3844475362.982,60.0008716583252,53530.462890625,0.674495808351088,6.50188252516451E-5
3844475383.092,60.0000419616699,53831.12890625,0.678208435984024,6.41980653230234E-5
3844475402.984,60.0007495880127,54130.1015625,0.681643876570911,6.4410959106118E-5
3844475422.951,59.9992923736572,54430.09765625,0.685407214241329,6.32485141036874E-5
3844475442.9605,60.0002861022949,54730.22265625,0.688973768379164,7.25496147559932E-5
3844475463.0615,60.0000534057617,55030.810546875,0.692574556587669,6.44394388627831E-5
3844475482.9475,59.9996337890625,55330.142578125,0.696169645516644,6.780631225761E-5
3844475502.921,60.000452041626,55629.4453125,0.699748741218909,6.9100219331234E-5
3844475522.959,59.9996814727783,55929.931640625,0.703328353145153,6.43897756499117E-5
3844475542.933,59.9996089935303,56228.921875,0.706766430377057,7.03634922032329E-5
3844475562.8425,59.9994411468506,56528.03125,0.710521679459103,7.03105975857565E-5
3844475582.841,60.0006942749023,56828.3125,0.713930611107907,7.20489978802509E-5
3844475602.9175,59.999906539917,57128.900390625,0.717486059655581,7.3286142378377E-5
3844475622.8025,60.0004367828369,57427.55859375,0.721066321549717,7.52240168049692E-5
3844475642.8005,60.0016002655029,57728.26953125,0.724545103593139,7.05526268796094E-5
3844475662.905,59.9992408752441,58030.109375,0.728110813651491,7.46718660574249E-5
3844475682.7485,60.0007266998291,58326.943359375,0.73165864609273,7.38033523122504E-5
3844475702.8425,60.0005207061768,58627.265625,0.735243550807864,6.50458161943141E-5
3844475722.7435,60.0015811920166,58926.16796875,0.738846591342992,7.01330378156821E-5
3844475742.816,60.0018482208252,59227.69140625,0.742209664117914,6.88010664481495E-5
3844475762.6795,59.9996395111084,59525.515625,0.745730982290605,7.69125881240598E-5
3844475782.7995,60.0005474090576,59826.79296875,0.74938724138151,7.65563759115344E-5
3844475802.708,60.0009822845459,60125.4609375,0.752926754553574,7.48204328155617E-5
3844475822.7595,59.9985389709473,60426.966796875,0.756594824225528,7.7501225465298E-5
3844475842.6515,60.000846862793,60725.09765625,0.759959448148718,7.08642274706426E-5
3844475862.686,60.0004997253418,61025.822265625,0.763742213695769,7.70649938835537E-5
3844475882.7725,60.0001926422119,61326.482421875,0.767283278599601,7.92617952354012E-5
3844475902.7245,60.0004787445068,61626.646484375,0.77066882482313,7.91823533486343E-5
3844475922.5515,60.0004005432129,61924.015625,0.774147459925614,6.98450167469606E-5
3844475942.5825,59.9999256134033,62224.8828125,0.777697949214093,6.92678884818772E-5
3844475962.7105,60.00022315979,62527.021484375,0.781220402677878,7.85950229501829E-5
3844475982.617,59.999963760376,62825.525390625,0.784572249125821,7.1936693713291E-5
3844476002.583,60.0001182556152,63124.82421875,0.788002063678205,6.21465977893014E-5
3844476022.595,60.0002117156982,63425.111328125,0.791713059329001,7.21238201140697E-5
3844476042.5985,59.9992027282715,63725.091796875,0.795106763144199,7.59698441950439E-5
3844476062.5155,60.0010051727295,64023.9375,0.798735119387934,7.29853411587899E-5
3844476082.469,60.0005226135254,64323.107421875,0.8021835418878,7.66523320523729E-5
3844476102.4605,59.9997444152832,64623.291015625,0.805710257550092,6.73388193514641E-5
3844476122.5195,60.0003566741943,64924.65625,0.809023971509238,7.90555704057436E-5
3844476142.5185,59.9993858337402,65224.791015625,0.812482299304567,7.57078950922363E-5
3844476162.4735,59.999095916748,65523.123046875,0.816138664173649,7.30224985692974E-5
3844476182.477,59.9994621276855,65823.3203125,0.819393670647803,6.68172553326024E-5
3844476202.5025,59.9996013641357,66124.08984375,0.82282802346052,7.57675966278461E-5
3844476222.478,59.9993553161621,66423.0234375,0.826327381899681,8.18248429034272E-5
3844476242.4015,59.9989395141602,66721.99609375,0.829887362700561,8.16484612390659E-5
3844476262.319,59.9999103546143,67020.453125,0.833356839309274,7.91666184682749E-5
3844476282.359,59.9998035430908,67321.296875,0.836708497196783,7.57342154147048E-5
3844476302.464,60.0010433197021,67622.67578125,0.840133384631791,8.40559381733732E-5
3844476322.3665,60.0005741119385,67921.30078125,0.843747346684918,8.4725493736493E-5
3844476342.2695,59.998836517334,68219.79296875,0.847066710063267,8.79744507617842E-5
3844476362.4235,60.0011329650879,68523.0546875,0.850442650249372,7.89899863242707E-5
3844476382.3175,60.0004463195801,68821.62109375,0.853845709974536,7.67437681181092E-5
3844476402.3275,59.9986705780029,69121.296875,0.857429397278326,8.56332111021309E-5
3844476422.214,59.9995765686035,69419.88671875,0.860828839727464,7.77931924126097E-5
3844476442.2855,59.9994449615479,69721.10546875,0.864309012095119,8.08263931507514E-5
3844476462.1565,60.0005378723145,70019.6875,0.867607600648961,8.98683996834531E-5
3844476482.279,59.9991130828857,70321.3359375,0.871065855777572,9.36823072210361E-5
3844476502.201,59.99755859375,70620.21484375,0.874508424466275,8.22646753173758E-5
3844476522.236,60.0002174377441,70920.90234375,0.878029522269868,7.15816260157273E-5
3844476542.11,60.0006771087646,71218.97265625,0.881289911985496,8.46015881462744E-5
3844476562.247,60.0004596710205,71521.890625,0.884856659008834,9.11597284917881E-5
3844476582.0865,59.9994144439697,71819.30859375,0.888019522798671,8.4156838125401E-5
3844476602.2405,59.9997291564941,72120.69140625,0.891412448643094,8.92960814266773E-5
3844476622.139,60.0009899139404,72419.42578125,0.894792262628223,8.84286149659386E-5
3844476642.1765,60.0001678466797,72720.09375,0.898259101820146,8.73063208704837E-5
3844476662.0805,60.0009174346924,73020.25,0.901627824208141,8.2066206313203E-5
3844476682.0035,60.0011787414551,73318.6953125,0.904881469619937,9.24778428206523E-5
3844476702.0505,60.0003852844238,73618.8671875,0.908135177622806,8.86789837928012E-5
3844476722.0665,60.0002574920654,73920.38671875,0.911494614369927,9.41125054361023E-5
3844476742.0745,60.0000820159912,74219.36328125,0.914941204277443,9.53861368876217E-5
3844476761.948,60.0001220703125,74517.4140625,0.918241171624922,8.46575059099575E-5
3844476781.9905,60.0012664794922,74817.9921875,0.92153270405227,8.2351505788238E-5
3844476801.975,60.000322341919,75117.2890625,0.92498698104738,8.06939686232853E-5
3844476821.9285,59.9992351531982,75416.4765625,0.928271139608131,8.82120166023451E-5
3844476842.0765,60.0011405944824,75718.94140625,0.931628892671877,8.34238133211731E-5
3844476861.868,59.9990253448486,76015.93359375,0.93519235168562,9.56122207949142E-5
3844476881.982,60.0000476837158,76318.6875,0.938470809344136,9.26955900284094E-5
3844476901.947,59.9999561309814,76617.12890625,0.941932599879619,8.98890806487063E-5
3844476921.9555,60.0000114440918,76917.72265625,0.94497412698256,8.13535148881626E-5
3844476941.827,59.999605178833,77215.50390625,0.948508592270574,8.45165495827867E-5
3844476967.248,59.9997367858887,77597.56640625,0.952447419647174,0.000103408471683865
3844476986.8115,59.9993858337402,77891.0078125,0.955711299784979,9.95496944279559E-5
3844477006.914,60.0001678466797,78193.8359375,0.958966648703627,9.62429188905582E-5
3844477026.732,59.9993019104004,78490.83984375,0.962131215422535,8.80166362787829E-5
3844477046.7755,60.0000667572022,78791.60546875,0.965363081488191,8.25354812730881E-5
3844477066.871,59.9994316101074,79093.13671875,0.968794400887608,9.15676200089215E-5
3844477086.881,60.0001029968262,79393.08203125,0.972067546089815,9.94383212263631E-5
3844477106.685,59.9992389678955,79689.78515625,0.975512876241612,0.000104881142665154
3844477126.7615,59.9995670318604,79991.17578125,0.978673212388619,9.3102809355862E-5
3844477146.6725,59.9992504119873,80289.77734375,0.981844764596417,9.44186190578073E-5
3844477166.6595,59.99928855896,80589.63671875,0.985129333278652,9.92423674353007E-5
3844477186.621,59.9994506835938,80888.9296875,0.988515257875463,0.000105180821034368
3844477206.64,60.0007915496826,81189.56640625,0.991488795952068,9.51160103253663E-5
3844477226.616,60.0002841949463,81488.984375,0.994817609898862,9.00670130527732E-5
3844477246.585,59.999584197998,81788.1171875,0.998002060368179,8.72425083387625E-5
3844477266.571,59.999963760376,82087.6796875,1.0012966543618,9.89174143864548E-5
3844477286.5455,60.0000343322754,82387.40234375,1.00446729833194,9.06019457884649E-5
3844477306.557,60.0005874633789,82687.4296875,1.00776592393282,0.000100176624673944
3844477326.5215,59.9996395111084,82987.296875,1.01114030109586,9.13154678466776E-5
3844477346.6275,60.0004730224609,83287.9765625,1.01436496026544,9.34963989888258E-5
3844477366.5225,60.000904083252,83586.5859375,1.01739119301263,9.79393692468837E-5
3844477386.498,59.9997787475586,83886.6484375,1.0207222573906,9.01740526556116E-5
3844477406.5975,59.9999885559082,84188.6640625,1.02385551185064,9.54661231106046E-5
3844477426.494,60.0012741088867,84487.3203125,1.02707550747759,8.01095994611134E-5
3844477446.522,59.9995708465576,84787.015625,1.03046822328148,0.000105900345629884
3844477466.419,60.000919342041,85085.7421875,1.03372242293089,9.36958674387167E-5
3844477486.518,60.0012435913086,85387.8046875,1.03680448770024,0.000100280592242068
3844477506.4115,59.9997100830078,85686.31640625,1.04005844372909,9.56368735507149E-5
3844477526.4105,60.0007152557373,85987.16015625,1.04326929381494,8.71465266828442E-5
3844477546.453,60.0001373291016,86287.05078125,1.04633371715627,9.37467056116881E-5
3844477566.343,59.9998455047607,86584.86328125,1.04935449155976,9.20486541748221E-5
3844477586.4515,59.9985046386719,86887.25390625,1.0527164744074,9.26998613412362E-5
3844477606.317,59.9976749420166,87185.5859375,1.05599300391409,9.70260871310128E-5
3844477626.3715,60.0016574859619,87485.859375,1.05911828997387,9.94867008018528E-5
3844477646.325,59.9998359680176,87785.19921875,1.06223548106464,0.000108374476578813
3844477666.3375,59.9997425079346,88085.28515625,1.06533851445549,9.73399829537475E-5
3844477686.2885,59.9985542297363,88384.53515625,1.06845720643765,9.85254492297816E-5
3844477706.2515,59.9973278045654,88683.6875,1.07169569031111,8.92780060909995E-5
3844477726.2805,59.9995365142822,88983.6015625,1.07501966424104,9.75053496712413E-5
3844477746.2195,59.9998645782471,89283.80078125,1.07795662100267,0.000110033190708987
3844477766.2235,59.9997081756592,89582.97265625,1.08081477283792,0.000101676148505604
3844477786.22,59.9993171691895,89882.8046875,1.08429851595554,0.000109539101238582
3844477806.159,60.0004482269287,90182.75390625,1.08725168705811,0.000102354075566164
3844477826.1805,60.0009899139404,90482.953125,1.09026647213314,9.39917478446046E-5
3844477846.2615,60.0009937286377,90784.6328125,1.09352910166848,0.000104021873895273
3844477866.2495,60.0000743865967,91084.71484375,1.09673037500873,0.000111179547101738
3844477886.1705,59.9994621276855,91383.52734375,1.09984487484946,9.70649289390634E-5
3844477906.085,59.9999561309814,91682.25390625,1.10303524259877,0.000111691796771588
3844477926.262,59.9992752075195,91985.4296875,1.1059962709,0.000110711157922715
3844477946.139,60.0006122589111,92283.37890625,1.10902711549577,0.000100214869373744
3844477966.0475,59.9997138977051,92582.640625,1.11205066557303,0.000100271224009354
3844477986.0405,59.9996280670166,92882.5859375,1.11515008329336,9.5620659823157E-5
3844478006.1135,59.9998149871826,93183.4609375,1.11824417506664,0.000103449933377384
3844478026.031,59.99924659729,93481.89453125,1.12124574466922,0.000117967287296557
3844478046.1155,59.9988079071045,93783.87109375,1.12438932974838,9.85376530146059E-5
3844478066.0805,60.0005893707275,94084.03515625,1.12754714541982,0.000123550982008002
3844478085.967,60.0000267028809,94382.67578125,1.1306172095686,0.000110006451702267
3844478105.996,60.0011901855469,94682.88671875,1.13348189590913,0.000106605116590333
3844478126.0625,59.9992866516113,94983.49609375,1.13659030063204,0.000109697075692884
3844478146.029,59.99951171875,95282.19921875,1.13935805052193,0.000105898659183358
3844478165.9385,59.998706817627,95580.5078125,1.14259153884875,0.000102677408293777
3844478186.005,59.9995498657227,95882.09375,1.14559161913924,0.000110712631389417
3844478205.869,59.9978713989258,96180.55078125,1.148522820012,0.000112996215779722
3844478225.9515,59.9978218078613,96481.44140625,1.15153017145679,9.32761763608217E-5
3844478245.926,59.9988460540771,96781.421875,1.15468274646746,0.00011502727780404
3844478265.896,59.9978008270264,97080.99609375,1.1577279109871,0.000118064649756397
3844478286.0195,59.9993057250977,97383.41015625,1.16076575573802,0.000120001040959165
3844478305.8,59.9987125396729,97679.578125,1.16387682633639,0.000103116188121553
3844478325.88,59.9995193481445,97980.29296875,1.16696546174474,0.000113633369506933
3844478345.8015,60.0006675720215,98280.30859375,1.16967428361728,0.000107302758319152
3844478365.9355,59.9984836578369,98582.2734375,1.17257205499821,0.000109533979789133
3844478385.8745,59.9986820220947,98881.546875,1.17561291676525,0.000110120529541916
3844478405.7315,59.9999980926514,99179.98828125,1.17869615044073,0.000127603283082239
3844478425.7945,59.9993190765381,99480.79296875,1.18153983731692,0.000114223590887158
3844478445.7025,59.9988059997559,99779.61328125,1.1845671770312,0.000106654408035912
3844478465.86,59.9990062713623,100081.8203125,1.18768298242258,0.00011569711123179
3844478485.661,59.9989948272705,100379.25,1.19051876224442,9.98140724299776E-5
3844478505.6445,59.9991016387939,100678.43359375,1.19310200876992,0.000114083417904888
3844478525.786,59.9986934661865,100980.83984375,1.19626162445543,0.000110947918172823
3844478545.6935,59.9990577697754,101279.1875,1.19932797035478,0.000122981662235937
3844478565.5875,59.9986419677734,101577.546875,1.20219115796275,0.000106602791106465
3844478585.5965,59.9985885620117,101878.203125,1.20507012655842,0.000120602275763942
3844478605.7025,59.9993495941162,102179.59375,1.20828635143548,0.000132648339895976
3844478625.736,59.9997024536133,102479.6015625,1.21110473583319,0.000115384387878234
3844478645.5795,59.9979877471924,102777.0703125,1.21397215522525,0.000111609619475925
3844478665.531,59.9993572235107,103076.09765625,1.21678974041688,0.000126640375599247
3844478685.6085,59.9988956451416,103377.48046875,1.21961005127016,0.000111755055172929
3844478705.486,59.9991989135742,103676.31640625,1.22265919589543,0.000110101880006783
3844478725.58,59.9990043640137,103977.765625,1.22563094502913,0.000123164811777285
3844478745.616,59.9981002807617,104277.71875,1.22858153099645,0.000125458414240859
3844478765.4825,59.9994525909424,104575.734375,1.23120034901164,0.000110766846182737
3844478785.4715,59.9989166259766,104876.5859375,1.23419440640945,0.000121211317079096
3844478805.5255,59.9993114471436,105177.671875,1.23718081129062,0.000128191735208204
3844478825.539,60.0000629425049,105477.609375,1.24010349835652,0.000133568553557428
3844478845.406,60.0012626647949,105776.17578125,1.24266555212359,0.000122480681925835
3844478865.462,59.9990692138672,106076.41015625,1.2457185827858,0.000127735807016861
3844478885.3915,60.0006790161133,106375.99609375,1.24863506634138,0.000112104882477165
3844478905.3925,60.0009651184082,106675.9453125,1.25117372366497,0.000117066955448987
3844478925.468,59.9996509552002,106976.76171875,1.25401263923332,0.000114545925323217
3844478945.4425,59.9983730316162,107276.53125,1.25704047616465,0.000122081759276669
3844478965.2995,59.9989891052246,107575.28515625,1.25974291690166,0.000114663546241043
3844478985.311,59.9985942840576,107874.4296875,1.26268671765854,0.000130858563409721
3844479005.2835,59.9984321594238,108173.890625,1.26564865493954,0.000123670354576245
3844479025.2865,59.9973392486572,108473.73046875,1.26849861720424,0.000123192258143917
3844479045.456,59.9976768493652,108775.9609375,1.27132082912924,0.000135326438342019
3844479065.2615,59.9985790252686,109073.60546875,1.27404013546219,0.000137975356078943
3844479085.322,59.9977264404297,109374.0703125,1.27677094952454,0.000144433904240813
3844479105.3145,59.9988651275635,109674.140625,1.27964009800535,0.000127502636467093
3844479125.2735,59.9978466033935,109973.359375,1.2821931550284,0.000126026071169978
3844479145.199,59.9970455169678,110272.125,1.2855393859585,0.000134539984353625
3844479165.18,59.9977741241455,110572.13671875,1.28813796440052,0.000128108885288043
3844479185.1765,59.997709274292,110871.8125,1.29102258114573,0.000142469275937977
3844479205.1835,59.9991455078125,111172.66015625,1.29373007593488,0.000130077258572862
3844479225.105,59.9987659454346,111471.70703125,1.29635699412337,0.00012015677078764
3844479245.1975,59.9997711181641,111773.328125,1.29905509937238,0.000145634482258563
3844479265.151,59.9999294281006,112072.8671875,1.30206778361509,0.000118952294037162
3844479285.114,59.9998397827148,112372.1953125,1.30456598937008,0.000126745186615853
3844479305.07,60.0002632141113,112672.4921875,1.30732204640716,0.000132174195697954
3844479325.076,60.0004005432129,112972.8515625,1.30993060434049,0.000115610394362307
3844479345.1395,59.9999828338623,113272.98046875,1.31259743359612,0.000103173202921935
3844479365.1225,60.0003089904785,113573.4921875,1.31533009776306,0.000124023195913502
3844479385.1225,60.0008163452148,113872.73046875,1.31816211414129,0.000119004547459911
3844479405.0765,60.0008811950684,114172.3984375,1.32110543605737,0.000132068173581483
3844479425.03,59.9995079040527,114471.2734375,1.32365089540164,0.000135411742485484
3844479445.0885,60.0007953643799,114773.828125,1.32624760295018,0.000126720777709119
3844479464.937,60.0001945495606,115071.51953125,1.3287535952212,0.000108179567635496
3844479484.949,60.0023765563965,115372.29296875,1.33136998478392,0.000117535612109081
3844479505.0205,60.0023384094238,115672.9375,1.33409943373066,0.000114815628194112
3844479524.9215,60.0013446807861,115970.12890625,1.3367799705626,0.000119469854406408
3844479545.0205,60.0001220703125,116272.03125,1.33954700097577,0.000121657412013056
3844479564.8835,60.0019645690918,116569.6640625,1.34219717488058,0.000118906202652298
3844479584.8765,60.0021629333496,116869.58203125,1.34501084270184,0.000112526402017273
3844479604.9435,59.9999141693115,117170.3671875,1.34748897821906,0.000108724193123617
3844479624.9135,60.0010318756104,117469.8984375,1.35019856914531,0.000117538648467502
3844479644.8015,60.0014877319336,117769.2890625,1.3530151637975,0.000135098676437819
3844479664.8775,60.0009822845459,118070.328125,1.35547211202534,0.000125806816887247
3844479684.8505,60.0008888244629,118369.4453125,1.35868888887691,0.000129717385056969
3844479704.811,60.0011577606201,118669.31640625,1.36096987409855,0.000117892372923932
3844479724.815,60.0006065368652,118969.34765625,1.36365137066994,0.00012913184911076
3844479744.7495,60.0011920928955,119268.2578125,1.3661865522671,0.000127521950194515
3844479764.7315,59.99928855896,119568.34765625,1.36901186748716,0.00013313897099461
3844479784.8085,59.9999332427978,119870.421875,1.37169887520919,0.000128535128816593
3844479804.679,59.9993686676025,120168.2734375,1.37415913709142,0.000135381376956652
3844479824.6815,59.9992980957031,120468.44140625,1.37692581702221,0.000126113413617046
3844479844.7495,60.0008983612061,120770.12109375,1.37945536377749,0.000125365263964636
3844479864.652,59.9998569488525,121068.60546875,1.38207476995916,0.000130920427001545
3844479884.6885,59.9977321624756,121369.2109375,1.38462583011823,0.000132278632765265
3844479904.6365,59.9994144439697,121668.50390625,1.387222034955,0.000124520691016661
3844479924.676,60.0001010894775,121968.69140625,1.38957992326036,0.000117146800450404
3844479944.67,60.0002841949463,122268.48828125,1.39222878342035,0.000114003015046131
3844479964.58,60.0014915466309,122566.91015625,1.3949299891551,0.000128819940483648
3844479984.604,60.0001010894775,122867.453125,1.39704052630029,0.000131552285403718
3844480004.6055,60.0007629394531,123167.6328125,1.39974986752473,0.000116616623581913
3844480024.6495,59.9998893737793,123468.89453125,1.40260228116908,0.00012910434659713
3844480044.529,60.0004653930664,123766.1953125,1.40497404840842,0.00011444812022443
3844480064.5365,60.000904083252,124065.046875,1.40754295335915,0.000134412602585091
3844480084.6375,60.0007076263428,124366.40625,1.41012382450422,0.000128195211318987
3844480104.573,59.9999771118164,124665.7734375,1.41251224702134,0.000126405568743027
3844480124.454,59.999568939209,124964.11328125,1.41508102047502,0.000115572259886829
3844480144.6895,60.0018844604492,125268.6953125,1.41774846025504,0.000145161636553727
3844480164.4735,60.000036239624,125564.9921875,1.42024532935542,0.000132667264845625
3844480184.4215,59.9997882843018,125864.71875,1.42316087093046,0.000145830227415029
3844480204.458,59.9995975494385,126164.0703125,1.4254601057892,0.000130378550199577
3844480224.5375,59.9991874694824,126465.91015625,1.42764121407181,0.00013384381502542
3844480244.4225,60.0010356903076,126764.55859375,1.43013811657884,0.000132141124838426
3844480264.4205,59.9996585845947,127064.140625,1.43264424693525,0.000132139390369797
3844480284.3575,60.0000286102295,127364.2578125,1.4352433538595,0.000128041723452825
3844480304.4175,60.0000190734863,127665.05859375,1.43776045588411,0.000138629020755127
3844480324.3275,60.0008316040039,127963.890625,1.44022369627307,0.00014031330074634
3844480344.377,59.9999256134033,128265.5,1.4426445017356,0.000132692091286276
3844480364.269,59.9994869232178,128563.47265625,1.44514637417166,0.000126562820898746
3844480384.4075,60.0013599395752,128865.875,1.44764341730278,0.000124468987371164
3844480404.298,59.9992580413818,129164.21484375,1.45016757861882,0.000144687876439313
3844480424.381,60.0009098052979,129464.8984375,1.4523950988063,0.00012742441916186
3844480444.221,60.0001945495606,129763.12109375,1.45490252225455,0.00014472255716161
3844480464.3855,59.9989929199219,130065.4296875,1.45716022715724,0.000131866146649315
3844480484.2515,60.000581741333,130363.9921875,1.45955728473758,0.000144649191715599
3844480504.179,59.998706817627,130663.04296875,1.46231144344986,0.000150895538567541
3844480524.2075,59.9992580413818,130963.0078125,1.46465092337793,0.000139420961935966
3844480544.265,59.9982643127441,131263.5546875,1.46703354786374,0.000141840684156342
3844480564.297,60.0008544921875,131563.8828125,1.46902553863465,0.000129862372894852
3844480584.119,60.0005970001221,131860.3671875,1.47160990392914,0.000136519980778101
3844480604.084,59.9998340606689,132160.15625,1.47420380362035,0.000145232033374245
3844480624.1995,59.9995918273926,132461.9375,1.47645594648431,0.000141934018203013
3844480644.0955,59.9995975494385,132760.3984375,1.47913001263871,0.000147144876861546
3844480664.2035,59.9997291564941,133061.8125,1.48135802163926,0.000126118895536506
3844480684.1805,60.0007209777832,133361.0703125,1.48366105191129,0.000139555181383834
3844480704.036,59.9998874664307,133659.9453125,1.48597705824714,0.000147321415324516
3844480724.257,60.0008525848389,133962.9765625,1.48837573513617,0.000130819680190163
3844480743.992,59.9991722106934,134259.0546875,1.49076814611518,0.000145408134161884
3844480764.026,59.9995021820068,134558.9609375,1.49289347028193,0.000138307818863357
3844480784.0905,60.001049041748,134861.6015625,1.49576461550637,0.000151611953765319
3844480803.9375,60.0000743865967,135158.0390625,1.49799813753289,0.000147217112954638
3844480824.0275,60.0000839233398,135460.1484375,1.50014902063727,0.000135113504994348
3844480843.948,60.0001583099365,135759.9453125,1.50256614694971,0.000145640735144813
3844480863.9755,59.9993419647217,136060.71875,1.50476320643956,0.000136872201529815
3844480883.892,59.9982414245606,136359.6796875,1.50755320792262,0.000148581200925221
3844480903.8865,59.9997901916504,136659.6484375,1.50985565542068,0.000164957351758254
3844480923.971,59.9989757537842,136960.8125,1.51181305804076,0.000141546675205868
3844480943.833,59.9986972808838,137258.6171875,1.51434282692917,0.000160164460889154
3844480963.8715,59.9993991851807,137559.09375,1.51659977028143,0.000149025944256378
3844480983.945,59.9996128082275,137860.6640625,1.51908975512913,0.000149447983261372
3844481003.8165,59.9997177124023,138159.4140625,1.52113028965193,0.000153186876125458
3844481023.979,59.9996891021729,138461.65625,1.52357289621801,0.000137794429045465
3844481043.796,59.9991054534912,138758.921875,1.5256936928444,0.000158234575416233
3844481063.758,59.9980888366699,139059,1.52804917220987,0.000149144864992213
3844481083.827,59.9999084472656,139359.6796875,1.53069405675902,0.000165538250316733
3844481103.726,59.9986572265625,139657.9921875,1.53273908540472,0.000159420020089285
3844481123.7985,59.9989719390869,139958.5625,1.53502688590904,0.000157260576583977
3844481143.83,60.0008888244629,140000.2890625,1.53496645261447,0.000127170834887267