File: MvsH/2021-10-25_EROI_34P8MG_MVSH_3P0K.DAT
Time Stamp (sec),Temperature (K),Magnetic Field (Oe),Moment (emu),M. Std. Err. (emu)
3844413434.238,3.0020937508929,-4999.93798828125,,
3844413539.026,3.00062572956085,-4855.52172851562,-0.274475266647848,9.05378870358123E-5
3844413558.942,2.99677717685699,-4556.42895507812,-0.258189218551716,8.43773490259504E-5
3844413578.925,2.99959790706634,-4256.4765625,-0.241611569143168,8.77707521437795E-5
3844413598.8825,2.99857473373413,-3958.3486328125,-0.225200879961015,8.67967581492456E-5
3844413618.983,2.99718201160431,-3656.57421875,-0.208579435444325,8.56875504527058E-5
3844413638.9495,2.99577915668488,-3357.47216796875,-0.191867485155916,8.30905580604229E-5
3844413658.8565,2.99753320217133,-3058.86572265625,-0.175122960701147,8.71574392307137E-5
3844413678.877,2.99823820590973,-2758.17578125,-0.15835788435602,8.83030820656638E-5
3844413699.0105,2.99502611160278,-2456.54284667969,-0.141417103201,8.54246126450463E-5
3844413718.802,3.00234615802765,-2159.61242675781,-0.124463640329006,8.57075683049474E-5
3844413738.8075,3.00323522090912,-1859.61151123047,-0.107492771194107,8.63817935012524E-5
3844413758.9135,2.99817252159119,-1558.25384521484,-0.090411104211468,8.78203035763481E-5
3844413778.823,2.99463760852814,-1259.34332275391,-0.0733548612940226,8.80289720740761E-5
3844413798.7905,3.0018265247345,-960.398101806641,-0.0562561992443532,8.75236592369803E-5
3844413818.7885,2.99689722061157,-660.314270019531,-0.0391003751731212,8.7168270418646E-5
3844413843.8345,2.99829018115997,-284.628814697266,-0.0176055026776649,8.76854038997969E-5
3844413863.7955,3.00152087211609,14.4173860549927,-0.000416971174904209,7.85214193523346E-5
3844413893.9785,3.00652372837067,467.226348876953,0.0254765280752107,8.82348864422152E-5
3844413913.703,2.99630129337311,762.905578613281,0.0427091741078717,8.87033593129861E-5
3844413933.649,2.99846541881561,1061.91174316406,0.0599141246276032,8.78294095428315E-5
3844413953.637,2.99880790710449,1361.47308349609,0.0770607653722685,8.7299299387878E-5
3844413973.639,3.00320887565613,1661.37072753906,0.0941797273334844,8.64311690652502E-5
3844413998.618,2.99859023094177,2036.59686279297,0.115554708055245,8.86821685791078E-5
3844414018.681,3.00383818149567,2337.0322265625,0.132607814162051,8.73830523340736E-5
3844414038.6485,3.0087913274765,2636.29125976562,0.149497212700873,8.80978273295808E-5
3844414058.54,2.9973167181015,2935.57299804687,0.166425208622202,8.80777899099822E-5
3844414078.5725,3.00737714767456,3234.76684570313,0.183174852113951,8.80457822041812E-5
3844414098.5805,3.00294315814972,3535.73767089844,0.199915282803306,8.80510057102179E-5
3844414118.6045,3.0013952255249,3836.31982421875,0.21652934823844,8.38295176836665E-5
3844414138.524,3.00027179718018,4134.23120117188,0.233035408030631,8.7614494544606E-5
3844414158.5255,3.00135898590088,4434.12548828125,0.249529015632881,8.51643156913382E-5
3844414178.5185,2.99635195732117,4734.3359375,0.265848504654677,8.72555529902649E-5
3844414198.4345,3.00332069396973,5033.50317382812,0.282092597117045,8.73796902632983E-5
3844414218.3865,3.00321626663208,5332.12036132812,0.298266191648413,8.81064290964837E-5
3844414238.515,3.00082409381866,5634.28002929687,0.314437206335312,8.77141474046947E-5
3844414258.4455,2.99764358997345,5932.95483398438,0.330337864170581,8.91595614669793E-5
3844414278.3545,3.00014925003052,6232.775390625,0.346365367442958,8.63505495688509E-5
3844414298.366,3.00710535049438,6531.80151367187,0.361910759786312,8.50045186460511E-5
3844414318.359,2.99779331684113,6831.48876953125,0.377691587780644,8.7417107552547E-5
3844414338.354,3.00104665756226,7132.2587890625,0.393325496838917,8.32331546070042E-5
3844414358.4035,3.00430130958557,7432.2294921875,0.408727974467332,8.23009757270775E-5
3844414378.294,3.00140309333801,7730.77465820312,0.424171285915913,8.86008189706279E-5
3844414398.324,3.00200951099396,8031.57299804687,0.439502682545732,8.61670209766416E-5
3844414418.3485,3.005375623703,8331.462890625,0.454684497169892,8.66445368103832E-5
3844414438.279,2.99502098560333,8630.9638671875,0.469811316510525,8.66326624489778E-5
3844414458.316,2.99123430252075,8931.6494140625,0.484857161146174,8.64210473795721E-5
3844414478.2485,3.00323271751404,9229.6767578125,0.499675753304622,8.63164523610506E-5
3844414498.1815,3.00080752372742,9528.91357421875,0.514543513213167,9.54387851033073E-5
3844414518.2385,3.00012767314911,9829.92236328125,0.529100086815678,9.1359606276007E-5
3844414538.1755,2.999387383461,10129.0708007813,0.543734598891288,8.5706473982675E-5
3844414558.176,3.00169777870178,10428.7607421875,0.558328914426805,8.37309063879721E-5
3844414578.1315,3.00142407417297,10729.1079101562,0.572720066866703,9.33024683913431E-5
3844414598.147,2.99703097343445,11029.130859375,0.586985325502702,9.59611908169608E-5
3844414618.1515,2.99883830547333,11329.1547851562,0.601154164650864,8.63107021874819E-5
3844414638.084,3.0023695230484,11628.4086914062,0.615286202974135,8.95170167906497E-5
3844414658.236,2.99842870235443,11930.2416992187,0.629286713349232,9.63435652615786E-5
3844414678.0865,2.99937951564789,12228.5551757813,0.643349690739822,8.69489601073154E-5
3844414698.0495,2.99805128574371,12528.0224609375,0.657299747541618,9.38082015147948E-5
3844414718.03,2.99566066265106,12827.1455078125,0.671241511658242,0.000103152849937292
3844414738.073,3.00136578083038,13127.9072265625,0.684897123545138,9.9407481253046E-5
3844414758.0855,2.99929451942444,13427.8349609375,0.698458307319795,8.98215599659406E-5
3844414777.9835,3.00134742259979,13726.6040039062,0.712065867702147,9.43333538214311E-5
3844414798.101,2.99308598041534,14028.7705078125,0.725733763503924,9.7401618649986E-5
3844414818.0115,3.00413596630096,14326.1298828125,0.739032838249936,9.53998806508866E-5
3844414838.0225,2.99970853328705,14626.6284179687,0.752622580832218,9.16992082370857E-5
3844414857.9965,3.00491631031036,14926.6284179687,0.765722712625334,8.6471785969458E-5
3844414877.923,2.9950966835022,15225.9858398438,0.779043243115892,9.1138942614296E-5
3844414897.9645,2.99678027629852,15525.9184570313,0.792346663967543,9.46783657886505E-5
3844414917.966,3.00338459014893,15826.1865234375,0.805317736702226,9.49446506946107E-5
3844414937.8885,2.99732077121735,16124.6162109375,0.818549165752627,0.000113234302087548
3844414957.848,3.0060703754425,16424.7724609375,0.831562582637111,9.75584700041742E-5
3844414977.8925,2.99875855445862,16724.5712890625,0.84453112255409,9.22458240264225E-5
3844414997.833,3.00490272045135,17024.2548828125,0.857150227629415,9.91641458792151E-5
3844415017.97,2.99217522144318,17325.642578125,0.870183045368037,9.62454855366585E-5
3844415037.8525,3.00396418571472,17625.07421875,0.883008095627631,9.96974796113984E-5
3844415057.8825,3.00009477138519,17924.2060546875,0.895895721129916,0.000106123832933873
3844415077.859,2.99876582622528,18224.1806640625,0.908457601000376,0.000103133504794982
3844415097.7725,3.00052189826965,18523.4033203125,0.920836102585875,0.000106134904691234
3844415117.8865,2.99978220462799,18824.6884765625,0.93360666272767,0.000107578771384438
3844415137.701,3.00581920146942,19121.806640625,0.946065283909675,0.000108872587388324
3844415157.75,2.99787831306458,19422.3818359375,0.958511735790847,0.000117438445724596
3844415182.6925,2.99282288551331,19797.0595703125,0.973963869429886,0.000108245153868837
3844415202.8175,2.99763369560242,20098.41015625,0.986439180958422,0.000114729540804061
3844415222.6645,2.99687659740448,20395.517578125,0.99843671072601,0.000114813671989973
3844415242.683,2.99460566043854,20696.2294921875,1.01084884211409,0.000114172897352443
3844415262.7285,3.00065886974335,20996.7744140625,1.02300301426525,0.000102885448356881
3844415282.7165,2.99392259120941,21296.7744140625,1.03539357113508,9.99617502120557E-5
3844415302.6335,2.99990081787109,21596.2509765625,1.04739900655024,9.60467021007105E-5
3844415322.589,3.0049694776535,21894.791015625,1.05972150292448,0.000112275799208432
3844415342.591,2.99668574333191,22195.138671875,1.0717243190586,9.90161550537359E-5
3844415362.672,3.00029027462006,22495.8095703125,1.08362467438627,0.000114963106319129
3844415382.7245,2.99793589115143,22796.4892578125,1.0959479805855,0.000112419274568404
3844415402.5535,2.99936068058014,23095.0146484375,1.10782706258596,0.000131532830002099
3844415422.508,3.00061237812042,23393.505859375,1.11973727396523,0.000114546519612371
3844415442.4995,2.99611866474152,23692.853515625,1.13183113803788,0.00011282458895662
3844415462.601,2.99684572219849,23994.9912109375,1.14373311289183,0.00011457568013883
3844415482.598,2.99982988834381,24294.9970703125,1.15555995265613,0.000121438270447051
3844415502.4565,3.00446903705597,24592.6640625,1.16760627826523,0.000124346612153934
3844415522.478,3.00101327896118,24892.3017578125,1.17929105726788,0.000123891997930332
3844415542.5335,2.99968123435974,25193.712890625,1.19114440559771,0.000122264510121725
3844415562.477,3.00075876712799,25492.4931640625,1.20271115560838,0.000120076431700087
3844415582.3945,3.00210583209991,25791.6083984375,1.21467080674293,0.000125403790553123
3844415602.4245,2.99618327617645,26092.4365234375,1.22656071067236,0.000133488000973227
3844415622.523,3.00309836864471,26393.0546875,1.23826596147809,0.000120612816486793
3844415642.4025,2.99921631813049,26691.6171875,1.24997484647159,0.000140429628651083
3844415662.3235,2.99935436248779,26990.919921875,1.26174038017808,0.00012641001256749
3844415682.3605,3.00281345844269,27290.7939453125,1.27368426538084,0.000143168536902164
3844415702.4915,3.0010586977005,27592.7412109375,1.28557816593206,0.000133112670948758
3844415722.2925,3.00200831890106,27889.568359375,1.29688350329307,0.000135229496933763
3844415742.4265,2.99946844577789,28192.0908203125,1.30864652347516,0.000134400567443069
3844415762.3515,2.9971776008606,28490.4052734375,1.32014272839917,0.000131220331308498
3844415782.35,2.99838352203369,28790.4609375,1.33195675685896,0.000131628738948994
3844415802.2145,3.00000131130218,29088.2578125,1.34348939251736,0.000127424591688348
3844415822.295,2.99998509883881,29389.83984375,1.35523044424001,0.000134941970759533
3844415842.1985,2.9997341632843,29688.3017578125,1.3664595052963,0.000127911250065117
3844415862.233,3.00214648246765,29989.4052734375,1.37839150823519,0.000142621253155482
3844415882.164,3.00339579582214,30287.8056640625,1.38985725156118,0.000133155874722563
3844415902.172,3.00179386138916,30587.8583984375,1.40115551906157,0.000143026709400604
3844415922.2515,2.99923956394196,30889.37890625,1.41251926172678,0.000153490522062875
3844415942.1785,3.00085639953613,31187.7353515625,1.42378103375637,0.000140980318944153
3844415962.1025,2.99869465827942,31487.23828125,1.43538216711921,0.000138317095275813
3844415982.1825,3.00129568576813,31788.6630859375,1.44668316836706,0.000138581950497743
3844416002.0595,3.00198495388031,32087.2607421875,1.45790020739917,0.000140918390839147
3844416022.144,3.00257098674774,32388.703125,1.46905366767421,0.000138150127647524
3844416042.1005,3.0038069486618,32687.7626953125,1.48015584665307,0.000156074429383322
3844416062.186,2.99584650993347,32988.939453125,1.49100076379197,0.000147861115773979
3844416082.0495,2.99919521808624,33286.9296875,1.50168096699682,0.00013856303339708
3844416102.0705,2.99975264072418,33586.8515625,1.5128913713316,0.000148741318361067
3844416122.151,3.00217545032501,33887.654296875,1.52376769984429,0.000159831200584129
3844416142.116,2.99357104301453,34187.578125,1.53442375343192,0.000145341373674929
3844416162.124,3.00301802158356,34488.263671875,1.54511371692159,0.000153013899230983
3844416181.954,2.99921667575836,34785.22265625,1.55582676970137,0.000160280139568074
3844416202.074,2.99884819984436,35086.65625,1.56585715809028,0.000147296950596718
3844416221.9325,3.00235199928284,35384.708984375,1.57616249604934,0.000146430787091027
3844416242.0835,3.0016325712204,35686.126953125,1.58653839752897,0.000150107602611715
3844416261.939,3.00536382198334,35984.869140625,1.59694897127088,0.000129523835800153
3844416281.9395,3.00083816051483,36284.759765625,1.60673563767317,0.000158338734651576
3844416301.842,3.00393903255463,36583.50390625,1.61671007911469,0.000165124269220404
3844416321.8515,3.00332939624786,36883.28515625,1.62654428662284,0.000147900794825407
3844416341.857,3.00096917152405,37184.37109375,1.63622099878937,0.000145847441192475
3844416361.9365,3.00261926651001,37485.044921875,1.64613681298778,0.000155380170967585
3844416381.7845,2.99855399131775,37782.484375,1.65537859345301,0.00015543441303013
3844416401.9085,2.99659299850464,38083.65625,1.66444186051181,0.000164044703827722
3844416421.864,2.99826049804687,38382.955078125,1.67360266800821,0.000142830926356682
3844416441.869,2.99783706665039,38683.740234375,1.68226048712889,0.000145316863939419
3844416461.734,2.99959206581116,38982.03125,1.69115795518755,0.000150546084531328
3844416481.8145,3.00234818458557,39282.98828125,1.70005956680142,0.000151907920595974
3844416501.864,2.99983084201813,39583.486328125,1.70915271444247,0.000158758925114588
3844416521.828,3.00113117694855,39882.9609375,1.71727346016514,0.000157899823553996
3844416541.8025,2.99795782566071,40182.921875,1.72570648194986,0.000161193529120626
3844416561.6855,2.99831581115723,40479.447265625,1.7340884386764,0.000173201770084358
3844416581.66,2.99518728256226,40780.064453125,1.7420786726028,0.000158102669036445
3844416601.873,3.00207507610321,41084.025390625,1.74998815749981,0.000175890445691582
3844416621.6635,3.0015252828598,41380.197265625,1.75776154034379,0.00017621997714332
3844416641.762,3.00113618373871,41681.49609375,1.76559398358543,0.000171906771717889
3844416661.656,2.99590599536896,41979.80859375,1.77340854814804,0.000168319387283534
3844416681.6105,3.00005125999451,42279.974609375,1.78035753624017,0.000167389913810855
3844416701.64,3.00085020065308,42579.91796875,1.78760400535184,0.000167109870855636
3844416721.593,3.00403690338135,42879.177734375,1.79497730411159,0.000180366587867627
3844416741.512,2.99899518489838,43177.193359375,1.80222188230169,0.00016446061245572
3844416761.5675,2.99632620811462,43478.564453125,1.80952627001906,0.000161167865109553
3844416781.5185,3.00133669376373,43777.369140625,1.81599593550503,0.000162161376882471
3844416801.6225,2.99889934062958,44078.6640625,1.82294328385863,0.000172004429892915
3844416821.499,3.00788652896881,44377.916015625,1.82928788121003,0.00017652216036786
3844416841.6155,3.00302493572235,44679.3984375,1.83576325199991,0.0001580228277961
3844416861.5205,3.00148439407349,44977.40625,1.84272247031479,0.000173550761844601
3844416881.4145,3.00353014469147,45275.93359375,1.84859843888962,0.00016489906192199
3844416901.448,2.99791371822357,45576.34375,1.85465253451141,0.000174487129868762
3844416921.423,3.00309801101685,45876.103515625,1.86115059175347,0.000167092955605607
3844416941.3715,3.00286400318146,46175.23828125,1.86686300798005,0.000164619071001426
3844416961.38,2.99998581409454,46475.455078125,1.87270545924848,0.0001609352015463
3844416981.3805,2.99756479263306,46775.353515625,1.87902118441804,0.00017116294707557
3844417001.499,3.00008845329285,47077.9375,1.88475884693472,0.000166890938515795
3844417021.3355,3.00279808044434,47374.970703125,1.8901886197759,0.000174806846354749
3844417041.3525,2.99977660179138,47675.3515625,1.89589069557637,0.000176217435975577
3844417061.2845,2.99763345718384,47974.603515625,1.90135760033689,0.000179129482490417
3844417081.345,3.0006023645401,48275.087890625,1.90649812006051,0.000176064249022209
3844417101.274,3.00094187259674,48574.4921875,1.91194082794727,0.000170205082616059
3844417121.277,3.00273191928864,48874.7421875,1.91728438816121,0.000178748302313364
3844417141.385,3.00091421604156,49176.193359375,1.92246443582499,0.000171641977116332
3844417161.234,2.99946236610413,49473.943359375,1.9274048317344,0.0001626021089432
3844417181.347,3.00038743019104,49775.439453125,1.93223181506349,0.000169846713823508
3844417201.227,2.99902164936066,50074.525390625,1.93710989396354,0.000159039160362332
3844417221.4135,2.99901759624481,50377.201171875,1.94205698665558,0.000175144347871223
3844417241.249,3.0005179643631,50674.7890625,1.94677453656203,0.000171271903902398
3844417261.132,2.99819791316986,50972.248046875,1.95114941763302,0.000164763180912761
3844417281.167,2.99473249912262,51273.744140625,1.95608251391962,0.00018241317497341
3844417301.1915,2.99738109111786,51573.11328125,1.96011804153205,0.00017302142040021
3844417321.094,2.9957423210144,51871.603515625,1.96536715517111,0.000183672020652031
3844417341.138,2.99895668029785,52173.880859375,1.9693290203108,0.000165505955084242
3844417361.2315,3.00202262401581,52474.611328125,1.97366550833403,0.000162089540331805
3844417381.0695,3.0009263753891,52772.470703125,1.97847935405442,0.000174106194217097
3844417401.0255,2.99728584289551,53071.689453125,1.98234331461027,0.000174275922949095
3844417421.0465,3.00034499168396,53372.220703125,1.98686078907321,0.00017194900802147
3844417441.0505,2.99733114242554,53672.626953125,1.99078144774828,0.000183544983546973
3844417460.9925,2.99736857414246,53970.9765625,1.99476497836125,0.000158267076475322
3844417481.024,3.00175893306732,54271.908203125,1.99871254563061,0.000142313933669879
3844417501.015,2.99605119228363,54571.853515625,2.00257272872767,0.000140805787037949
3844417520.9835,2.99780285358429,54871.314453125,2.00673879961612,0.000174608259805369
3844417541.0255,3.00328922271729,55171.908203125,2.0104517173755,0.000142886118364474
3844417560.9245,3.00125169754028,55470.44921875,2.01401713289749,0.00015571707141979
3844417580.9695,3.00413072109222,55770.39453125,2.01810315429647,0.000189620012912831
3844417600.984,3.00168573856354,56070.853515625,2.02185574576626,0.000193901737824275
3844417620.898,2.99961316585541,56369.375,2.02530823656303,0.000156321517895869
3844417641.0365,3.00126898288727,56670.9609375,2.02921610792683,0.000156486125720442
3844417660.8545,2.99754512310028,56969.619140625,2.03268721230215,0.000178179705431192
3844417680.8585,2.99586081504822,57269.9453125,2.03590210961027,0.000169721546317909
3844417700.8315,3.0040043592453,57569.517578125,2.03988684051145,0.000171051946999648
3844417720.8415,2.99645483493805,57870.373046875,2.04312178745303,0.000161969558817899
3844417740.84,3.00542151927948,58170.052734375,2.04671558660037,0.00018567915686531
3844417760.7595,3.00167310237885,58468.720703125,2.04971279128287,0.000197661248957566
3844417780.856,3.00300061702728,58769.908203125,2.05303628669033,0.000208530131315047
3844417800.876,2.99837553501129,59070.486328125,2.0566268196901,0.000178543018577764
3844417820.7735,2.99920296669006,59368.544921875,2.05942530473234,0.00018781958185026
3844417840.8525,2.99762535095215,59670.673828125,2.06281742759718,0.00019639359789139
3844417860.85,2.99994969367981,59970.7421875,2.06601453473795,0.000178385646138031
3844417880.834,3.00576329231262,60269.849609375,2.06916152763157,0.000167780484776497
3844417900.6465,2.9930431842804,60567.001953125,2.0724006473414,0.000163112346270866
3844417920.773,2.99463677406311,60869.3125,2.07529046300719,0.000177293244336685
3844417940.623,2.99738430976868,61166.8125,2.07839563250829,0.000187410095422026
3844417960.617,2.99680662155151,61466.4453125,2.08147265214375,0.000189368018137134
3844417980.7225,2.99694561958313,61767.6640625,2.08456724902174,0.000193937041345581
3844418000.717,2.99837851524353,62067.9453125,2.08763564967466,0.000186028678347942
3844418020.65,2.99569535255432,62367.044921875,2.09040035010127,0.000167832233352142
3844418040.564,2.99859738349915,62665.328125,2.09320107236499,0.000183721733729346
3844418060.632,3.00086438655853,62965.92578125,2.09590190328585,0.000184094833455253
3844418080.595,3.00355291366577,63266.087890625,2.09853979102517,0.000174607280273292
3844418100.619,3.00318646430969,63566.087890625,2.10146826442003,0.000179565017225194
3844418120.5575,2.99550366401672,63864.88671875,2.10399987379809,0.00017335182239628
3844418140.6015,2.99859082698822,64165.48046875,2.10681438844756,0.000176632272891065
3844418160.615,3.00006604194641,64466.267578125,2.10955674268853,0.000188182956681813
3844418180.4655,2.99910879135132,64763.54296875,2.11217485472449,0.000162268581078021
3844418200.514,2.99351811408997,65064.1953125,2.11491146288463,0.000162744347143984
3844418220.513,3.00009489059448,65365.115234375,2.11743201871236,0.000172873429808127
3844418240.5205,3.00008285045624,65665.11328125,2.11987891077402,0.000211288166760991
3844418260.4285,2.99715828895569,65964.0078125,2.12264056129517,0.000177440727817297
3844418280.489,3.00259137153625,66264.109375,2.12547667270792,0.000191269834455277
3844418300.391,2.99792146682739,66562.46484375,2.12800028380092,0.000167138470409154
3844418320.5375,2.99864196777344,66865.45703125,2.13033932148537,0.000174376775020007
3844418340.455,2.99709403514862,67165.13671875,2.13280922641405,0.000178889979163046
3844418360.408,2.9978004693985,67464.33203125,2.13511707227464,0.000180935427778697
3844418380.3605,2.9977000951767,67763.03125,2.13737149933992,0.00017177520483281
3844418400.501,3.00133275985718,68066.05859375,2.14033607966129,0.000188180150146059
3844418420.462,2.99937343597412,68365.25,2.14262216352911,0.0001616657190545
3844418440.2625,2.99779295921326,68661.69140625,2.14485312812548,0.000163819322198229
3844418460.339,3.00125229358673,68962.51953125,2.14685985861803,0.000175896888683233
3844418480.2645,3.00409770011902,69261.2421875,2.14945599076939,0.000198234618800305
3844418500.2735,3.00237536430359,69561.91796875,2.15177107787804,0.000189112812056415
3844418520.198,3.0014032125473,69860.67578125,2.15416392883733,0.000202795660735243
3844418540.2385,3.00287389755249,70161.2265625,2.15614743821213,0.000171532353589126
3844418560.1895,2.99958431720734,70461.31640625,2.15844633585944,0.000186464702900763
3844418580.1655,2.99921882152557,70760.45703125,2.16042051708823,0.000182631588266911
3844418600.17,3.00059866905212,71060.609375,2.1625263179553,0.000180530125184546
3844418620.1165,3.00312685966492,71360.53515625,2.16511103295466,0.000164391166175567
3844418640.1075,3.00018084049225,71659.30078125,2.16697254268634,0.000158714048454735
3844418660.239,2.9993691444397,71961.20703125,2.16927767482382,0.000186966317719251
3844418680.145,3.0006594657898,72259.96484375,2.17120093317201,0.000177429131320125
3844418700.0875,3.00138521194458,72559.3828125,2.17330413135133,0.000191608114508799
3844418720.121,3.00268566608429,72860.08203125,2.17557929268156,0.000198864888778055
3844418740.064,2.99854469299316,73160.390625,2.17793049412173,0.000183604112496512
3844418760.055,3.00165462493897,73460.56640625,2.17980232667462,0.000178402416427102
3844418780.104,2.99640047550201,73760.953125,2.1819627315365,0.000166035077125623
3844418800.141,2.9993668794632,74061.859375,2.183620777888,0.000154067995672063
3844418820.0605,3.00230193138123,74360.125,2.18578069822125,0.00017795264905074
3844418840.0605,3.00131857395172,74661.01171875,2.18802003485635,0.000201878087997551
3844418860.0995,3.00192594528198,74962.1953125,2.18967761219142,0.000189260463050241
3844418879.959,2.99850797653198,75259.0390625,2.1918596958501,0.000186197563061656
3844418900.113,3.00016462802887,75562.046875,2.1937669416788,0.000177453502368158
3844418920.079,3.00178444385529,75861.24609375,2.1960187977788,0.000178441418691886
3844418939.9365,3.00012385845184,76159.78125,2.19753681172094,0.000191594519777466
3844418959.9965,2.99650430679321,76460.6328125,2.19946257725156,0.00017056589492777
3844418980.0215,3.00048017501831,76760.46875,2.20152370251987,0.000195295655516326
3844418999.9435,2.99897181987762,77059.26171875,2.20299378973229,0.000172996130174667
3844419019.8235,2.99582409858704,77356.98828125,2.20481445943502,0.000209093906297822
3844419040.0205,3.00305330753326,77659.95703125,2.2067340851753,0.000160310026196207
3844419059.8395,3.0063716173172,77956.83203125,2.20886891492637,0.000187417169359696
3844419079.8285,2.99987971782684,78257.15234375,2.21062991071473,0.000201150103434427
3844419099.7795,2.99946928024292,78556.19140625,2.21202297241549,0.000207829796095468
3844419119.849,2.99825513362885,78857.203125,2.21431927213174,0.000186446231227245
3844419139.849,3.00336611270905,79157.39453125,2.21600798919621,0.000186996437987812
3844419159.791,3.00089991092682,79456.66796875,2.21747560924505,0.00018136952481759
3844419179.811,2.99852740764618,79756.49609375,2.21914442204588,0.000165564793426992
3844419199.8685,2.99353814125061,80057.25390625,2.22124819257838,0.000184858282229481
3844419219.682,2.99578237533569,80355.2890625,2.22266580353395,0.000184870677045475
3844419239.699,3.00319111347198,80655.2890625,2.22462567062159,0.000182085308769313
3844419259.68,2.99779951572418,80955.69140625,2.22632631500023,0.000198288333836543
3844419279.7575,2.99494481086731,81256.4765625,2.22802886604109,0.000189437673635204
3844419299.7275,3.00066590309143,81556.84765625,2.22997720683334,0.000196967344247627
3844419319.7225,3.00206315517426,81856.83984375,2.23146041145311,0.000204039579574309
3844419339.6855,3.00223636627197,82156.08984375,2.23298181370533,0.000164456542325399
3844419359.762,2.99896240234375,82456.8671875,2.23447069887782,0.0001686603214765
3844419379.683,3.00057768821716,82755.515625,2.2363834128405,0.000202135268130194
3844419399.7315,3.00340473651886,83056.93359375,2.23786145361893,0.000241880389239276
3844419419.5485,3.00387322902679,83353.73046875,2.23959327164274,0.00017771192875173
3844419439.512,3.00120007991791,83652.86328125,2.24077627461945,0.000193712807022675
3844419459.6795,3.00084233283997,83955.18359375,2.24249568024992,0.000177597957424911
3844419479.5255,2.99817514419556,84253.046875,2.24396813345338,0.000191592426903523
3844419499.4635,2.99664962291718,84552.9296875,2.24572602247822,0.000207790014444015
3844419519.6165,2.99675691127777,84854.71484375,2.24674535427376,0.000199722621366094
3844419539.488,2.99785137176514,85152.3203125,2.24874049445148,0.000190392816218771
3844419559.4335,3.00252151489258,85451.703125,2.25013702273904,0.000186313341689943
3844419579.606,3.00273585319519,85754.671875,2.25161267433528,0.000177905492358875
3844419599.5395,2.99658489227295,86053,2.25355101509887,0.000170669432102443
3844419619.3765,3.0006982088089,86350.8046875,2.25488901754129,0.000189916004193295
3844419639.572,3.00041580200195,86653.8671875,2.25600930447615,0.000192717321332402
3844419659.357,3.00011312961578,86950.9453125,2.25765007182024,0.000187855492788796
3844419679.3425,3.00486361980438,87250.2578125,2.25894799665303,0.000197945222316604
3844419699.406,2.99970901012421,87551.703125,2.26052833829605,0.000191033839260689
3844419719.51,3.00144588947296,87853.29296875,2.26245776333438,0.000199083140717551
3844419739.4745,3.00261735916138,88153.72265625,2.26330390954058,0.0002022838961069
3844419759.4045,2.99680972099304,88452.35546875,2.26478022137161,0.000176036860453635
3844419779.319,3.00010645389557,88751.0234375,2.266628327134,0.000202279974396108
3844419799.253,2.99979710578918,89050.41796875,2.26790280610405,0.000191574906990156
3844419819.2695,2.99805283546448,89350.98828125,2.26925052757433,0.000196175787258839
3844419839.2505,2.99958217144012,89651.76953125,2.27071613879621,0.000201152026054742
3844419859.299,3.001593708992,89951.421875,2.27211006857307,0.000176720899364232
3844419879.2675,3.00199162960052,90250.5546875,2.27345566748863,0.000195444832276792
3844419899.2605,3.00042331218719,90550.66796875,2.27491843324688,0.000193475189492745
3844419919.1925,2.99943697452545,90850.1953125,2.27604246683661,0.000194690730868188
3844419939.1505,3.00063192844391,91149.4375,2.27739999622916,0.000189900366500845
3844419959.296,2.99570000171661,91451.6953125,2.27885802443115,0.000192808932579086
3844419979.164,3.0051600933075,91749.078125,2.28007679574867,0.000196590609482338
3844419999.316,2.99562585353851,92052.4609375,2.28181495121245,0.000192413546248383
3844420019.1295,3.00456309318542,92349.2890625,2.28294281096654,0.000186668980289178
3844420039.0785,3.00271499156952,92647.95703125,2.28401852804527,0.000198833757508949
3844420059.1125,2.99833941459656,92947.7578125,2.28562685205245,0.000196692175080562
3844420079.2215,2.9976589679718,93250.33984375,2.28658020714058,0.000185166265790952
3844420099.1385,2.99819111824036,93548.796875,2.28776101051896,0.000212920009686811
3844420119.015,2.99929749965668,93848.296875,2.28923829792893,0.00019222686565426
3844420139.199,2.99562478065491,94150.6328125,2.29064307749277,0.000182537779468235
3844420159.027,2.99882698059082,94448.66015625,2.29169942705828,0.000239988927349174
3844420179.172,2.99845910072327,94751.1171875,2.29297239253704,0.000180422535488212
3844420199.0175,3.00124824047089,95048.859375,2.29444988798073,0.000207076061303975
3844420218.9515,2.99932217597961,95347.3515625,2.29530659311661,0.000192001718575397
3844420239.0845,2.9971410036087,95649.734375,2.29641167862561,0.000160977856206877
3844420258.8995,3.00212943553925,95947.92578125,2.29769939426624,0.000185597160896407
3844420279.064,2.99654448032379,96250.30078125,2.29961111455433,0.000226421012748069
3844420299.007,3.00147104263306,96549.80859375,2.30017545330766,0.00022045976971343
3844420318.9135,3.00234317779541,96848.1640625,2.30183089086352,0.000189372074060607
3844420338.933,3.00357675552368,97148.375,2.30292076097239,0.000201969421787117
3844420358.975,2.9979681968689,97449.140625,2.30365315596124,0.000204842507842218
3844420378.9115,2.99478244781494,97747.8359375,2.3052297682349,0.00021334071862269
3844420398.8345,2.99735462665558,98046.34765625,2.30641888681411,0.000164304823507898
3844420418.8305,3.00240576267242,98347.03515625,2.30708311660696,0.000203884522960408
3844420438.781,3.00100493431091,98645.51171875,2.30889856128773,0.000188525441581553
3844420458.9055,2.99819362163544,98947.54296875,2.30967700708039,0.000199962635990752
3844420478.887,3.00305807590485,99247.89453125,2.31118386407325,0.000191484221143881
3844420498.921,3.00424063205719,99548.4921875,2.31168447262533,0.000198773215236197
3844420518.7115,2.99705064296722,99844.7734375,2.3132036609783,0.000183542852269571
3844420538.728,3.00005304813385,100145.69921875,2.31434295286906,0.000204402880965936
3844420558.8,2.99678218364716,100445.88671875,2.31568388373211,0.000187323208058763
3844420578.7745,2.99831199645996,100746.03515625,2.31665233718802,0.000191879224203919
3844420598.6975,3.00106513500214,101045.70703125,2.31771293378317,0.000208234380419498
3844420618.7505,3.00119113922119,101345.77734375,2.31896439162925,0.000182057106350923
3844420638.6625,2.99594914913177,101644.671875,2.31995441161769,0.000207448570978837
3844420658.6015,3.00078237056732,101943.953125,2.32094626920727,0.000198606206497877
3844420678.707,3.00427198410034,102246.5234375,2.32208105879944,0.000186501829516483
3844420698.6545,3.00037205219269,102545.3671875,2.323175419202,0.000199056830400451
3844420718.713,3.00601661205292,102846.8125,2.3240549929766,0.000196678720243188
3844420738.569,3.00317180156708,103144.4921875,2.32587318089326,0.000182128016246092
3844420758.67,3.0081946849823,103446.08203125,2.32642278994697,0.000206893838061071
3844420778.528,3.00137388706207,103744.0390625,2.32714191614647,0.000211439088677276
3844420798.595,3.00062918663025,104044.6875,2.32889033644878,0.000184266537951425
3844420818.574,3.00042176246643,104344.45703125,2.32989292281216,0.000211867508798665
3844420838.4905,2.99635744094849,104642.82421875,2.33068246230054,0.000178883041602625
3844420858.5185,2.9997969865799,104943.64453125,2.33131655308894,0.000188760519033354
3844420878.6115,3.0000821352005,105244.90234375,2.33253045375096,0.000199608284931026
3844420898.4625,3.00813472270966,105541.5703125,2.3334888217204,0.000224630285368224
3844420918.4895,3.00454223155975,105842.2109375,2.33463574771701,0.000195453863327099
3844420938.5615,3.00189614295959,106143.55078125,2.33554321838254,0.000185553638484193
3844420958.4215,3.00231397151947,106441.90234375,2.33669347422577,0.000201058300788545
3844420978.531,3.00088167190552,106743.41015625,2.33752722397224,0.000209995560290166
3844420998.371,3.00392138957977,107040.55078125,2.33835791740781,0.000208784637593083
3844421018.3525,3.00280714035034,107340.65625,2.33950862132999,0.000212717205657594
3844421038.4115,2.99801874160767,107641.78515625,2.34080866814299,0.000199286428150338
3844421058.388,2.99978423118591,107941.1171875,2.3416192753342,0.000194281830517206
3844421078.3415,2.99704658985138,108240.75390625,2.34266090102483,0.000199764526926199
3844421098.355,2.99978268146515,108540.1875,2.34340840305909,0.000192789270178342
3844421118.315,2.99838936328888,108840.57421875,2.34419343277489,0.000194554456651916
3844421138.4925,3.00005626678467,109143.6484375,2.34574278132378,0.000191450256244901
3844421158.2915,2.99637770652771,109440.78515625,2.34654237225802,0.0001929769319989
3844421178.2405,2.99982905387878,109740.34765625,2.34766958309825,0.000219170311233565
3844421198.401,2.99795949459076,110043.5234375,2.34839809781977,0.000199420459948848
3844421218.195,3.00105500221252,110339.96875,2.34900383713741,0.000183227884869087
3844421238.3395,3.00223517417908,110641.69140625,2.35028886127439,0.000221202103279912
3844421258.161,3.00114786624908,110938.9453125,2.35065177634132,0.000213450799162024
3844421278.2495,2.99920582771301,111240.421875,2.35206879880708,0.000186487313545002
3844421298.1375,3.00086033344269,111538.93359375,2.35310713977631,0.000224016118288858
3844421318.157,3.00633347034454,111838.74609375,2.35378437295552,0.00019021111830585
3844421338.123,3.00120460987091,112138.75390625,2.35445261782944,0.000190496942659923
3844421358.256,2.99725103378296,112439.9609375,2.35559022369127,0.000188541334185382
3844421378.2125,2.9990828037262,112740.140625,2.35624062863128,0.000188637398761905
3844421398.1555,2.99937343597412,113039.22265625,2.35721121417318,0.000194406657442466
3844421418.074,2.99833059310913,113337.25390625,2.35782741589464,0.000202939730249157
3844421438.192,3.00108087062836,113638.625,2.35907007728177,0.000202274215097891
3844421458.031,3.00117528438568,113936.27734375,2.35997235109588,0.000224955649424313
3844421478.0065,3.00041520595551,114236.4609375,2.36071070912271,0.000196630515775745
3844421498.1185,3.00215089321136,114538.0546875,2.36134167321006,0.00021611993266116
3844421517.9685,2.99981701374054,114836.87109375,2.36275528102675,0.000223781534028449
3844421538.047,2.99802553653717,115138.49609375,2.36343856223618,0.000202991304780354
3844421557.9745,2.9986469745636,115437.234375,2.3645383436855,0.000227074976867411
3844421578.0535,3.00347661972046,115738.84375,2.36497742218649,0.00020360960827303
3844421597.936,2.99915325641632,116036.40625,2.36619531300111,0.000202677330124898
3844421618.0495,2.99591791629791,116338.65625,2.36703471023469,0.000198634271415647
3844421637.9085,2.99922800064087,116636.88671875,2.36724888618713,0.000204699471605572
3844421657.993,3.00055289268494,116938.51171875,2.36821745584418,0.000186565491528573
3844421677.907,2.99792790412903,117236.4375,2.36909652110955,0.000191794747023905
3844421697.8325,3.0027734041214,117535.82421875,2.36996313411303,0.000182513501222218
3844421717.9175,3.00097155570984,117837.4296875,2.37079531966491,0.000193697494762048
3844421737.8815,2.99915051460266,118137.17578125,2.37173572925221,0.000194360517757216
3844421757.912,3.00077712535858,118437.8125,2.37215378187863,0.000208867403127416
3844421777.974,3.00117492675781,118738.171875,2.37341109767702,0.000213225910665934
3844421797.8925,3.00405740737915,119037.96875,2.37419920636108,0.000217014563882723
3844421817.8065,2.99878489971161,119335.91015625,2.37503213571991,0.000226184377322846
3844421837.844,2.99817299842834,119636.3125,2.37567223917291,0.000182537763262094
3844421857.7705,2.99790811538696,119934.96875,2.37664382348758,0.000204842682200194
3844421877.8425,3.00105750560761,120236.33203125,2.37743022432968,0.000196883206771934
3844421897.7785,3.00228703022003,120535.3203125,2.37818433588193,0.00019198863019934
3844421917.745,2.99974310398102,120835.16796875,2.37907886154012,0.000214297690714841
3844421937.698,2.9994124174118,121133.41015625,2.37936568263047,0.000206469733359751
3844421957.684,2.99498856067657,121433.1484375,2.38039770063918,0.000217247828232322
3844421977.6595,2.99835622310638,121732.44140625,2.38106772238173,0.000208492169016552
3844421997.7565,3.00156605243683,122034.2734375,2.38179583670186,0.000354102924810862
3844422017.6745,3.0004962682724,122333.4453125,2.38250287191428,0.000420559135824253
3844422037.71,3.00390434265137,122633.921875,2.38314822941144,0.000219597836142576
3844422057.5785,3.00402915477753,122932.515625,2.38363988546133,0.000167139232017655
3844422077.626,3.00232565402985,123232.94921875,2.38445366301252,0.000204069406741143
3844422097.551,3.0013233423233,123532.87109375,2.38555946264766,0.000215219938421385
3844422117.542,3.00064742565155,123831.94921875,2.38630441657305,0.000196478309118435
3844422137.6,3.00204706192017,124132.66796875,2.38697410214485,0.000200656868035182
3844422157.5025,3.00102519989014,124431.51171875,2.38755158304107,0.000214397296345192
3844422177.5875,2.99480092525482,124733.1640625,2.38848844215529,0.000211878056608694
3844422197.479,2.99957323074341,125031.63671875,2.3890249039656,0.000216013561618291
3844422217.534,3.00178182125092,125333.27734375,2.38972216421412,0.000185094120872561
3844422237.4835,2.9988522529602,125631.98046875,2.3903173129019,0.000227657382344283
3844422257.4685,3.00025546550751,125932.45703125,2.39099326822426,0.000204308469360286
3844422277.4595,2.99739503860474,126232.78515625,2.39188014757447,0.000194169178096463
3844422297.562,2.99957716464996,126533.69921875,2.39255437183723,0.000206286173263693
3844422317.417,3.00426816940308,126831.2578125,2.3930937316688,0.000191009517344058
3844422337.458,2.99458289146423,127132.24609375,2.39407398143456,0.000193450112543166
3844422357.3745,2.99849915504456,127430.4921875,2.39413514044662,0.000212594005101482
3844422377.475,3.00090444087982,127731.7734375,2.39562322223137,0.000207213459813331
3844422397.419,3.00053763389587,128030.78125,2.39600615201788,0.000190104786210133
3844422417.4675,2.9998631477356,128331.5546875,2.39655839626738,0.000216752168532561
3844422437.3135,2.99869406223297,128629.875,2.39729515632431,0.000197577811508423
3844422457.448,3.00054383277893,128931.140625,2.39763424520886,0.000220059721925766
3844422477.3985,2.99400770664215,129230.171875,2.39837104473283,0.000199470411593863
3844422497.266,3.00745403766632,129528.6953125,2.39951808213671,0.00019260590101653
3844422517.2385,2.99927282333374,129828.37890625,2.39994892214168,0.000187377718290535
3844422537.3405,2.99492883682251,130129.80859375,2.40064918277554,0.000194181592024098
3844422557.262,2.99950230121613,130429.2578125,2.4010591310914,0.000200755351428702
3844422577.308,2.9993554353714,130729.36328125,2.40169601078928,0.000177580038971669
3844422597.2795,3.0013120174408,131029.68359375,2.4021499221173,0.000212606664162075
3844422617.298,3.00194907188416,131330.671875,2.40310910535626,0.000209120315288139
3844422637.1865,3.00074589252472,131628.0546875,2.40360361793959,0.000224927690235818
3844422657.202,3.00071918964386,131928.2265625,2.40450551496074,0.000210804481414
3844422677.2445,2.99956107139587,132229.9921875,2.40521485067808,0.000214016075090582
3844422697.14,3.0007449388504,132527.8984375,2.40596087295207,0.000183277605333135
3844422717.2155,3.00233900547028,132829.59375,2.40615292943776,0.000212300736940048
3844422737.1155,3.0022714138031,133128.7578125,2.40687424413452,0.000199741773439853
3844422757.1515,3.00337171554565,133429.0078125,2.40759411439451,0.000236162541018656
3844422777.166,2.99988269805908,133728.515625,2.40835176835794,0.000219273662696236
3844422797.0335,2.99939894676209,134027.0234375,2.40855333851291,0.000226958566637491
3844422817.0495,3.00071179866791,134326.96875,2.40917244687941,0.00020138523667101
3844422837.015,2.99671065807343,134626.21875,2.40996353467979,0.000295060986144633
3844422857.003,2.99949908256531,134927.359375,2.41063502091124,0.00025887046598595
3844422877.038,3.00144743919373,135228.140625,2.4113740292302,0.000242578250086724
3844422897.0365,3.00359654426575,135529.25,2.4118311578247,0.000239600591116134
3844422917.0435,2.9975209236145,135828.3828125,2.4123117877666,0.000237202032824773
3844422936.926,2.99911499023438,136126.703125,2.41288022592874,0.000278297339770256
3844422956.915,3.00047278404236,136426.6640625,2.41346991855842,0.000224616330200716
3844422976.9145,3.00105237960815,136726.3046875,2.41378703001581,0.000227469833773627
3844422997.1115,2.99612677097321,137028.6796875,2.41464899692573,0.000251188861083997
3844423016.909,3.00029683113098,137325.390625,2.41517819844007,0.000207482908318249
3844423036.869,3.00173592567444,137625.25,2.41562680055094,0.000237792368181172
3844423056.862,3.00268137454987,137924.328125,2.4158972105769,0.000219016945496994
3844423076.891,2.99725186824799,138225.1796875,2.41674069345811,0.000357819357106109
3844423096.951,2.99852132797241,138525.7890625,2.41718837824372,0.000226735913107245
3844423116.8245,2.99942636489868,138824.6171875,2.41775242158554,0.000464872221221448
3844423136.785,3.00158762931824,139123.015625,2.41851241161766,0.000351024408994568
3844423156.854,2.99756813049316,139423.4140625,2.41890266250898,0.000199356239777898
3844423176.746,3.00146675109863,139722.71875,2.41938445608671,0.000379317133694492
3844423196.7465,3.00085210800171,140022.828125,2.41984493793248,0.000491128378433018
3844423211.8105,3.00090074539185,140001.9921875,2.4205454055034,0.000284061729053601