File: MvsH/2021-10-25_EROI_34P8MG_MVSH_5P0K.DAT
Time Stamp (sec),Temperature (K),Magnetic Field (Oe),Moment (emu),M. Std. Err. (emu)
3844424925.525,4.9939536510594,-0.0711120069026947,,
3844425025.4955,5.00026845932007,-4847.14404296875,-0.23805784903893,7.82862534964742E-5
3844425045.4545,5.00289154052734,-4548.09619140625,-0.22354334103646,7.51177704164023E-5
3844425065.3575,4.99678802490234,-4248.88305664063,-0.209057298645664,7.77658804011723E-5
3844425085.3305,5.00142598152161,-3950.10681152344,-0.194454627712772,7.53813748905079E-5
3844425105.3845,4.99876618385315,-3649.6181640625,-0.179931406252598,7.49911301035264E-5
3844425125.312,4.99959254264832,-3350.52844238281,-0.165353575151851,7.7978198258447E-5
3844425145.281,5.00127625465393,-3051.11779785156,-0.150674442920055,7.47893258422919E-5
3844425165.333,5.00164937973022,-2750.50061035156,-0.136018859951859,7.76250686987673E-5
3844425185.398,5.00258946418762,-2449.85095214844,-0.12136880016102,7.57872216102275E-5
3844425205.244,5.0006639957428,-2152.21765136719,-0.106676601506788,7.63814175973939E-5
3844425225.3605,4.99825239181519,-1849.79498291016,-0.0919724627712936,7.67461788277009E-5
3844425245.224,4.99976801872253,-1552.17358398438,-0.0772506929763855,7.5809125559412E-5
3844425265.2285,4.99864816665649,-1252.63409423828,-0.062522242490152,7.52615423741997E-5
3844425285.243,4.99920606613159,-952.098052978516,-0.0477976306525224,7.47968929013601E-5
3844425313.2635,4.99884271621704,-532.865783691406,-0.029344511069637,7.52252496463835E-5
3844425330.2815,4.99994993209839,-277.307968139648,-0.014599820311545,7.5524190390138E-5
3844425358.4475,5.00307369232178,144.487487792969,0.00390777164254367,7.56994764467341E-5
3844425380.547,5.00358891487122,475.927749633789,0.0224335872540695,7.53236401112893E-5
3844425400.1335,4.99828696250916,770.867004394531,0.0372397256382269,7.54912697099188E-5
3844425420.065,4.99918937683105,1069.21759033203,0.0520233122286546,7.56548991118496E-5
3844425440.2065,4.9977765083313,1371.09362792969,0.0667929117711159,7.59498312091134E-5
3844425460.087,5.0008237361908,1668.67828369141,0.0815232167489155,7.62930973083197E-5
3844425480.076,5.00146055221558,1968.63439941406,0.0962953993749864,7.61157257016036E-5
3844425505.1425,5.0012264251709,2345.1162109375,0.114715129113853,7.5122543130339E-5
3844425525.11,4.99886393547058,2644.3466796875,0.129419850388268,7.7186321979204E-5
3844425545.097,4.99956774711609,2944.16748046875,0.144071055595053,7.50725638008492E-5
3844425565.014,4.99867510795593,3242.67248535156,0.158660207933072,7.68217200303914E-5
3844425585.0035,4.99855041503906,3542.63879394531,0.173319506097273,7.45219571366141E-5
3844425604.9465,5.00100016593933,3841.8310546875,0.18788545079568,7.68815943220428E-5
3844425624.918,5.00222373008728,4140.662109375,0.202389036987499,7.60641481803521E-5
3844425645.031,5.00176000595093,4442.83129882812,0.216906730263566,7.88088289553845E-5
3844425665.0595,4.99805212020874,4743.0322265625,0.231325997221864,7.9145270312544E-5
3844425684.986,5.0002019405365,5042.19287109375,0.245759488103613,7.82379981019173E-5
3844425704.9145,4.99713754653931,5340.80541992188,0.260147343126198,7.60637128107063E-5
3844425724.858,5.00267934799194,5639.86157226562,0.274427775560698,7.8760407900216E-5
3844425744.9435,4.9990758895874,5941.59741210937,0.288796714956962,7.85268004378836E-5
3844425764.8135,4.99756550788879,6239.94091796875,0.302997173707627,7.74329951743684E-5
3844425784.807,4.99943733215332,6538.86767578125,0.317196013758303,7.82070866995077E-5
3844425804.7985,5.00016331672668,6838.80859375,0.331324277997101,7.95522643083315E-5
3844425824.9695,4.99662637710571,7141.083984375,0.345517756440436,8.06688074874308E-5
3844425844.798,5.00024652481079,7439.61694335938,0.359405571687241,7.39471820409634E-5
3844425864.9135,5.00220203399658,7741.02075195313,0.373407292812469,7.79819502015501E-5
3844425884.7385,5.00019812583923,8038.15014648438,0.387337896066479,7.97180673799818E-5
3844425904.7235,5.00235962867737,8338.0634765625,0.401290199422719,7.96529899826681E-5
3844425924.7065,4.9993634223938,8637.4365234375,0.415110514063999,8.06683262073877E-5
3844425944.7245,5.00061273574829,8937.943359375,0.428938692918419,7.6760366270411E-5
3844425964.7255,5.00083303451538,9237.568359375,0.442765525271511,8.00315288449946E-5
3844425984.696,4.99793672561646,9537.484375,0.456347612265692,8.0734224281905E-5
3844426004.747,5.00131392478943,9838.44775390625,0.470136585841962,8.35427201498115E-5
3844426024.643,4.9968900680542,10136.875,0.483761547879711,8.0268916081285E-5
3844426044.6495,5.00079131126404,10437.279296875,0.497211273509682,8.62205109005282E-5
3844426064.703,4.99884605407715,10738.3452148438,0.510668957991049,8.35307959364126E-5
3844426084.629,5.00001931190491,11037.69140625,0.524210623373489,8.42088379537061E-5
3844426104.6235,4.99873185157776,11336.9223632813,0.537639396833289,9.0889497719377E-5
3844426124.5495,4.99838900566101,11635.9287109375,0.550974211640315,8.80402235569175E-5
3844426144.613,4.99996519088745,11936.3452148438,0.564274607526474,8.88896232477339E-5
3844426164.6475,4.99953985214233,12237.0131835938,0.577299990895715,8.69800430924072E-5
3844426184.5705,5.00211429595947,12536.486328125,0.590647437539133,8.51654247892155E-5
3844426204.5205,5.00098919868469,12835.6396484375,0.603746840384844,8.70573985049989E-5
3844426224.548,4.99877762794495,13135.5864257813,0.616797366514822,9.05702077145897E-5
3844426244.6605,5.00135588645935,13437.1000976563,0.629884172195024,9.29457243100809E-5
3844426264.5005,4.99959826469421,13735.0268554687,0.642827944483512,8.6076185486443E-5
3844426284.528,4.99941515922546,14035.7612304687,0.655838697412225,9.4319346315229E-5
3844426304.4295,4.99988746643066,14333.912109375,0.668589144728253,8.74224057776595E-5
3844426324.5755,4.99790334701538,14635.912109375,0.68140829388975,9.57389037274539E-5
3844426344.509,5.00207567214966,14934.4677734375,0.694156800560529,9.55444363057646E-5
3844426364.5045,5.00240063667297,15235.1767578125,0.706776464879077,9.17833195028208E-5
3844426384.38,5.00013136863708,15532.8198242187,0.719535858460118,9.14223115774239E-5
3844426404.3875,4.99869918823242,15833.2006835938,0.732114078689118,8.39668523003681E-5
3844426424.4245,4.99966073036194,16133.7778320313,0.74479745985075,9.68443008316593E-5
3844426444.4645,5.00085878372192,16434.8115234375,0.757144806828927,9.38623880434084E-5
3844426464.327,4.99945092201233,16732.2919921875,0.769728484682192,9.42279754218133E-5
3844426484.319,5.00362777709961,17032.0830078125,0.782069485544431,0.000101710527385209
3844426504.474,4.99976992607117,17334.154296875,0.794451481704587,8.9993731857358E-5
3844426524.251,4.99990606307983,17630.5927734375,0.806726588732099,0.00010682104783754
3844426544.4155,5.00046968460083,17933.5478515625,0.819090753095037,0.000101063973002884
3844426564.227,4.99938654899597,18230.390625,0.831553678891496,9.72311953598272E-5
3844426584.353,5.00041627883911,18532.6533203125,0.843519661178352,0.000102445978323076
3844426604.401,5.00182867050171,18833.4931640625,0.855663806373715,9.72116590880405E-5
3844426624.1875,4.99797320365906,19129.560546875,0.867750842866556,9.87154707348885E-5
3844426644.1815,4.9995424747467,19430.2939453125,0.879935214426061,0.00010840746590602
3844426664.151,5.00206780433655,19729.36328125,0.891748186226816,0.000101149957531119
3844426684.2615,4.99890947341919,20030.8232421875,0.903979467032421,0.000111123425254739
3844426704.1345,5.00439119338989,20328.7138671875,0.915901397406402,9.67638743231154E-5
3844426724.1815,4.99589061737061,20629.978515625,0.927753798170892,0.000101743204089658
3844426744.202,5.00190877914429,20929.849609375,0.939671246678221,0.000101141469102496
3844426764.1175,5.00064730644226,21228.14453125,0.951602388155462,0.000106656444057323
3844426789.389,5.00295448303223,21607.8525390625,0.965935084892216,0.000115473261086089
3844426809.1095,4.99996876716614,21903.251953125,0.977671860451082,0.000110350290571335
3844426829.087,4.99869275093079,22202.919921875,0.989571505713864,0.00011857831025479
3844426849.01,4.99965953826904,22502.13671875,1.00123405827887,0.000112417470043923
3844426869.059,5.00119471549988,22802.10546875,1.01267221765768,0.000110386584563211
3844426889.053,5.00131726264954,23102.767578125,1.02432132315746,0.00011749579018712
3844426909.106,5.00111842155457,23403.6875,1.03578214779956,0.000106335366725818
3844426928.989,4.99900555610657,23701.4443359375,1.04733410250535,0.00011191151239952
3844426949.163,5.00343656539917,24004.45703125,1.05888309727065,0.000118861702535031
3844426968.971,5.00028944015503,24301.505859375,1.07038124786517,0.000113340151593855
3844426988.9445,4.99944663047791,24600.671875,1.08178531792274,0.000116906158150535
3844427008.969,4.99916315078735,24901.0185546875,1.09326752458123,0.000132956046777604
3844427028.887,5.00135517120361,25199.4072265625,1.10435675620952,0.000123069073460161
3844427049.026,4.99819898605347,25501.8173828125,1.11564552020614,0.00012633240210172
3844427068.899,5.0004894733429,25799.5029296875,1.1269137948461,0.000111434889726234
3844427088.8305,5.00099897384644,26098.7646484375,1.13803629978022,0.000118697433875873
3844427108.9695,5.00037026405334,26400.951171875,1.14919537349786,0.000116390292391542
3844427128.845,5.00028324127197,26699.46484375,1.16046094096735,0.000124939366061
3844427148.7785,4.99674916267395,26998.0537109375,1.171631095594,0.000126344482164124
3844427168.787,4.99856853485107,27297.712890625,1.18295830604083,0.000126087938447912
3844427188.8585,5.00142312049866,27598.091796875,1.19354042747521,0.00011981588067274
3844427208.7455,4.99816656112671,27897.1943359375,1.20439282979105,0.000120248215976939
3844427228.838,5.00032615661621,28198.1044921875,1.21521837670615,0.000121321926348995
3844427248.7715,4.99809288978577,28497.2294921875,1.22631080417146,0.000125363364223572
3844427268.8305,4.99756789207458,28798.052734375,1.23705244247355,0.000124642000598089
3844427288.8035,5.00124073028564,29097.9453125,1.24800554278894,0.000117572689508831
3844427308.8045,4.99905252456665,29398.2509765625,1.25915638210613,0.00013231231874053
3844427328.8555,5.00404620170593,29698.16796875,1.26957667773347,0.000124950999689365
3844427348.6405,5.00145792961121,29995.5703125,1.28064243401668,0.000128300647231285
3844427368.7345,4.99569082260132,30296.05078125,1.29118921087971,0.000117420203581331
3844427388.606,5.00199103355408,30593.8779296875,1.30172324083994,0.000131387083177306
3844427408.7155,5.00042223930359,30896.2490234375,1.31225354248336,0.000133773591874231
3844427428.642,4.99926686286926,31195.3896484375,1.32278422885575,0.000140006032257663
3844427448.6375,4.99945640563965,31495.578125,1.33338106387201,0.000136213235619556
3844427468.5885,4.99837851524353,31795.4833984375,1.34379774369911,0.000146924549876333
3844427488.6575,5.00136923789978,32096.3935546875,1.35416499385507,0.000140580741660154
3844427508.549,4.99725556373596,32394.6953125,1.36489422899973,0.000158249334164273
3844427528.674,5.00279092788696,32696.560546875,1.37477068890723,0.00012128038284606
3844427548.514,4.99915671348572,32993.578125,1.38536441544021,0.000143480308230767
3844427568.6735,5.00100898742676,33296.693359375,1.39572171146722,0.000129914366025652
3844427588.506,5.00085926055908,33593.615234375,1.40590180725798,0.0001346643309654
3844427608.4805,4.9987165927887,33893.689453125,1.41567313779322,0.000139063658675508
3844427628.4705,4.99956893920898,34193.521484375,1.42608664333969,0.000144673985163344
3844427648.4705,4.99897933006287,34493.625,1.43599150970464,0.00013800948296655
3844427668.583,5.0002269744873,34795.078125,1.44583454781316,0.000158054676788063
3844427688.4575,4.99867010116577,35093.541015625,1.45585262703296,0.000143462537889997
3844427708.3915,5.00246787071228,35391.560546875,1.4656166378888,0.000138036861347419
3844427728.442,5.00155663490295,35692.265625,1.47535358929357,0.000162658497838303
3844427748.3715,5.00092935562134,35991.67578125,1.48486905569064,0.000159455937244902
3844427768.363,5.00255036354065,36291.56640625,1.49447348665684,0.000134835529054368
3844427788.316,4.99917817115784,36591.224609375,1.50400297932283,0.000156906076589785
3844427808.4385,4.99718189239502,36892.65625,1.51388725345462,0.000140430740426219
3844427828.389,4.99698185920715,37192.095703125,1.5232912602835,0.000143261280721064
3844427848.2755,4.99941468238831,37491.185546875,1.53233953551429,0.000155221118360593
3844427868.3775,5.0005190372467,37792.330078125,1.54196132552952,0.000167168681826393
3844427888.3585,5.00055885314941,38091.341796875,1.5510118088755,0.00014641920395185
3844427908.3715,5.00019288063049,38391.373046875,1.56036496657961,0.000167156184611953
3844427928.211,4.99946475028992,38689.1796875,1.56937959354088,0.000151041168642156
3844427948.2605,4.9992196559906,38989.72265625,1.57808538543332,0.000150688503402397
3844427968.208,4.99782299995422,39289.048828125,1.58736393010411,0.00015625582014213
3844427988.243,5.0006787776947,39589.076171875,1.59616316279325,0.000147994764699738
3844428008.336,5.00206351280212,39891.41796875,1.60480309876652,0.000156123267933912
3844428028.2555,4.99939966201782,40189.98828125,1.61370845247882,0.00016002153133612
3844428048.152,4.99869871139526,40488.3203125,1.62220585375457,0.000166618772746427
3844428068.142,4.99905681610107,40788.33203125,1.63078612897281,0.000159200150544285
3844428088.0945,4.99818229675293,41087.970703125,1.63922939264578,0.000157417039354545
3844428108.165,4.99987554550171,41388.66796875,1.6477869761506,0.000166565790713814
3844428128.094,4.9995813369751,41687.87109375,1.65602915786375,0.000166076110961139
3844428148.2085,5.0008978843689,41989.96875,1.66396286809493,0.000166881750375669
3844428168.0325,4.99645757675171,42287.06640625,1.67234420154504,0.000160646600434851
3844428188.051,5.00017285346985,42587.2890625,1.68025490448043,0.000161189365751692
3844428208.013,4.99955320358276,42886.421875,1.68793677519007,0.000152211432640418
3844428228.2215,4.99612522125244,43189.896484375,1.69595755044179,0.000178369575902433
3844428248.038,5.00125575065613,43486.76171875,1.70341455505485,0.000178155584766186
3844428268.0365,5.00116443634033,43787.005859375,1.71094109737038,0.000158292607007437
3844428287.981,5.00035333633423,44086.302734375,1.71855622523745,0.000149839659283233
3844428308.077,5.00132274627686,44387.794921875,1.72574195069931,0.000164682546813572
3844428327.9635,4.99852299690247,44686.3203125,1.73315049675197,0.000171905238761158
3844428348.004,4.9986720085144,44986.365234375,1.74040614594443,0.000167325884721714
3844428367.9245,5.00128960609436,45285.62890625,1.74757328163225,0.000165522479277873
3844428388.003,5.00229358673096,45586.666015625,1.75459208746938,0.000173268476787658
3844428407.8505,5.00081491470337,45884.255859375,1.76175121381016,0.000177570917676244
3844428427.8745,5.00147199630737,46183.552734375,1.76857808348091,0.000168336860508745
3844428447.9345,4.99946260452271,46485.23828125,1.77525457016339,0.000176036263883686
3844428467.7985,4.9999828338623,46783.626953125,1.78220036035509,0.000170060066749887
3844428487.8345,4.99815583229065,47084.568359375,1.78878071725685,0.000173410130761128
3844428507.924,5.00020003318787,47385.294921875,1.79513486200848,0.000163024142262729
3844428527.781,5.00042986869812,47683.166015625,1.80157128940402,0.000181307797188493
3844428547.8485,4.99825739860535,47984.583984375,1.80825019726705,0.000170293854175624
3844428567.863,4.99997854232788,48284.451171875,1.8146892974347,0.0001853044900001
3844428587.869,5.00017476081848,48583.439453125,1.82069946384991,0.000170569197991452
3844428607.779,5.00187730789185,48882.7421875,1.82671217011327,0.000177516211203642
3844428627.8175,4.99949741363525,49183.416015625,1.83252727948129,0.000163856081578131
3844428647.86,4.99954032897949,49484.1171875,1.83873768575668,0.000159654419107352
3844428667.789,4.99974894523621,49783.46484375,1.84455177069816,0.000167918106841147
3844428687.7055,4.9987473487854,50081.734375,1.85050219960033,0.000184648739596351
3844428707.7095,5.00184535980225,50382.630859375,1.85629757725919,0.000185394760333414
3844428727.6605,4.99891114234924,50681.130859375,1.86200166604189,0.00015969920942758
3844428747.663,4.99932503700256,50981.5625,1.86721315304151,0.000179867273289002
3844428767.635,5.00098419189453,51280.775390625,1.87308649503704,0.00016839211365116
3844428787.592,5.00143074989319,51580.28125,1.87835797555156,0.000179718821877896
3844428807.657,4.99903607368469,51881.21484375,1.88407405761131,0.000171384779767683
3844428827.539,5.00032019615173,52180.916015625,1.88911134146907,0.000177253276075177
3844428847.5265,4.99981045722961,52480.798828125,1.89439513668378,0.000190339781486755
3844428867.5665,5.00003433227539,52782.025390625,1.89951334502588,0.000158361811009138
3844428887.621,4.99854278564453,53081.916015625,1.9047540534826,0.000184252423171598
3844428907.482,4.99994158744812,53380.193359375,1.90955564584371,0.000179856692587622
3844428927.478,5.00139331817627,53680.05078125,1.91430772797323,0.000188767452863253
3844428947.55,4.99987101554871,53980.796875,1.91949555359731,0.000171769062448966
3844428967.475,4.99981307983398,54279.580078125,1.92433205453913,0.000175657908598333
3844428987.513,4.99951648712158,54580.322265625,1.92897256336091,0.000186187234252551
3844429007.454,5.00049757957458,54879.697265625,1.9335867974535,0.000188449147741474
3844429027.4265,4.99927759170532,55179.609375,1.93773986221586,0.000160223273994307
3844429047.5505,5.00112295150757,55481.970703125,1.94244581321156,0.000172545204929813
3844429067.404,5.00182628631592,55779.6953125,1.94726039778318,0.00017189785873342
3844429087.497,5.00031542778015,56080.150390625,1.95147098851109,0.000187297176300416
3844429107.349,5.00058269500732,56377.845703125,1.95576079597386,0.00019529876364978
3844429127.457,5.00297403335571,56680.048828125,1.95996343134423,0.00019124071572653
3844429147.482,5.00310111045837,56980.115234375,1.96457241775018,0.00019023431161559
3844429167.3675,4.99880003929138,57278.7265625,1.96874029749505,0.00017915022754099
3844429187.308,5.00011658668518,57577.9921875,1.97281915814691,0.00016377593448217
3844429207.415,4.99770975112915,57879.455078125,1.97717446260251,0.000186850536501797
3844429227.3325,4.99986672401428,58178.171875,1.98121868659931,0.000178822143474961
3844429247.2315,4.99879026412964,58476.482421875,1.9851712987138,0.000180151022879774
3844429267.2475,5.00155901908874,58776.759765625,1.98863243213548,0.000164985911051765
3844429287.2085,4.99918556213379,59075.861328125,1.99305393236777,0.000183291341618787
3844429307.2795,4.99793004989624,59377.43359375,1.99686032828312,0.000187100557083751
3844429327.189,5.00203800201416,59675.8828125,2.00072586229044,0.000164663684887192
3844429347.258,4.99937105178833,59976.88671875,2.004674489408,0.000186706064823827
3844429367.1995,5.00308871269226,60276.19921875,2.00784656179191,0.000191161681742625
3844429387.1565,5.00137805938721,60575.513671875,2.01159938991104,0.000183776342284026
3844429407.31,4.99802470207214,60877.91015625,2.01567460836793,0.000198722502615237
3844429427.0945,4.99966144561768,61174.734375,2.01866387020432,0.000172951778522107
3844429447.167,5.00044417381287,61475.435546875,2.02261816179986,0.00018012449205693
3844429467.193,4.99872922897339,61776.380859375,2.02629984944587,0.000169662618202666
3844429487.0745,4.99992179870605,62075.107421875,2.02948573360449,0.000185081184716555
3844429507.032,5.000652551651,62373.708984375,2.03334247353404,0.000187671311618828
3844429527.188,5.00061941146851,62676.6171875,2.03615899191448,0.0001657485447743
3844429547.146,4.99765491485596,62975.87109375,2.03992590780982,0.000179478420354664
3844429567.007,4.99940919876099,63273.890625,2.04294722078904,0.000179066481057047
3844429587.013,4.99785685539246,63573.87109375,2.04650943464435,0.00017400755176793
3844429607.017,4.99771952629089,63874.314453125,2.04972839895941,0.000210722180306369
3844429626.9825,4.99896597862244,64174.146484375,2.05273062461555,0.000189498336844039
3844429646.9555,5.00021696090698,64473.48046875,2.05592207193875,0.000172790993572681
3844429666.9645,4.99728965759277,64772.775390625,2.05914566741967,0.000175569803522763
3844429686.9085,4.99848484992981,65072.59375,2.06220397894131,0.000181151838752698
3844429707.009,4.99958300590515,65374.177734375,2.06528720975475,0.000193303900085069
3844429726.871,5.00025963783264,65671.79296875,2.06807362367429,0.000191625220216156
3844429746.8605,4.99964666366577,65971.98828125,2.07126594846482,0.000194886615985371
3844429766.996,4.99854707717895,66274.2109375,2.07421087743548,0.000176083208291751
3844429786.8375,4.99886751174927,66570.68359375,2.07725812281779,0.00020137697379091
3844429806.8575,5.00272035598755,66870.64453125,2.07986821558259,0.00017058841729279
3844429826.8115,5.00063800811768,67170.8671875,2.0827588497731,0.000173423117479725
3844429846.7815,5.00312542915344,67469.9375,2.08557602208685,0.000198217159393712
3844429866.7715,5.00150108337402,67770.84765625,2.08866708765239,0.000178706731875923
3844429886.8095,5.00045824050903,68070.73828125,2.09192810867291,0.000198828106774702
3844429906.8115,5.0002453327179,68370.953125,2.09432640854605,0.000180384221856211
3844429926.9555,4.99723076820374,68673.44140625,2.09683406949366,0.000185939768907897
3844429946.718,4.999587059021,68970.48828125,2.09983894915948,0.000203090518526183
3844429966.823,4.99944877624512,69271,2.10260684356924,0.000169007612559645
3844429986.739,5.00133347511292,69570.4140625,2.104534571037,0.000177346977802435
3844430006.7255,5.00119757652283,69870.82421875,2.10771186660775,0.000181969111375608
3844430026.742,5.000652551651,70170.8984375,2.11054007497933,0.000191194492301331
3844430046.6445,5.00074291229248,70469.55859375,2.11297938759078,0.000168182557616783
3844430066.7545,5.00202012062073,70771.125,2.11535209946298,0.000194259178844627
3844430086.635,4.99642252922058,71069.796875,2.11808967363338,0.000188234881675776
3844430106.65,5.00058746337891,71370.52734375,2.12033919544474,0.000190503652277389
3844430126.5875,5.00119066238403,71669.33203125,2.12290872516528,0.000185527961015793
3844430146.586,5.00032949447632,71968.53125,2.12537249169924,0.000182631894878743
3844430166.578,4.99972987174988,72268.57421875,2.12778093828114,0.00017219047280517
3844430186.631,5.00025200843811,72569.28515625,2.1302471259253,0.000190306389283834
3844430206.555,4.99889540672302,72867.65625,2.13285976401018,0.000192323935071599
3844430226.526,5.00074458122253,73168.6640625,2.13499031807832,0.000199022432127288
3844430246.5995,5.00017189979553,73470.0390625,2.13727445986094,0.000175536074780055
3844430266.5345,5.00116753578186,73769.47265625,2.13974527580637,0.000185162947468003
3844430286.637,5.00206446647644,74070.0546875,2.14193345100853,0.000176239482001331
3844430306.6055,5.00144004821777,74368.84375,2.1441956900533,0.000188413512747713
3844430326.4545,5.00014972686768,74666.55078125,2.14563831657805,0.000186277960608271
3844430346.5285,5.0018789768219,74968.0546875,2.14876962885798,0.000197070893134085
3844430366.4125,4.99840188026428,75266.453125,2.15105243185742,0.000198838800585416
3844430386.3995,4.99749255180359,75566.49609375,2.15319192964755,0.00016699968603101
3844430406.55,5.00042676925659,75868.91015625,2.15551395799568,0.000178104829270037
3844430426.356,5.00048494338989,76165.96875,2.15768675307396,0.000181851130799745
3844430446.5065,5.00042772293091,76468.4375,2.15980466332045,0.000187420581852617
3844430466.354,4.99864077568054,76766.30078125,2.16210317266463,0.000189440136635184
3844430486.4545,4.99808144569397,77067.671875,2.16424290125759,0.000190641402896831
3844430506.471,4.99901676177978,77367.84765625,2.1660040875702,0.000190082676530343
3844430526.35,4.99885272979736,77666.6796875,2.16862397206401,0.000201193182262845
3844430546.2825,4.99843668937683,77966.05078125,2.17046257838655,0.000219081748431
3844430566.342,5.00193309783936,78267.21484375,2.17225683844553,0.000203621000088736
3844430586.25,5.00051307678223,78565.73046875,2.17424640207447,0.000184823958590835
3844430606.421,4.9986743927002,78868.9296875,2.17667450796038,0.000183434547944872
3844430626.218,5.00106358528137,79165.19140625,2.17821141182319,0.000201972990306518
3844430646.306,5.00113201141357,79467.12890625,2.1805916120204,0.000201476355046078
3844430666.3035,5.0003674030304,79766.8828125,2.18235663490653,0.000211721654379916
3844430686.2615,4.99868321418762,80065.3046875,2.18428983355161,0.000187722988644932
3844430706.139,5.00044655799866,80363.8671875,2.18598379144889,0.00019698623039597
3844430726.166,4.99755454063416,80664.484375,2.18811587405964,0.000200345578828465
3844430746.27,4.99717950820923,80966.15625,2.18993842314619,0.000205751079915384
3844430766.1345,5.00090312957764,81263.6875,2.19159193995894,0.000183599516727536
3844430786.175,5.00013518333435,81564.4921875,2.19374934983552,0.000200076500233671
3844430806.063,4.99895858764648,81862.8984375,2.19559408243427,0.000195660915789312
3844430826.2185,5.00031328201294,82164.5390625,2.19724326304204,0.000226100623429457
3844430846.119,5.00043749809265,82463.01953125,2.19926060736759,0.000192580825486877
3844430866.116,5.00201797485352,82763.38671875,2.20110798116189,0.000207552579695752
3844430886.006,4.99987316131592,83061.91796875,2.20253301934975,0.000199573417917205
3844430906.037,4.99998688697815,83362.67578125,2.20499034010077,0.000192496650018407
3844430925.9725,5.00159025192261,83661.18359375,2.20616747050773,0.000193829326910972
3844430945.9865,4.99887466430664,83962.06640625,2.20818685935139,0.000190898535662833
3844430966.13,5.00084662437439,84264.61328125,2.21001278188861,0.000190323250437623
3844430986.008,4.99948263168335,84562.52734375,2.21148448041675,0.000182406193609173
3844431005.923,4.99995255470276,84860.90234375,2.21333360788427,0.000187345629479021
3844431026.0345,4.99929928779602,85163.3125,2.21526229769326,0.000173499651210735
3844431045.9385,4.99979186058044,85462.1953125,2.21649919236493,0.000199708295295271
3844431065.988,4.99935221672058,85762.1796875,2.21837088175327,0.000172014770960957
3844431086.0205,4.99924492835999,86063.65234375,2.22053102610464,0.000192425847076629
3844431105.9845,5.00044631958008,86362.9296875,2.22199151111569,0.000177444661388849
3844431125.909,5.0001015663147,86662.4140625,2.22348763179696,0.000192525575578457
3844431145.8405,4.99871516227722,86960.7734375,2.22509292393433,0.000188636495762011
3844431165.8815,4.99758291244507,87262.03515625,2.22686541202407,0.000193188912282274
3844431185.826,4.99821758270264,87560.1875,2.22819008834031,0.000191468811224651
3844431205.8105,5.000408411026,87859.15234375,2.22975662896825,0.000188449613210523
3844431225.7585,5.00109100341797,88159.43359375,2.23137712395272,0.000195121823457826
3844431245.7405,4.99807167053223,88458.4296875,2.23284680153076,0.000179093843610969
3844431265.828,5.00063419342041,88759.31640625,2.23484744799608,0.000209390186756623
3844431285.699,5.00047588348389,89058.48828125,2.23623063900891,0.000219232097815253
3844431305.858,5.00201678276062,89360.9375,2.23751232975446,0.000203639169252631
3844431325.67,5.00307583808899,89657.9921875,2.23918358346091,0.000192878720124069
3844431345.6705,4.99989652633667,89957.8046875,2.2409343964146,0.000184365314149992
3844431365.806,5.00075316429138,90259.28515625,2.24205506850408,0.000195293103247068
3844431385.684,4.99955654144287,90558.2578125,2.24388517955499,0.000193067161299104
3844431405.647,5.0008602142334,90858.31640625,2.24526329414817,0.000200127120025537
3844431425.634,4.99953293800354,91157.78515625,2.24680193502832,0.000204850793224851
3844431445.7385,4.99917149543762,91459.51953125,2.24813102978942,0.000196743766748574
3844431465.7475,5.00233578681946,91760.29296875,2.24943452452358,0.000196162672433852
3844431485.681,4.99920654296875,92059.1796875,2.25128248920475,0.000202065614063465
3844431505.558,5.00201940536499,92357.96484375,2.2523809428377,0.00022110543265104
3844431525.5955,4.99857950210571,92657.66796875,2.25374130486661,0.000206887134626672
3844431545.6225,4.99744153022766,92958.3671875,2.25575021466288,0.000180543421283969
3844431565.529,5.00012302398682,93257.15625,2.25682508320504,0.000222383245678526
3844431585.6445,4.99736022949219,93558.5703125,2.25850857164197,0.000210373329053433
3844431605.586,4.99941682815552,93858.67578125,2.25952278496882,0.000196942568666001
3844431625.4995,5.00077390670776,94157.90625,2.26109777117328,0.000199948281222553
3844431645.4625,5.00052523612976,94456.296875,2.26240003258149,0.000190646752186278
3844431665.5105,4.99927735328674,94757.94140625,2.26387658177356,0.000195100500391105
3844431685.406,4.99952387809753,95055.99609375,2.26531065807945,0.000198491778177656
3844431705.398,5.00225448608398,95355.65234375,2.26670096366983,0.000190373289795847
3844431725.393,5.00357294082642,95655.421875,2.26750807091842,0.0002007156587403
3844431745.3705,5.00043678283691,95954.9296875,2.26884801829545,0.000200783836631232
3844431765.4515,5.00054216384888,96256.34375,2.27024143389836,0.000188831690526437
3844431785.368,4.99847984313965,96555.6875,2.27143002280479,0.000198930738124892
3844431805.397,5.0002007484436,96855.71875,2.27292413598406,0.000206711589742184
3844431825.408,4.99949169158936,97155.9453125,2.27406105325753,0.000218825276470414
3844431845.34,5.00047993659973,97455.3359375,2.27568009793522,0.000190412865430934
3844431865.382,4.99996423721313,97755.9921875,2.27720237084723,0.000204044622761967
3844431885.37,4.99988985061646,98056.1171875,2.27838610819488,0.000197151672088026
3844431905.3625,4.99944281578064,98356.3671875,2.2795270027197,0.000185164190919931
3844431925.305,5.00174641609192,98655.8125,2.28035854157034,0.000212916157883126
3844431945.353,4.99902367591858,98956.05859375,2.28208471714437,0.000197311344244699
3844431965.2205,4.99964094161987,99254.93359375,2.28323886667869,0.000203330957800743
3844431985.252,4.99917936325073,99555.03125,2.28422281008837,0.000174782915578871
3844432005.171,4.9990918636322,99854.42578125,2.28578284747152,0.000190148871915033
3844432025.189,4.99913692474365,100155.0625,2.28684421051479,0.000212934057207489
3844432045.186,4.99998736381531,100453.984375,2.28835285741306,0.000202685086852405
3844432065.3405,4.99950551986694,100756.09765625,2.28884554430084,0.000231612707644805
3844432085.1105,4.99988079071045,101052.58203125,2.29042545509173,0.000206136965671017
3844432105.209,4.9998619556427,101354.46484375,2.29151726898863,0.000199690228882911
3844432125.173,4.99898862838745,101653.8125,2.29295337589318,0.000191873837454207
3844432145.112,4.99918174743652,101952.8828125,2.29414195527997,0.000212612104416591
3844432165.098,5.00006151199341,102252.65625,2.2957559622226,0.000220476743509342
3844432185.1775,5.0004608631134,102554.01171875,2.29607060030392,0.000211617741647247
3844432205.035,5.00112366676331,102851.05078125,2.29766791560782,0.000226063881001234
3844432225.1615,4.99841237068176,103152.85546875,2.2987913911317,0.000225771082428449
3844432244.997,4.99813032150269,103450.7109375,2.30011431852256,0.000226479451100862
3844432265.0885,5.00037860870361,103752.4296875,2.30102235058901,0.000195936517582417
3844432285.011,5.00094413757324,104051.08203125,2.30221891594783,0.00020770285786659
3844432305.0995,4.99863457679749,104352.625,2.30317927583507,0.00019973744832894
3844432324.959,5.00117588043213,104650.484375,2.30410620085859,0.000203934074760594
3844432344.9685,4.99972128868103,104950.18359375,2.30563504397131,0.000226901401307537
3844432365.149,5.00043368339539,105253.30078125,2.30656712528946,0.000228335477048165
3844432384.9855,4.9995105266571,105551.55078125,2.30769466634062,0.00018472868551801
3844432405.013,4.99988698959351,105852.3203125,2.3088602769049,0.000217631643297656
3844432424.997,4.99792957305908,106151.97265625,2.30954263858681,0.000224388831511283
3844432444.9385,4.9992458820343,106451.453125,2.31089189677699,0.000209068692623408
3844432464.847,5.00111222267151,106749.9296875,2.31192974184288,0.000215225823092196
3844432484.8625,4.99968385696411,107050.015625,2.31309388040662,0.000227674171001616
3844432504.82,5.00061678886414,107349.171875,2.31391927716474,0.000200229406808703
3844432524.781,5.00010704994202,107649.2734375,2.31516115857202,0.000196916718172012
3844432544.8535,4.99961972236633,107949.953125,2.31626907718627,0.00022400807859524
3844432564.861,5.00089526176453,108249.5,2.31703529514742,0.000185245539197343
3844432584.8405,5.00016188621521,108549.35546875,2.31778516109253,0.000210581420190284
3844432604.953,4.99975728988647,108850.79296875,2.3190763982203,0.00021062599194706
3844432624.844,4.99846768379211,109149.1796875,2.32017963615912,0.000208167546957263
3844432644.725,4.99868726730347,109447.65234375,2.32136300363237,0.000205412813660868
3844432664.7185,5.00282955169678,109747.4609375,2.32186096078026,0.000230493438707411
3844432684.778,5.00093269348145,110049.14453125,2.32306923893546,0.000218717522490229
3844432704.833,5.00086116790771,110349.984375,2.32392621051895,0.000223922124753043
3844432724.715,4.99983263015747,110647.89453125,2.3250417460213,0.000212491545543978
3844432744.7425,5.00170230865479,110947.59765625,2.32593531483147,0.000225699055862925
3844432764.719,5.00113296508789,111247.71484375,2.32674099538869,0.00022697299389334
3844432784.612,5.00097012519836,111546.515625,2.32806923754611,0.000202873005688326
3844432804.5865,5.00204420089722,111846.6171875,2.32928281791196,0.000183024964587474
3844432824.639,5.00013375282288,112146.78515625,2.33028987431023,0.000224243878858301
3844432844.6025,4.99956464767456,112447.0078125,2.33123857774007,0.000214099837567698
3844432864.6515,5.00169587135315,112748.17578125,2.33225638928753,0.000211184813119702
3844432884.6605,5.00086903572082,113048.19140625,2.33314206395813,0.000196785871453291
3844432904.543,4.99995303153992,113346.7265625,2.33358640864535,0.000218472468982854
3844432924.548,4.99852633476257,113646.64453125,2.33493097127456,0.000229561495612944
3844432944.533,4.99925875663757,113947.0234375,2.33598653297097,0.000238209576329983
3844432964.5355,4.99884176254272,114246.33984375,2.33687086754439,0.00022570340013096
3844432984.5135,5.00020575523376,114546.2890625,2.33729584656745,0.000198130931180906
3844433004.64,5.00009560585022,114848.55078125,2.33845772260097,0.000211421987187771
3844433024.421,5.00102686882019,115145.40234375,2.33953223911897,0.000216517874590146
3844433044.4565,4.99982190132141,115446.25,2.34012806302313,0.000200821539291033
3844433064.5175,4.99914622306824,115746.80078125,2.34122207763201,0.000193023440317551
3844433084.417,4.99893522262573,116044.8984375,2.3417575972223,0.000206772982094608
3844433104.428,4.99959564208984,116345.46875,2.34311404441297,0.000241569166045057
3844433124.453,4.99990391731262,116645.44921875,2.34374565558214,0.00022159384965935
3844433144.3635,5.00098133087158,116943.734375,2.34460392419526,0.000229463350541465
3844433164.346,4.99898290634155,117244.62890625,2.34555951387983,0.000217951859021911
3844433184.4825,5.00193214416504,117546.2265625,2.34661800053618,0.000204198040812201
3844433204.2975,5.00041508674622,117843.2421875,2.34710718515985,0.000204091687156752
3844433224.3165,4.99922442436218,118144.1875,2.34799240240114,0.000198271617906468
3844433244.343,4.99651384353638,118444.26171875,2.34915928053811,0.000208601602398985
3844433264.292,4.99962854385376,118744.1015625,2.35011706217313,0.000221423897981363
3844433284.462,5.00047373771667,119045.7109375,2.35053995093642,0.000255246638120109
3844433304.2215,4.99941277503967,119343.09375,2.35160746778428,0.000194378511329181
3844433324.2055,5.00084638595581,119642.36328125,2.35255231900015,0.000208952017697784
3844433344.2235,4.99779796600342,119943.73828125,2.3530896541312,0.000218582969898219
3844433364.277,4.99850559234619,120244.56640625,2.35391310736429,0.00020339211048122
3844433384.283,5.00228142738342,120545,2.35482917201245,0.000184495080560153
3844433404.1345,5.00030064582825,120843.41015625,2.35557029493779,0.000209767763284214
3844433424.268,4.99975252151489,121145.6328125,2.35649518760472,0.000196456068925467
3844433444.148,5.00022602081299,121442.4453125,2.35771335321302,0.000207223708175245
3844433464.0975,5.00153779983521,121742.484375,2.35794543958832,0.000213989771247783
3844433484.167,4.9992823600769,122043.53515625,2.35863024288492,0.00023053568137172
3844433504.117,4.99983978271484,122342.74609375,2.36004095088437,0.000199217254232891
3844433524.14,4.9988317489624,122643.56640625,2.36084106305594,0.000201296515901401
3844433544.1655,4.99836659431458,122944.03125,2.36117649626499,0.000205534810056761
3844433564.1295,4.99962496757507,123243.359375,2.36217719885711,0.000210208224134544
3844433584.12,5.00201725959778,123543.09375,2.36250663361402,0.000212928443198883
3844433604.194,4.99957370758057,123843.2734375,2.36342250822198,0.000212498702682579
3844433624.0735,4.99939799308777,124140.6328125,2.36408348323221,0.000228494387991586
3844433643.9885,5.00045418739319,124440.0390625,2.36553125531871,0.000240067411567284
3844433663.964,4.99770998954773,124739.16796875,2.36599000330049,0.000236857649661678
3844433683.927,4.99883651733398,125038.99609375,2.36653123591128,0.000229860662566955
3844433704.0755,5.0002236366272,125340.47265625,2.36789683737808,0.000213370020484658
3844433723.9045,5.00005006790161,125638.328125,2.36781237997996,0.000243455420826088
3844433743.984,4.99999070167542,125939.3828125,2.36875396690792,0.000220022974939036
3844433763.923,5.00002312660217,126238.7109375,2.36930128905219,0.000229893953330636
3844433783.853,5.00111842155457,126537.8125,2.37041361599289,0.000236650853883807
3844433804.0165,4.99914693832397,126840.9609375,2.37142846329258,0.000214272089460046
3844433823.9615,4.99959421157837,127140.64453125,2.37174769138783,0.00022502056857248
3844433843.8265,5.00007700920105,127438.33984375,2.37240831345328,0.000204098214405204
3844433863.8655,5.00069212913513,127739.28515625,2.37324745546541,0.000198779890749295
3844433883.8845,5.00161218643188,128039.359375,2.37390453188788,0.000247060038557952
3844433903.8425,5.00143599510193,128338.9453125,2.37485048061606,0.000204318857105099
3844433923.802,5.00049877166748,128638.4765625,2.37505492998351,0.000225743160883826
3844433943.831,4.99955248832703,128939.0546875,2.37596308862542,0.000206411588883866
3844433963.7595,5.00094771385193,129238.21484375,2.37666539198686,0.000241611118774311
3844433983.8895,5.0002224445343,129540.671875,2.37768185098946,0.000217087677507739
3844434003.7685,5.00050377845764,129838.91015625,2.37793877343967,0.000235703576537797
3844434023.678,4.99947094917297,130138.04296875,2.37905532312874,0.000230977743131994
3844434043.7565,4.999267578125,130438.2421875,2.37955399018735,0.000212510433016809
3844434063.7205,4.9994523525238,130738.12890625,2.3802675208926,0.000206111909996331
3844434083.8025,5.00111889839172,131039.65234375,2.38087134991082,0.000207126593339361
3844434103.7295,4.99979162216186,131337.96875,2.38146949786046,0.000247215707045926
3844434123.5995,5.00149655342102,131635.8359375,2.38193145513598,0.000199943018192404
3844434143.609,4.99992346763611,131935.5546875,2.3825046694029,0.000228667586297121
3844434163.6815,5.00220012664795,132236.203125,2.38313391519632,0.000214377279976031
3844434183.608,5.00009894371033,132535.0625,2.38447359459866,0.00023121946655995
3844434203.655,5.00103902816772,132835.7890625,2.38478428930595,0.000202035862568911
3844434223.6215,5.00022578239441,133135.09375,2.38526338135322,0.000220311802548175
3844434243.5595,4.99654507637024,133434.234375,2.38651906635954,0.000225633386915645
3844434263.524,5.00066304206848,133733.84375,2.38648183757211,0.000200423987687056
3844434283.6705,4.99971556663513,134036.7890625,2.38719576544027,0.000217833945992456
3844434303.5655,5.0017101764679,134334.40625,2.38804904739272,0.00023244089491271
3844434323.5855,5.00106263160706,134635.265625,2.38852679039214,0.000250028610284904
3844434343.468,5.00051069259644,134934.078125,2.38912046200561,0.000227839217830004
3844434363.6085,4.99954271316528,135235.671875,2.38973839897581,0.000236055779061535
3844434383.427,5.00068998336792,135534.578125,2.39050330594935,0.000226329789851885
3844434403.4015,4.99875402450562,135833.7421875,2.39092666506076,0.000209634277443261
3844434423.532,5.00174522399902,136136.2421875,2.39162139828608,0.000219210897087069
3844434443.393,4.99927830696106,136434.8984375,2.39201836907879,0.000209992399887581
3844434463.431,5.00090503692627,136734.875,2.39282159699073,0.000216504681682463
3844434483.4325,5.00065398216248,137035.3671875,2.3937216716532,0.000240879735566129
3844434503.3765,4.99981760978699,137333.9140625,2.3941022935219,0.000251941637556306
3844434523.4425,5.00051188468933,137634.4375,2.39472535723952,0.000234367474696355
3844434543.3685,4.99988508224487,137934.4921875,2.39524992517332,0.000232086058893545
3844434563.3605,5.00028228759766,138234.765625,2.39599138734416,0.000231916746253874
3844434583.2525,4.99847888946533,138533.3046875,2.39638985615647,0.000244545675836271
3844434603.2655,4.99962329864502,138833.6640625,2.39727975122445,0.000256134716784718
3844434623.4005,5.00060606002808,139135.203125,2.39688412797788,0.000220848452176674
3844434643.262,5.00068712234497,139433.4140625,2.39852224587352,0.000236393532698255
3844434663.306,4.99992060661316,139733.4296875,2.39898467329118,0.000235278192860648
3844434698.182,4.99979710578918,140000.5546875,2.39986541446726,0.000242316648529136