File: MvsH/data/2021-10-25_EROI_34P8MG_MVSH_10P0K.DAT
Time Stamp (sec),Temperature (K),Magnetic Field (Oe),Moment (emu),M. Std. Err. (emu)
3844436424.946,9.98420700589194,-0.160002008080482,,
3844436521.9025,9.99767637252808,-4846.90625,-0.185867290791306,6.00377492002928E-5
3844436541.8135,10.0000691413879,-4548.72119140625,-0.17442580539363,6.24478445457847E-5
3844436561.8045,9.99770975112915,-4247.98486328125,-0.16296992915818,5.83314720731172E-5
3844436581.8815,9.99986457824707,-3947.49340820313,-0.151531776151502,6.01047826593345E-5
3844436601.886,9.99889087677002,-3647.87341308594,-0.140136571529985,5.81983368023311E-5
3844436621.7435,10.0004086494446,-3350.34045410156,-0.128686741520647,5.92594679042669E-5
3844436641.8975,9.99914693832397,-3047.11096191406,-0.117240443045333,5.97204895548053E-5
3844436661.8975,9.99985361099243,-2747.19104003906,-0.105810041542701,5.98624199728177E-5
3844436681.819,9.99992895126343,-2447.87902832031,-0.0943502563942258,5.93518352013802E-5
3844436701.782,10.0000348091125,-2148.97595214844,-0.0829248093587804,6.01681693154113E-5
3844436721.7615,9.99952077865601,-1848.79449462891,-0.0714459275592521,5.85120738972288E-5
3844436741.7085,10.0006456375122,-1550.40191650391,-0.0599769901885343,5.81750543035862E-5
3844436761.648,10.0003628730774,-1251.53485107422,-0.0485153481751786,5.83188455243842E-5
3844436781.759,9.99988317489624,-949.480224609375,-0.0370390735439459,5.86117475732468E-5
3844436806.63,10.0004329681396,-577.437164306641,-0.0226963080832186,5.89239210429543E-5
3844436826.593,10.0011696815491,-277.601135253906,-0.0112435855255474,5.84532181587536E-5
3844436854.6225,9.99915885925293,142.659034729004,0.00309630718503375,5.86571874393282E-5
3844436879.7315,10.0007085800171,519.034790039063,0.0174586491319367,5.8701496625067E-5
3844436896.576,10.0000581741333,771.804840087891,0.0289518874572941,5.88073414911674E-5
3844436916.6425,10.0003542900085,1072.45227050781,0.0404482569858745,5.88472514874782E-5
3844436936.5225,9.99851226806641,1369.70306396484,0.0519406957127382,5.8965733493875E-5
3844436956.565,10.0001177787781,1671.09216308594,0.0634257642916757,5.92500697267378E-5
3844436976.5395,9.99953842163086,1970.33520507813,0.0749353292737936,5.90094491860977E-5
3844436996.531,10.0004963874817,2270.31457519531,0.0864226110207665,5.89832358998128E-5
3844437016.526,10.0015935897827,2570.32922363281,0.0978878884605212,5.91666131659018E-5
3844437041.446,9.99989223480225,2943.66479492188,0.112215594565145,6.05501257134457E-5
3844437061.4245,10.0007772445679,3243.58276367188,0.123647704954453,5.9120613679086E-5
3844437081.4375,10.0009007453918,3544.48327636719,0.135092955998621,6.04089795812889E-5
3844437101.449,9.99987697601318,3844.24365234375,0.146478808583507,6.17310433688922E-5
3844437121.4575,10.0003709793091,4143.10595703125,0.157884152649135,5.96296346131063E-5
3844437141.3645,9.99876880645752,4442.31884765625,0.16931112919805,6.0258286150771E-5
3844437161.5285,9.99953126907349,4744.74853515625,0.180668129147566,6.00488805372073E-5
3844437181.3975,10.0003318786621,5043.15405273438,0.192053939398468,6.08714413241599E-5
3844437201.3695,10.0009431838989,5342.40625,0.203433203412132,6.12486261990571E-5
3844437221.4995,9.99870109558105,5643.82568359375,0.214828511942651,5.97479225892654E-5
3844437241.443,10.0002112388611,5944.07690429688,0.226104828052644,6.26825717663893E-5
3844437261.4,9.99976396560669,6243.14697265625,0.237484612989106,5.95602370423678E-5
3844437281.3475,9.99928569793701,6542.01635742188,0.248787758485695,6.26743980399504E-5
3844437301.332,10.0004568099976,6841.81982421875,0.26003631567803,6.17311092453218E-5
3844437321.363,10.0000014305115,7141.89184570312,0.271363640945323,6.52948007750237E-5
3844437341.2185,9.99957370758057,7440.3017578125,0.282639351977423,6.13529715934166E-5
3844437361.2005,10.0006322860718,7739.49438476563,0.293951568909583,6.30721595463458E-5
3844437381.1745,9.99961948394775,8039.4169921875,0.30514620957125,6.4947608995843E-5
3844437401.2355,9.99884366989136,8340.00537109375,0.316406453758395,6.45051341069336E-5
3844437421.26,9.99884700775146,8640.2431640625,0.327582999194152,6.67031671059118E-5
3844437441.2265,10.0008239746094,8940.07373046875,0.338777315972746,6.50894698508557E-5
3844437461.1815,10.000572681427,9238.89453125,0.349953407734421,6.37007648471243E-5
3844437481.1835,10.000804901123,9538.20947265625,0.361225985724394,6.79520568624357E-5
3844437501.186,10.0002245903015,9839.7509765625,0.37228002540635,7.1819483520716E-5
3844437521.125,9.99975442886353,10137.4116210938,0.383468762413947,6.64226884057087E-5
3844437541.2935,10.0004420280457,10441.1181640625,0.394608154675917,6.64283346608408E-5
3844437561.13,9.99943876266479,10738.900390625,0.40578715002008,7.13138994342278E-5
3844437581.0485,10.0000309944153,11037.40625,0.416824312604373,7.06808354361663E-5
3844437601.1935,10.0006756782532,11339.5859375,0.427914582439493,6.92299461511966E-5
3844437621.058,10.0002255439758,11638.0302734375,0.438976368790146,7.12337610007358E-5
3844437641.065,10.0000419616699,11936.8251953125,0.450059107071951,6.85336031532683E-5
3844437661.067,9.99993562698364,12236.7495117188,0.461042810691286,6.71421487213923E-5
3844437681.1415,9.99941444396973,12537.7021484375,0.472092032165786,7.71568206376021E-5
3844437701.0765,9.99976587295532,12837.59375,0.482924173774635,7.65365242978032E-5
3844437720.955,10.0006279945374,13135.423828125,0.4938906915576,7.26501671628462E-5
3844437741.054,10.0008344650269,13437.4833984375,0.504889986954769,6.47259341495305E-5
3844437760.9,9.99831104278564,13734.685546875,0.515999964391919,7.44822036638658E-5
3844437781.034,10.0001831054688,14037.4799804687,0.526639699363564,7.86803370851796E-5
3844437800.878,10.0008068084717,14333.4663085938,0.537495168629019,7.25598464863368E-5
3844437821.0035,9.99948883056641,14636.2641601562,0.548390573045426,7.31313559216273E-5
3844437840.938,9.99928283691406,14935.4399414062,0.559269604381927,7.2163613959971E-5
3844437860.8315,10.0003151893616,15233.181640625,0.569985804743036,7.51302452577854E-5
3844437880.8245,9.99959897994995,15533.8618164062,0.580858622745351,6.86953098345967E-5
3844437901.004,9.99961662292481,15836.4423828125,0.591652341100832,7.71148390348064E-5
3844437920.772,9.99925374984741,16133.4067382812,0.602446087949263,7.90878798049337E-5
3844437940.9565,10.0004100799561,16435.716796875,0.613088271626547,7.92223739183094E-5
3844437960.8325,10.0010242462158,16734.0625,0.623687429571688,8.08705014000349E-5
3844437980.7615,10.0006031990051,17032.939453125,0.634403383976092,7.82157113413917E-5
3844438000.7125,9.99976968765259,17331.302734375,0.645126166529759,8.25684525445344E-5
3844438020.8465,9.9982385635376,17633.5458984375,0.655779065271213,7.87518624767667E-5
3844438040.6975,9.99997997283935,17930.98828125,0.666409336757458,8.3185234783734E-5
3844438060.8315,9.99955129623413,18233.2431640625,0.676995504910687,8.34157884347118E-5
3844438080.666,10.0008482933044,18530.9853515625,0.687453843231624,8.47114223743651E-5
3844438100.752,10.0007662773132,18832.25,0.698008934523789,8.04955194308546E-5
3844438120.734,10.0000104904175,19131.015625,0.708487635280826,8.99762764941323E-5
3844438140.655,9.99970054626465,19430.11328125,0.718948119201206,9.16781184559698E-5
3844438160.7245,10.0010814666748,19731.359375,0.729497169919667,8.75655089253482E-5
3844438180.62,9.99989986419678,20028.9130859375,0.739812302785612,8.98267445111764E-5
3844438200.7255,10.0010762214661,20331.296875,0.750156388919483,9.36783655316313E-5
3844438220.7185,10.0004415512085,20631.1962890625,0.760527352101575,9.11030489628714E-5
3844438240.575,9.99998807907105,20928.7900390625,0.770881246436047,8.92121690756747E-5
3844438260.6635,9.99970102310181,21230.2978515625,0.781119766387997,9.46730472919449E-5
3844438280.5555,10.0002069473267,21528.8740234375,0.791576719369497,9.52579306969839E-5
3844438300.598,9.99986028671265,21828.7265625,0.801809536169146,8.56691647693058E-5
3844438320.634,9.99887657165527,22129.3662109375,0.812131591071107,8.95702546289099E-5
3844438340.5615,10.0001301765442,22428.2578125,0.822280026685266,9.3707760092091E-5
3844438360.583,10.0010852813721,22728.1650390625,0.832479195411475,9.65401814406221E-5
3844438380.5005,10.0004062652588,23026.8916015625,0.842701791386488,9.89403320691079E-5
3844438400.419,9.9986629486084,23326.1279296875,0.852771391334454,9.90817535504145E-5
3844438420.5475,10.0011200904846,23627.8193359375,0.862956829064368,9.87332269545742E-5
3844438440.4355,9.99969387054443,23926.1240234375,0.872995515655954,8.71499285112671E-5
3844438460.378,9.99936819076538,24226.380859375,0.883105935742084,9.72044858575122E-5
3844438480.3765,9.99998092651367,24525.419921875,0.893126248458207,9.66159821260396E-5
3844438500.4595,10.0012159347534,24826.484375,0.90306203136261,9.90973003451363E-5
3844438520.353,9.99948215484619,25124.994140625,0.913126067384477,9.63513953437145E-5
3844438540.4175,10.0013365745544,25425.177734375,0.922834817344228,0.000101673781822578
3844438560.372,10.0001330375671,25725.138671875,0.932975557014273,9.87667329787603E-5
3844438580.374,9.99907255172729,26025.14453125,0.942709080675873,0.000102049896614803
3844438600.4145,10.0006394386292,26326.58984375,0.952529272023734,0.000100259482973427
3844438625.8915,10.0010938644409,26707.748046875,0.964722942497545,0.000110658156737404
3844438645.3485,10.0001502037048,27001.0576171875,0.974290538902986,0.000105273491910605
3844438665.224,9.99985933303833,27297.9208984375,0.984356462229077,0.000115220413262693
3844438685.281,10.0004501342773,27598.9404296875,0.993863293311054,0.000103069316836463
3844438705.2315,9.99982929229736,27898.162109375,1.00349222735043,0.000106429259086316
3844438725.183,9.99926996231079,28196.931640625,1.01345498734433,0.000115983556528445
3844438745.3205,9.99974012374878,28499.2353515625,1.02299518635371,0.000102852537600584
3844438765.236,9.99891901016235,28798.537109375,1.03258556714997,0.000107074267802209
3844438785.155,10.0003333091736,29096.9580078125,1.0421336486496,0.000110874459321357
3844438805.3285,10.0006132125854,29399.5107421875,1.05179300628565,0.000107326973975659
3844438825.1125,10.0009827613831,29697.0634765625,1.06121839646511,0.000109781870254226
3844438845.132,9.99977016448975,29995.89453125,1.07085666662965,0.000124787766972752
3844438865.0945,9.99985361099243,30295.7236328125,1.08012478543581,0.000115732239178955
3844438885.146,10.0004210472107,30596.46875,1.08982099935733,0.000113909314429116
3844438905.083,9.99984359741211,30895.841796875,1.09922453023687,0.000122737053519558
3844438925.126,10.0005621910095,31196.32421875,1.10832932157407,0.000120053936650519
3844438945.0295,9.99949789047241,31495.8642578125,1.11775607404934,0.000126230315780558
3844438965.0835,9.99988031387329,31796.431640625,1.12712949428502,0.000121498435512593
3844438985.0395,10.0002799034119,32096.7578125,1.13642326317516,0.000123491937727305
3844439005.147,9.99948835372925,32398.1455078125,1.14539796137675,0.000110987130017624
3844439024.9785,9.99979257583618,32694.826171875,1.15447532285349,0.000105433514172292
3844439045.024,9.99977540969849,32995.41796875,1.16373913608904,0.000109150776904755
3844439065.065,10.0003786087036,33296.46875,1.17264627722268,0.000113612096029443
3844439084.982,10.0000419616699,33594.751953125,1.18198101936885,0.000142552926914962
3844439104.9765,9.99868106842041,33895.6171875,1.19072858401689,0.000117368188451878
3844439124.957,9.99935865402222,34194.513671875,1.19992044241602,0.000124628976705417
3844439144.9835,10.0000586509705,34495.37109375,1.20872448900794,0.000122436000632733
3844439165.016,9.99968528747559,34795.373046875,1.21787436110525,0.000133600338717118
3844439184.954,9.99903297424316,35094.529296875,1.22675238817988,0.000128196112046315
3844439204.955,10.0006198883057,35394.1640625,1.23535544583306,0.000121778027690449
3844439224.9605,10.0003471374512,35694.7109375,1.24427426406235,0.000127409890563142
3844439244.9195,9.99967241287231,35993.537109375,1.25319748230054,0.000127320716161925
3844439264.7915,10.0009942054749,36291.904296875,1.26178351242979,0.000114706565957575
3844439284.799,9.99979496002197,36592.234375,1.27079540311393,0.000120389292488897
3844439304.8855,9.99993181228638,36893.66015625,1.27935756328295,0.00013233217503455
3844439324.8345,10.0003099441528,37193.048828125,1.28789665292711,0.000125418600461591
3844439344.784,10.0007300376892,37492.171875,1.2964849781282,0.000130976826451735
3844439364.787,9.99994850158691,37791.728515625,1.30507224107143,0.000141443125539754
3844439384.8495,10.0003590583801,38092.25390625,1.31355689692107,0.000144129222323038
3844439404.679,10.0005011558533,38390.099609375,1.3221602269547,0.000123084455577182
3844439424.776,9.99969005584717,38690.87890625,1.33092254633703,0.000136611978054754
3844439444.741,9.99987983703613,38990.73046875,1.33880455515609,0.000133559103153349
3844439464.6495,9.99976253509522,39289.40234375,1.34735372877789,0.00012135456949355
3844439484.7735,9.99992609024048,39591.599609375,1.35568161952775,0.00013083487792822
3844439504.6005,10.0005130767822,39888.818359375,1.36410753305625,0.000136617761615686
3844439524.753,10.0010151863098,40191.7890625,1.37225245540271,0.000142974616662529
3844439544.5615,9.99971580505371,40487.791015625,1.38038102329332,0.000138146950840652
3844439564.69,10.0008940696716,40790.134765625,1.38858538644272,0.000138490126377413
3844439584.6135,10.0003280639648,41089.65625,1.39673220431333,0.000129760341295659
3844439604.544,9.99986839294434,41388.85546875,1.40494809552425,0.000144325347577884
3844439624.5985,10.0000238418579,41688.76171875,1.4128172055434,0.000137335777467252
3844439644.5745,9.99985647201538,41988.775390625,1.42097249748739,0.000150857025710774
3844439664.6275,9.9993839263916,42289.673828125,1.42886384512005,0.000147220160475544
3844439684.631,10.0005922317505,42589.97265625,1.43654483216705,0.000131969744687537
3844439704.5595,9.99917984008789,42889.138671875,1.44446741347692,0.000133072311141453
3844439724.4385,10.0000500679016,43187.380859375,1.45211031386887,0.000158665285547491
3844439744.502,10.0004353523254,43488.04296875,1.46021703921612,0.000141485263292578
3844439764.425,9.99982023239136,43786.69921875,1.46774665475886,0.000142447824623018
3844439784.5255,10.0004014968872,44088.1953125,1.4754264807624,0.000128646827020367
3844439804.4415,10.0011610984802,44387.544921875,1.48284688269394,0.000144384049897037
3844439824.547,9.99998617172241,44689.02734375,1.49067396301494,0.000148269349322575
3844439844.3945,10.0004267692566,44986.970703125,1.49820515566891,0.000153802655254595
3844439864.5275,10.0002365112305,45289.0390625,1.50598150656115,0.000157572275166022
3844439884.3395,9.99956178665161,45585.87890625,1.51316953230336,0.000152772503897391
3844439904.4035,10.0002193450928,45886.478515625,1.52075423287969,0.000167429688840942
3844439924.3115,10.0000672340393,46184.94140625,1.52814667406377,0.000147378138779257
3844439944.46,10.0003304481506,46487.423828125,1.53554533052161,0.000165359371402258
3844439964.3285,9.99972677230835,46785.70703125,1.54253361546155,0.000159073439496836
3844439984.3765,9.99990844726563,47086.583984375,1.54976770493124,0.000153027414505808
3844440004.263,10.0004148483276,47384.234375,1.55677477006942,0.000144522360566682
3844440024.204,9.99972438812256,47683.58984375,1.56402751186946,0.000149183268984645
3844440044.2745,10.0002799034119,47985.015625,1.57113487845154,0.000144702725051704
3844440064.3105,10.0008058547974,48285.494140625,1.57809491882839,0.000157092327881257
3844440084.179,10.0002861022949,48583.11328125,1.58522435401522,0.00016333609823601
3844440104.2345,10.0013737678528,48883.955078125,1.59203436946727,0.000168815471217262
3844440124.1605,10.0000267028809,49183.13671875,1.59908968763287,0.000151311905394003
3844440144.1505,10.0010905265808,49482.314453125,1.60566809640886,0.000145808534715193
3844440164.212,9.99952030181885,49783.71875,1.61273511326694,0.000160911467968382
3844440184.1195,9.99881219863892,50082.17578125,1.61965413720266,0.000160943673066433
3844440204.133,10.0014033317566,50382.3125,1.62600628700275,0.000154321228563794
3844440224.2005,10.000075340271,50683.771484375,1.63279809657317,0.000154522524407576
3844440244.054,10.0001931190491,50980.5625,1.63930002978538,0.000150340092889441
3844440264.138,9.99981307983398,51282.638671875,1.64641006624797,0.0001797925704884
3844440284.159,10.000862121582,51582.99609375,1.6525798536065,0.000167412163208778
3844440304.0665,9.99932765960693,51881.6484375,1.65890241028657,0.000161582139493051
3844440324.156,9.99954795837402,52184.35546875,1.66550385922139,0.000162581946468014
3844440344.0725,10.0003099441528,52482.859375,1.67189756628131,0.000169956616458881
3844440364.1,9.99848890304565,52783.87890625,1.67801446567752,0.000165579457978179
3844440383.9665,10.0004968643188,53080.900390625,1.68432724634147,0.000162091104351363
3844440404.076,9.99949979782104,53383.791015625,1.69075889259955,0.000181508780869364
3844440424.0795,9.99877452850342,53682.751953125,1.69669367195563,0.00016858184688984
3844440443.967,9.99972629547119,53981.978515625,1.70287781313229,0.000147980395761781
3844440463.9065,10.0004892349243,54280.716796875,1.70903070171901,0.000152190291235612
3844440483.9575,10.0000333786011,54581.470703125,1.71478428055521,0.000185329698392591
3844440503.9085,10.0006904602051,54880.791015625,1.72097771460197,0.000166247792566275
3844440523.859,10.0012178421021,55180.720703125,1.72677185523258,0.000164761139406006
3844440543.9305,9.99957513809204,55481.02734375,1.73260111260148,0.000179376456566655
3844440563.89,9.99968957901001,55780.9140625,1.73832878105776,0.000173711539782627
3844440583.9325,9.99997758865356,56081.333984375,1.74412613027518,0.000183823542085924
3844440603.7955,9.99983835220337,56378.880859375,1.75003663262649,0.000176561401810872
3844440623.828,10.0006122589111,56679.76953125,1.75543737914466,0.000165962265611185
3844440643.8055,10.0001096725464,56979.654296875,1.76148070148659,0.000169075996028421
3844440663.9335,10.0001759529114,57281.228515625,1.76680120621927,0.000176632405961032
3844440683.8245,10.0001764297485,57579.091796875,1.77224143760412,0.000157318732269394
3844440703.7265,10.0001454353333,57878.158203125,1.77748697450395,0.000158740374435697
3844440723.856,10.0009188652039,58180.0234375,1.78295953088574,0.00018504614055438
3844440743.7575,10.000967502594,58478.46875,1.78858501468071,0.000184896832100352
3844440763.6725,10.0004811286926,58777.166015625,1.79349041532306,0.000170788511561483
3844440783.7855,9.99969148635864,59078.626953125,1.79935155658781,0.000181845204621994
3844440803.7925,9.99946069717407,59379.40234375,1.80414136819093,0.000179854254636938
3844440823.645,10.0005574226379,59677.12890625,1.80967089011268,0.000179452381031431
3844440843.6265,10.0005006790161,59976.349609375,1.81494697326854,0.000189819591629112
3844440863.721,9.99942302703857,60278.091796875,1.82005793994578,0.000199516953552271
3844440883.7415,9.99943685531616,60578.90234375,1.82503214775885,0.00019401935041971
3844440903.6205,10.0000581741333,60876.82421875,1.83019391362875,0.000169265673802599
3844440923.6635,9.99999475479126,61177.4375,1.83507886202928,0.000174680829639841
3844440943.559,10.0005989074707,61475.87109375,1.84018916587167,0.000177169818164665
3844440963.606,9.99922466278076,61776.69140625,1.84476211215297,0.000182767438050311
3844440983.7055,10.000331401825,62078.6015625,1.85002914821712,0.000183302001231792
3844441003.5195,9.99944639205933,62376.1953125,1.85487890751579,0.000170723992862348
3844441023.645,10.0002751350403,62677.59375,1.85982950249817,0.000205862819335243
3844441043.4485,9.99993753433228,62974.724609375,1.86392477352863,0.00018694465267147
3844441063.583,9.99939966201782,63277.25,1.86904164145453,0.000182448781733933
3844441083.5225,10.0012674331665,63576.580078125,1.87369623161539,0.000203924679993408
3844441103.4765,9.99961566925049,63875.3203125,1.87819933242848,0.000216566245827622
3844441123.595,10.0005135536194,64176.75390625,1.88270407645387,0.000171611372970697
3844441143.5185,9.99908113479614,64475.35546875,1.88710289620358,0.000165879365512663
3844441163.3695,10.0002565383911,64773.083984375,1.89161934212305,0.000196461351526468
3844441183.503,10.000253200531,65075.283203125,1.89590262206773,0.000179115842431185
3844441203.352,9.99944972991943,65372.998046875,1.90034491449139,0.00016879049460514
3844441223.3445,9.99895906448364,65672.98828125,1.90485935511483,0.000174360307251608
3844441243.317,9.99993419647217,65973.2578125,1.90878096163249,0.000192016781053415
3844441263.3665,10.0004644393921,66272.9765625,1.91310757652156,0.000190704448954752
3844441283.3945,10.0009174346924,66574.171875,1.91754388523378,0.000165403510786525
3844441303.2705,9.99957895278931,66871.84765625,1.92187972681228,0.000196875670356684
3844441323.2505,9.99967861175537,67172.0390625,1.92586043219857,0.000195498968707173
3844441343.328,9.99989175796509,67472.7265625,1.92979508495938,0.000186863113218244
3844441363.257,9.99983024597168,67771.23046875,1.9341561403853,0.00019195824276436
3844441383.2565,10.0006928443909,68071.3125,1.93832711546176,0.00019749795418343
3844441403.233,9.99928998947144,68370.61328125,1.941971538165,0.00018448401284272
3844441423.327,10.0002999305725,68672.34375,1.94595111772507,0.000179945665173524
3844441443.2265,9.99868774414062,68970.8984375,1.95033722674567,0.000213526681517283
3844441463.2895,10.0010576248169,69273.04296875,1.95406949055537,0.00020984241397893
3844441483.185,9.999183177948,69570.9140625,1.95771152917682,0.000168204443889758
3844441503.155,10.0007839202881,69871.16015625,1.96148807007857,0.000178019884970802
3844441523.2525,10.0006222724915,70172.93359375,1.96524014708135,0.000182382511610069
3844441543.1405,9.99971485137939,70471.57421875,1.96940464351163,0.000177529398146552
3844441563.0915,10.0011539459229,70770.75,1.9727787360795,0.000160706953959444
3844441583.0545,10.0010142326355,71070.34765625,1.97655503893204,0.000200153212099179
3844441603.198,10.000048160553,71371.82421875,1.9804195117093,0.000192156401039785
3844441623.113,9.99958229064941,71670.7890625,1.98372425432538,0.000164154953332339
3844441643.1905,9.99982118606567,71971.39453125,1.98733325995378,0.000174513600315299
3844441663.0785,9.99979734420776,72269.80859375,1.99078419363081,0.000187927221771814
3844441683.1205,9.99974203109741,72570.6875,1.99478578259034,0.000182496260993173
3844441703.09,10.0005083084106,72869.7890625,1.99790878994678,0.000176156018198096
3844441722.9895,10.0001983642578,73169.34765625,2.00137979301251,0.000186789136216324
3844441743.0765,10.0000638961792,73470.6875,2.00522700476891,0.000206192639186909
3844441762.9195,10.000807762146,73768.56640625,2.0083484804409,0.000190884558325567
3844441783.0325,10.00013256073,74069.98828125,2.01151508252459,0.000188582671716428
3844441803.0145,9.9994330406189,74369.61328125,2.01467588399515,0.000181894658708636
3844441822.9755,10.0003523826599,74668.75390625,2.0182343008679,0.000175102652820705
3844441842.9245,9.99919700622559,74968.08203125,2.02192292901671,0.000210165056741566
3844441863.014,10.0012044906616,75270.09375,2.02460072690028,0.000185989748273687
3844441882.911,10.0002565383911,75568.34765625,2.0280416733897,0.000217634042839336
3844441902.9945,9.99883031845093,75869.96875,2.03136415488247,0.000195935056359709
3844441922.8045,10.0007514953613,76167.90625,2.03432132380296,0.00020061882781401
3844441942.9615,10.0005435943604,76470.16015625,2.03732809158384,0.000207790859714608
3844441962.8345,9.99930143356323,76767.3671875,2.0402951936833,0.000213832865597796
3844441982.785,9.99964094161987,77067.27734375,2.04337727100419,0.000190331035838062
3844442002.8285,9.99957799911499,77368.109375,2.0468173441876,0.000200929663364049
3844442022.8815,10.001042842865,77669.28515625,2.04986927611181,0.000200639490903764
3844442042.7915,9.99969339370728,77968.578125,2.05282719272927,0.000182729187370928
3844442062.735,10.0001702308655,78267.49609375,2.0560085836842,0.000190792707243901
3844442082.8245,9.99978446960449,78568.94921875,2.05854944398364,0.000207205492218905
3844442102.6835,10.0003247261047,78866.88671875,2.0618203179608,0.000187717715285479
3844442122.7585,10.0003819465637,79168.34765625,2.06431048332758,0.00018224320628571
3844442142.663,9.99970245361328,79466.484375,2.06717321428779,0.000203969540138598
3844442162.7295,9.99997997283935,79767.00390625,2.07036085031138,0.000197112135842953
3844442182.7115,10.00004529953,80066.83984375,2.07308448415569,0.000197371127148
3844442202.6045,10.0008735656738,80364.6640625,2.07596765992012,0.000187991191355718
3844442222.663,9.99991607666016,80666.078125,2.07874167150506,0.000182917574052892
3844442242.6155,9.9998574256897,80965.47265625,2.08136366589282,0.000207672369961195
3844442262.6895,10.0000200271606,81266.75,2.08426917533075,0.00020507362452519
3844442282.541,9.99951267242432,81564.0234375,2.08689778675311,0.00018314918921389
3844442302.6125,10.0001368522644,81865.2578125,2.08963244592873,0.00018869275921119
3844442322.5315,9.99977588653564,82163.453125,2.09210241558556,0.000220261383250455
3844442342.554,10.0003476142883,82463.96875,2.09477642659722,0.000205356527135986
3844442362.606,9.99978399276733,82765.06640625,2.09732082867616,0.000181538830551431
3844442382.532,9.99989748001099,83064.171875,2.0999251701797,0.000208842161665116
3844442402.56,10.0009422302246,83364.08984375,2.10249648926672,0.000199695780563176
3844442422.436,10.0001978874207,83662.80078125,2.10497512031942,0.000208934207368138
3844442442.6405,10.0003061294556,83965.0703125,2.10769433428707,0.000229026360745734
3844442462.4095,9.99950695037842,84263.3359375,2.11022058317552,0.000180410598588404
3844442482.5125,10.0000653266907,84564.171875,2.11282823050444,0.000203272734249623
3844442502.5775,10.0004506111145,84864.72265625,2.11518139366199,0.000221540729047437
3844442522.3895,10.000331401825,85162.578125,2.11759042155358,0.000210924655134045
3844442542.346,10.0001111030579,85462.2421875,2.12037589804758,0.00021742202825918
3844442562.347,9.99932289123535,85762.31640625,2.12261890231119,0.000214979686262954
3844442582.4735,9.99979686737061,86064.4609375,2.1245965402717,0.000196395009506822
3844442602.2965,9.99954175949097,86361.44921875,2.1272687750055,0.000198802985396704
3844442622.421,10.0003275871277,86663.14453125,2.12939543350731,0.000191114190187741
3844442642.289,9.99981498718262,86962.33203125,2.13155280428906,0.000169274042578498
3844442662.3445,10.000180721283,87262.06640625,2.13410628132777,0.000192279118139512
3844442682.2535,9.99990034103394,87560.26171875,2.13651632469735,0.000182260682455418
3844442702.275,9.99986410140991,87860.80078125,2.13886051529185,0.000199768913856298
3844442722.369,9.99933958053589,88161.7109375,2.14086430112447,0.000196319721611543
3844442742.21,10.0004286766052,88460.02734375,2.14316615025447,0.000195540268193701
3844442762.3255,9.99970388412476,88761.41015625,2.14550219756355,0.000199901420302125
3844442782.2025,10.0001649856567,89059.92578125,2.14738662846704,0.000221768875308208
3844442802.287,9.9998459815979,89361.00390625,2.1497898400243,0.000198527837905737
3844442822.3245,9.99985694885254,89660.98828125,2.15239236302326,0.000213568371148521
3844442842.128,10.0008273124695,89958.46875,2.15384525184041,0.000184065371453061
3844442862.159,9.99972772598267,90258.66796875,2.15663095255713,0.000204991684216312
3844442882.1625,9.99963474273682,90559.0078125,2.15873810962565,0.000215364133627375
3844442902.103,9.99900150299072,90859.03125,2.16053235651938,0.000187099504690447
3844442922.064,10.0004744529724,91159.2890625,2.16252696182881,0.000205682453449321
3844442942.1505,9.99986267089844,91459.375,2.1647851849862,0.000216733502032801
3844442962.123,9.99971199035645,91760.2578125,2.1670706315399,0.000196660210296818
3844442982.0725,10.0006384849548,92059.08203125,2.16888499536608,0.000216211829765762
3844443002.1055,10.0000224113464,92360.78515625,2.17091173361902,0.000182055425442254
3844443021.997,10.0009140968323,92658.2265625,2.17293825565329,0.000224122051669882
3844443042.07,10.0001082420349,92958.9140625,2.17443764754637,0.000212721726978735
3844443061.985,10.0004014968872,93257.62109375,2.17667715049913,0.000203139218418546
3844443082.0995,10.0001893043518,93559.77734375,2.17888570875529,0.000205218863752717
3844443101.938,10.0003342628479,93858.46484375,2.18075694749324,0.000212109196874996
3844443122.007,10.0002722740173,94159.11328125,2.18275493131526,0.000217776619075391
3844443141.9505,10.0006828308105,94458.17578125,2.1843322131286,0.000212170943009001
3844443161.997,10.0001606941223,94758.98828125,2.18694867804725,0.000215517533656771
3844443181.888,10.0000114440918,95057.00390625,2.18819796300773,0.000210494163626353
3844443201.8595,9.9997296333313,95356.73828125,2.19016521948347,0.000207591874765294
3844443221.8865,10.0000281333923,95657.390625,2.19241894362842,0.000225171381995742
3844443242.016,10.0000486373901,95958.90625,2.19374519189597,0.000198855639047908
3844443261.8415,10.0004868507385,96255.8828125,2.19583398457602,0.000196300610755681
3844443281.933,10.0007176399231,96557.71875,2.19760999634303,0.000186141191647538
3844443301.979,10.0001606941223,96858.5859375,2.19950681837162,0.000200632012608374
3844443321.7725,10.000039100647,97155.95703125,2.20153678870488,0.000225230041393404
3844443341.9135,9.99904727935791,97458.20703125,2.20338501240026,0.000216548352973247
3844443361.762,10.000590801239,97755.0546875,2.20486581289912,0.000201001887710801
3844443381.726,10.0009512901306,98054.92578125,2.20675452881713,0.000208096224466477
3844443401.736,10.000581741333,98355.328125,2.20853975725037,0.000201376131253989
3844443421.841,9.99982309341431,98657.078125,2.21042954029793,0.000218074077108666
3844443441.702,9.99990177154541,98955.8203125,2.21192061813398,0.000201539418260103
3844443461.752,9.9997410774231,99257.01171875,2.2135195328822,0.000212157583152491
3844443481.6535,9.99959754943848,99554.73828125,2.21516306213212,0.000228734510890966
3844443501.7055,10.0000004768372,99856.44921875,2.21691461227595,0.000216965003923036
3844443521.6465,9.99981546401978,100155.63671875,2.21861690919249,0.000209792088357331
3844443541.743,9.99936103820801,100457.43359375,2.22028782215482,0.000214743694856763
3844443561.677,9.99973011016846,100755.08984375,2.22189145182615,0.000218429185731506
3844443581.613,10.0004119873047,101054.4609375,2.22363714894552,0.000216453507623737
3844443601.6305,10.0001406669617,101355.08984375,2.22514578284974,0.000227547786719696
3844443621.537,10.0011615753174,101653.70703125,2.22654100971313,0.000200675576606776
3844443641.5495,10.0002236366272,101953.52734375,2.22830133828709,0.000218755338431771
3844443661.55,9.99949836730957,102253.34765625,2.22976829602922,0.000209466111172363
3844443681.6505,10.0008964538574,102554.8125,2.23144836418509,0.000204606558969497
3844443701.621,10.0001034736633,102854.68359375,2.23303666687384,0.000225850074657141
3844443721.5005,9.9992036819458,103152.14453125,2.23481259153461,0.000213576391296579
3844443741.573,10.0000524520874,103453.68359375,2.23623893960899,0.000226380185252437
3844443761.5515,10.0007901191711,103753.19140625,2.23778206081645,0.000202515307667128
3844443781.5055,9.99962377548218,104052.484375,2.23974059790383,0.000204976991295607
3844443801.4335,10.0008935928345,104351.74609375,2.24109563971841,0.000223966229037768
3844443821.479,9.99967002868652,104652.65234375,2.24260345722491,0.000207613886794653
3844443841.431,9.99976301193237,104952.4765625,2.24396192099977,0.000216205618679678
3844443861.41,10.0007209777832,105251.71875,2.24536779261121,0.000214619214777704
3844443881.343,10.0003747940063,105550.796875,2.24728730278659,0.000205086002597548
3844443901.349,10.0001120567322,105850.89453125,2.24881576010647,0.000194551376252184
3844443921.4385,10.0002312660217,106152.70703125,2.25009982814011,0.00020564097018334
3844443941.331,9.99971103668213,106451.4921875,2.25157499703123,0.000206251976096254
3844443961.4325,9.99940967559814,106752.36328125,2.25269807523999,0.000203185612799212
3844443981.3325,10.0021677017212,107052.40234375,2.25408195060215,0.000219499131649099
3844444001.3715,9.99995994567871,107352.2734375,2.25528948643306,0.0002014191157918
3844444021.358,9.99597692489624,107652.37890625,2.25688486530096,0.000174986755275103
3844444041.2525,9.99534034729004,107950.109375,2.25860386931457,0.000182664227546915
3844444061.348,9.9997673034668,108251.140625,2.25948137141754,0.000194510908304638
3844444081.4105,10.0021300315857,108552.37109375,2.26106932348654,0.000205919950881702
3844444101.212,9.99898433685303,108849.546875,2.26274556371706,0.000200750446792699
3844444121.1835,9.99801826477051,109148.5546875,2.26401032426372,0.000197005886336897
3844444141.166,10.0003800392151,109448.61328125,2.26536366671691,0.000219615827621481
3844444161.1765,10.0008893013,109749.0546875,2.26702256864951,0.000226451177702671
3844444181.3555,9.9993257522583,110051.4296875,2.26824906399244,0.000227237453100318
3844444201.1495,9.99894332885742,110348.625,2.2692909727038,0.000231415406281184
3844444221.2095,10.0017352104187,110649.47265625,2.27045838052316,0.000206683408087286
3844444241.1325,10.00062084198,110948.58984375,2.27203532805377,0.000190225847290235
3844444261.146,9.99985027313232,111248.3828125,2.27365693611712,0.000213319999378329
3844444281.1,10.0010933876038,111548.05859375,2.27450103386971,0.000214065100571907
3844444301.1755,10.0008840560913,111849.765625,2.27593616053346,0.000196143771952473
3844444321.0335,10.0004806518555,112146.8125,2.2767281287484,0.0002144509986833
3844444341.094,9.9994158744812,112448.515625,2.27823165573027,0.00023669220152674
3844444361.0105,10.0000510215759,112747.48828125,2.27959336843002,0.000223203638576443
3844444381.023,9.99853467941284,113048.3125,2.2811688540916,0.000209250073074964
3844444401.004,10.0006313323975,113347.51953125,2.28220057645167,0.000227447268650356
3844444421.087,9.99856424331665,113648.98828125,2.28390828380226,0.000228463199430821
3844444440.9705,10.002815246582,113947.69140625,2.28495066717209,0.000211858153301063
3844444461.019,10.0009260177612,114247.6171875,2.28588260233962,0.000201317968668307
3844444480.9235,10.0003957748413,114546.84765625,2.28733572530119,0.000196540227115197
3844444500.8935,10.0008335113525,114846.99609375,2.28874143255694,0.000206253018445896
3844444520.939,10.0002098083496,115148.3828125,2.28981291977069,0.000220553051236025
3844444540.874,9.99897575378418,115446.9375,2.29100768449188,0.000217728052203152
3844444560.96,9.99977493286133,115748.28125,2.2917512412411,0.00019507399226173
3844444580.839,10.0007829666138,116045.4765625,2.29299758623772,0.000222859414727383
3844444600.9535,9.9984335899353,116346.79296875,2.29417077532159,0.000221396930347891
3844444620.8555,9.99897575378418,116646.0234375,2.29541039898596,0.000201054993634044
3844444640.8655,9.99957180023193,116945.9140625,2.2966694244269,0.000231424905984177
3844444660.9345,9.99958562850952,117246.3515625,2.2980911764428,0.000259946166538839
3844444680.842,10.0004720687866,117546.13671875,2.29914750595042,0.000233396727503344
3844444700.792,10.0004234313965,117845.46484375,2.30006876311108,0.000203232557778347
3844444720.7245,10.0009942054749,118143.97265625,2.30131924310896,0.000227989329063929
3844444740.7955,9.99849510192871,118444.85546875,2.30223151923781,0.000214930740906547
3844444760.695,9.99980926513672,118743.3046875,2.30359982375509,0.000231963593366576
3844444780.7455,10.0008397102356,119045.03125,2.30430223549498,0.000197916723037572
3844444800.688,10.000470161438,119344.58984375,2.30557631356382,0.000227788727731582
3844444820.6575,10.0007696151733,119643.890625,2.30689187319571,0.000216562207222443
3844444840.6705,9.99942970275879,119944.40234375,2.30815348500048,0.000218645072895374
3844444860.632,9.99992609024048,120244.53125,2.30942479170363,0.000227533166279533
3844444880.658,9.99963092803955,120544.9375,2.31012738421325,0.000209894243948067
3844444900.702,9.99891185760498,120845.73828125,2.31118070337177,0.000211913475056925
3844444920.609,10.0010824203491,121144.03515625,2.31220579752733,0.00023799857352056
3844444940.6855,9.99894952774048,121446.21875,2.31288562902659,0.000197375125061069
3844444960.614,9.99914646148682,121744.82421875,2.31450670848447,0.000234315142298558
3844444980.6725,9.99962759017944,122045.7890625,2.31563319296786,0.000202237854900169
3844445000.599,10.0001111030579,122344.90625,2.31647446662954,0.000204961129885581
3844445020.613,9.99968910217285,122644.9609375,2.31787551751536,0.000235392656192771
3844445040.5515,9.99985218048096,122944.109375,2.31859935402395,0.000208509597675351
3844445060.4835,9.99879789352417,123241.83203125,2.31944454946994,0.000181513195819478
3844445080.5845,9.99734210968018,123543.765625,2.32071069260225,0.000212688515660365
3844445100.4855,9.99976301193237,123841.7578125,2.32178617087643,0.000229743532778739
3844445120.441,9.99930381774902,124140.57421875,2.32289892002534,0.000243344379712193
3844445140.4705,10.0018129348755,124440.6796875,2.32389202686496,0.000221633827046879
3844445160.5405,10.000385761261,124741.95703125,2.32454255482123,0.000245453417191188
3844445180.5465,9.99878358840942,125042.64453125,2.32565280588681,0.000213619985606507
3844445200.383,9.99991130828857,125339.703125,2.32672615312014,0.000232068649447565
3844445220.474,9.99783897399902,125641.22265625,2.32777529940705,0.000229148860034885
3844445240.373,10.0054697990417,125940.05078125,2.32839770512657,0.000196502948298302
3844445260.405,9.99665594100952,126240.734375,2.32919194569943,0.000208777006540844
3844445280.4425,10.0046029090881,126541.3515625,2.33050448864081,0.000215641566836314
3844445300.3645,9.99814939498901,126839.7578125,2.33134110453879,0.000219754776267403
3844445320.4255,9.99810171127319,127140.91796875,2.33230390389361,0.000246841210228454
3844445340.2615,10.0031929016113,127438.10546875,2.33308907968756,0.000203839584156049
3844445360.3355,9.99893665313721,127739.6875,2.33416527324562,0.000230753935241365
3844445380.2635,9.99712467193603,128038.19140625,2.33466099376199,0.000228235477268009
3844445400.2755,10.0013451576233,128339.37890625,2.33584210415532,0.000199480630415569
3844445420.2205,10.0009455680847,128638.8046875,2.33698725165217,0.00023469549580957
3844445440.246,9.99847173690796,128939.48828125,2.33756081629696,0.00017722261336556
3844445460.179,10.0002493858337,129238.55078125,2.33867724167575,0.000214338613361892
3844445480.1885,10.0005412101746,129538.8125,2.33913951272374,0.000221872672269537
3844445500.284,9.99935007095337,129840.51171875,2.34034070013332,0.000241685163884455
3844445520.157,9.99920797348022,130138.3828125,2.34151149799929,0.000221608710621445
3844445540.2225,10.0018858909607,130439.50390625,2.34222832746439,0.000220985549537184
3844445560.2295,9.9993462562561,130739.46484375,2.34338627361637,0.000243711701143819
3844445580.18,10.0008025169373,131038.87109375,2.3440712708391,0.000223342283764725
3844445600.1015,10.0002255439758,131337.9453125,2.34489844933025,0.000231630704410974
3844445620.209,9.99740648269653,131639.609375,2.34573747314657,0.000222416498867837
3844445640.136,9.99656867980957,131937.9921875,2.34675177732614,0.000209418180188839
3844445660.0365,10.0012302398682,132236.15625,2.34700188985876,0.00022553458014142
3844445680.043,10.000762462616,132536.046875,2.34837400578587,0.000232079559297699
3844445700.1635,10.0000877380371,132837.390625,2.34904624819922,0.000226527188954051
3844445720.0855,10.0000076293945,133136.4921875,2.34993670264473,0.000218109810820473
3844445739.9935,9.99895620346069,133435.71875,2.35089923104349,0.000196056967902301
3844445759.986,9.99929857254028,133735.125,2.35182281182894,0.000230286383287536
3844445780.1905,10.0005660057068,134038.234375,2.35212886497415,0.000208702549211196
3844445800.008,9.9997935295105,134334.8671875,2.35307991898474,0.000233082693485741
3844445819.911,9.99975872039795,134634.1796875,2.35394248539535,0.000196740579701383
3844445839.9215,10.0002517700195,134933.7421875,2.35501209306218,0.000215827369232019
3844445859.965,9.99852991104126,135235.296875,2.35539364388503,0.000232170749436667
3844445880.017,10.0002374649048,135537.21875,2.35633435947275,0.000234137528659214
3844445899.858,10.0000138282776,135834.2265625,2.35699546266706,0.000229240322768393
3844445919.92,10.0002861022949,136135.96875,2.35803540856465,0.000227825377339258
3844445939.8815,10.0001263618469,136436.25,2.35874487916858,0.000211869741635527
3844445960.041,10.0004343986511,136738.484375,2.35954641451482,0.000235414498721019
3844445979.834,9.99971437454224,137034.6484375,2.36035314988215,0.000234222664967054
3844445999.796,10.0005369186401,137334.4921875,2.3609811410072,0.000219882794169847
3844446019.805,10.0000190734863,137635.0234375,2.3620639538567,0.000215264313017833
3844446039.876,10.0007610321045,137936.6328125,2.36272975779232,0.000219725447677636
3844446059.7665,10.000256061554,138234.4765625,2.36355038839485,0.000206704626588701
3844446079.8245,10.0004653930664,138535.25,2.36448371676329,0.000188639851789214
3844446099.8675,9.99992656707764,138836.4375,2.36475438310819,0.000239264439972745
3844446119.747,9.99841070175171,139134.2734375,2.36570823028957,0.000225610356041928
3844446139.79,9.99966478347778,139435.5,2.36622909798589,0.00021933120751503
3844446159.7315,9.99985265731812,139734,2.36696869860649,0.000232814661737124
3844446179.6655,10.003707408905,140035.15625,2.36789003674328,0.000231005105301202
3844446194.6365,10.0007772445679,140000.84375,2.36776951459862,0.000212587665298903