File: MvsH/data/2021-10-25_EROI_34P8MG_MVSH_40P0K.DAT
Time Stamp (sec),Temperature (K),Magnetic Field (Oe),Moment (emu),M. Std. Err. (emu)
3844459740.728,39.9751594370731,0.213336005806923,,
3844459834.597,39.9819869995117,-4842.00024414063,-0.0852992688147687,2.76020092876811E-5
3844459854.4905,39.9838733673096,-4543.47973632812,-0.0800165400867326,2.78058440140522E-5
3844459874.544,39.9872932434082,-4242.08959960937,-0.0747531101899464,2.80403725671935E-5
3844459894.4795,39.9866714477539,-3943.96508789063,-0.0694859959264262,2.8171383861123E-5
3844459914.498,39.9892158508301,-3643.54724121094,-0.0642186786972699,2.74587822985079E-5
3844459934.4365,39.9891414642334,-3345.34875488281,-0.0589566775072403,2.76367600428952E-5
3844459954.4945,39.9900856018066,-3043.53955078125,-0.0536886202170282,2.73750321619606E-5
3844459974.461,39.9904327392578,-2743.87475585938,-0.0484361607673279,2.70614504636352E-5
3844459994.4565,39.9913940429687,-2443.78698730469,-0.0431611384081887,2.68586983047579E-5
3844460014.3975,39.9931678771973,-2144.6982421875,-0.0379100735610186,2.69767568888539E-5
3844460034.567,39.9939594268799,-1842.2216796875,-0.0326485410805735,2.68655656231856E-5
3844460054.453,39.9929714202881,-1544.62811279297,-0.0273877593921795,2.70234935376872E-5
3844460074.3305,39.9950160980225,-1246.70672607422,-0.0221380737009631,2.67612187026278E-5
3844460094.5045,39.9958553314209,-943.861358642578,-0.0168841349979289,2.68703002364182E-5
3844460114.3435,39.996187210083,-646.119995117187,-0.0116292150007887,2.69855305901656E-5
3844460134.281,39.9962158203125,-347.741851806641,-0.00637221370531555,2.67693345859056E-5
3844460159.618,39.9963226318359,31.527566999197,0.00020980382655988,2.40712040481555E-5
3844460179.3005,39.998104095459,326.833267211914,0.00548431395947998,2.68773215815119E-5
3844460199.2285,39.9976825714111,626.130950927734,0.010757227953271,2.69002425821698E-5
3844460224.321,39.9975643157959,1002.45489501953,0.0173570586391164,2.69793529628033E-5
3844460244.244,39.9989452362061,1300.68841552734,0.0226257440518125,2.70172152435184E-5
3844460264.1915,39.997257232666,1600.44244384766,0.0278997661219625,2.69870915707624E-5
3844460284.1635,39.9987945556641,1899.67834472656,0.0331640144301029,2.70784748567569E-5
3844460304.2585,39.9982166290283,2200.49194335938,0.0384455963075124,2.70505258083279E-5
3844460324.2735,40.0003337860107,2501.02233886719,0.043714445802011,2.71838769986047E-5
3844460344.134,39.9983806610107,2798.8095703125,0.0489904950166853,2.71639356611223E-5
3844460364.2055,39.9993953704834,3100.2275390625,0.0542589718528821,2.78748925179415E-5
3844460384.1245,39.9991264343262,3398.7822265625,0.0595307716513868,2.80834926271604E-5
3844460404.144,40.0007209777832,3699.44494628906,0.0647982190310888,2.7780934920321E-5
3844460424.1795,39.9997272491455,3999.10205078125,0.0700457402295117,2.73291996408428E-5
3844460444.138,39.9995803833008,4298.93359375,0.0753158515999044,2.79578046157146E-5
3844460464.139,39.9996013641357,4598.326171875,0.0805665464565447,2.82463872984393E-5
3844460484.053,39.9990215301514,4896.66967773438,0.0858255639571088,2.71094162492153E-5
3844460504.1615,40.0002574920654,5198.96997070313,0.0910980467653996,2.769806936697E-5
3844460524.0105,40.0000858306885,5496.67504882812,0.0963506271899714,2.84979683877183E-5
3844460548.984,39.9991970062256,5871.71875,0.102942477530189,2.9140346378258E-5
3844460568.973,40.0003280639648,6170.99780273437,0.108198553897952,2.83446631886617E-5
3844460589.022,40.0003528594971,6472.2626953125,0.113455299733005,2.94821927272721E-5
3844460609.12,40.0004863739014,6772.74438476563,0.118689796304531,2.93305643773715E-5
3844460628.967,40.0004844665527,7070.96044921875,0.123933721054239,2.813933461212E-5
3844460648.9505,40.0001697540283,7371.275390625,0.129197355928432,3.02735222594796E-5
3844460669.0975,39.9997787475586,7672.68823242188,0.134447791922509,2.9812800432555E-5
3844460688.885,40.0003261566162,7969.59228515625,0.13969999338889,3.23677202787303E-5
3844460709.0525,40.0000801086426,8271.7978515625,0.144944183110023,2.87490356780186E-5
3844460728.954,39.9994087219238,8570.38818359375,0.15020756660895,3.03071120681532E-5
3844460748.91,40.0000019073486,8869.61474609375,0.155426575159384,3.08821511242497E-5
3844460768.9905,39.999662399292,9170.67724609375,0.160700996643547,3.17020847163132E-5
3844460788.8045,39.9998302459717,9467.50341796875,0.165916208675541,3.0546685279967E-5
3844460808.935,39.9993171691895,9769.728515625,0.171182846948687,3.15514399887147E-5
3844460828.768,40.000452041626,10067.4799804688,0.176411096084421,3.17896399431798E-5
3844460848.781,39.9988689422607,10367.6982421875,0.181676900963114,3.28308223839067E-5
3844460868.8065,39.9996643066406,10668.9868164062,0.186926590162015,3.5692384592076E-5
3844460888.7285,40.0002918243408,10968.1279296875,0.192158057241841,3.37235909219685E-5
3844460908.758,39.9997444152832,11267.5776367187,0.197406217728796,3.59764454466713E-5
3844460928.7505,40.0005931854248,11567.4565429688,0.202650579913054,3.50360100260817E-5
3844460948.834,39.9999504089355,11868.6186523437,0.207861022442124,3.03096440558906E-5
3844460968.714,39.9999866485596,12166.8950195313,0.213124863922071,3.50447286930348E-5
3844460988.6535,40.0006122589111,12466.3994140625,0.218356263872359,3.40034556267849E-5
3844461008.79,40.0003223419189,12767.9169921875,0.223594854220972,3.35135070835531E-5
3844461028.652,40.0003681182861,13066.2573242187,0.22879505286674,3.47026162202479E-5
3844461048.686,40.0001583099365,13366.9057617188,0.234004280176072,3.49743131627167E-5
3844461068.7085,39.999849319458,13666.7592773437,0.239254904930017,3.51783553491345E-5
3844461088.688,40.0001487731934,13966.9047851562,0.244496185244754,3.70317900321056E-5
3844461108.677,39.9997653961182,14266.0346679688,0.249757637164147,3.77589997603139E-5
3844461128.6955,40.0007381439209,14566.3076171875,0.254910143103369,3.93334188063744E-5
3844461148.6515,40.0001277923584,14865.4448242187,0.260156077261694,3.68392911441447E-5
3844461168.5675,40.0001773834229,15164.962890625,0.265400341836409,3.59404816873195E-5
3844461188.6675,39.9994220733643,15466.384765625,0.270576155957864,3.5986172548438E-5
3844461208.501,40.0002784729004,15763.65625,0.275777331401863,3.70765946441178E-5
3844461228.5565,40.0006046295166,16064.2661132812,0.281064397067257,3.57180602641805E-5
3844461248.5405,40.0011310577393,16364.4584960938,0.286290187230516,4.05694403471705E-5
3844461268.459,39.9993000030518,16662.8779296875,0.291423455743938,3.75608480018646E-5
3844461288.587,40.0003128051758,16964.75390625,0.296659802641793,3.92666373106216E-5
3844461308.477,40.0002403259277,17263.1533203125,0.301874043939972,3.65269269713792E-5
3844461328.4885,40.00022315979,17563.9794921875,0.307069912802352,3.80450598244881E-5
3844461348.4175,40.0005722045898,17861.7666015625,0.312300299235986,4.27096748448972E-5
3844461368.432,39.9993629455566,18162.203125,0.317486115045653,4.00261681350686E-5
3844461388.3505,40.0003395080566,18460.8837890625,0.322704423026285,4.31646644661817E-5
3844461408.476,40.0005302429199,18763.0146484375,0.327810774708603,3.87581513831317E-5
3844461428.322,39.9998931884766,19061.00390625,0.333093462992056,3.78685597373192E-5
3844461448.51,39.9999694824219,19363.8515625,0.338234448182885,3.92255442824835E-5
3844461468.295,39.9999389648438,19660.4912109375,0.34342172943252,3.80518342673193E-5
3844461488.288,39.9998874664307,19959.6005859375,0.34860596115966,4.08400793282699E-5
3844461508.4285,39.999662399292,20262.1171875,0.35382544985295,4.30308549144776E-5
3844461528.3225,39.9995765686035,20560.482421875,0.358944236589824,4.27914024157207E-5
3844461548.2875,39.9998817443848,20859.5263671875,0.364188797517993,4.5281606932464E-5
3844461568.253,40.0003433227539,21159.46875,0.369348623994795,4.30566449718723E-5
3844461588.2205,39.9998645782471,21458.798828125,0.374524474424495,4.18800331803166E-5
3844461608.226,39.9999961853027,21758.8271484375,0.379761646147192,4.4173646790685E-5
3844461628.3625,40.00022315979,22060.9736328125,0.384973378253177,4.51444131675001E-5
3844461648.186,40.0001831054687,22358.2578125,0.390051161261097,4.68884667201858E-5
3844461668.2725,39.9999256134033,22659.697265625,0.395225699973231,4.58350022659786E-5
3844461688.1785,39.9993209838867,22958.408203125,0.400385958014968,4.38932122761765E-5
3844461708.1825,40.0006294250488,23258.3505859375,0.405504070645572,4.90745401242968E-5
3844461728.2455,39.9997119903564,23559.0947265625,0.410727116119389,4.96486590594337E-5
3844461748.09,39.9999446868897,23856.833984375,0.415845852104678,4.3790153196631E-5
3844461768.1825,39.9998302459717,24158.388671875,0.421036467839614,4.66978052848988E-5
3844461788.0965,39.9997005462646,24456.9755859375,0.426183630480297,4.61668882613755E-5
3844461808.212,39.9998226165771,24758.1708984375,0.43128619105541,4.50340305718331E-5
3844461828.0465,39.9994659423828,25055.7802734375,0.436429827354831,4.65512845933936E-5
3844461848.015,40.0000514984131,25355.7314453125,0.44163710196272,5.20607500206835E-5
3844461868.0355,39.9996242523193,25655.9345703125,0.446746202501578,5.0004150548701E-5
3844461888.0865,39.9996032714844,25956.5166015625,0.451900415034327,4.86703474507551E-5
3844461907.9985,40.0000095367432,26255.2060546875,0.457041914954261,5.11857985039199E-5
3844461928.0985,40.000129699707,26556.6025390625,0.462168293372545,5.25320728589192E-5
3844461948.0275,40.0006675720215,26856.142578125,0.467171699516568,5.19031998515397E-5
3844461967.997,39.9995574951172,27155.3076171875,0.472254028690141,5.35001397339606E-5
3844461987.9195,40.0002174377441,27453.4921875,0.47745648423438,4.84115628168619E-5
3844462007.997,39.9994659423828,27754.8720703125,0.482634709225768,5.13734041741188E-5
3844462027.9965,39.9990425109863,28055.0458984375,0.487749898440551,5.60165490162941E-5
3844462047.941,39.999813079834,28355.009765625,0.492860621137139,5.36494985917907E-5
3844462067.8805,39.9992294311523,28653.431640625,0.497956838376511,5.27065911256843E-5
3844462087.946,39.9997901916504,28954.1611328125,0.502982669834182,5.58288240095383E-5
3844462107.821,39.9989070892334,29252.662109375,0.508179612665511,5.34822344701714E-5
3844462127.9055,40.0000247955322,29553.5087890625,0.513193166075957,5.11765807437069E-5
3844462147.801,39.9995155334473,29851.7763671875,0.518284063706238,5.80289142802741E-5
3844462167.8735,40.000072479248,30152.9072265625,0.523389044828817,5.13643955903787E-5
3844462187.825,39.9991188049316,30452.0224609375,0.528446668325323,5.72188493317525E-5
3844462207.752,39.9985771179199,30750.7734375,0.533637644149907,5.34637435622671E-5
3844462227.79,40.0001277923584,31052.2724609375,0.53863871575729,5.41311493331921E-5
3844462247.8175,40.0001125335693,31354.0361328125,0.543614346999629,5.44473417307233E-5
3844462267.7485,39.9995956420898,31651.6669921875,0.548799150474626,5.25525164674808E-5
3844462287.873,40.0000476837158,31954.2294921875,0.553783341161499,5.35613369033885E-5
3844462307.7645,40.0005397796631,32252.5029296875,0.558840963371092,5.76684474855471E-5
3844462327.686,40.0000076293945,32551.4921875,0.563781822720208,4.98649913746548E-5
3844462347.742,39.9999027252197,32851.279296875,0.568978477886512,5.28347790845414E-5
3844462367.793,39.9995422363281,33151.734375,0.574048541577916,6.47644684926524E-5
3844462387.6665,40.0003471374512,33450.50390625,0.579017986382876,6.1708810951983E-5
3844462407.628,39.9997882843018,33750.396484375,0.584013211852601,5.58163313558067E-5
3844462427.602,40.0000019073486,34049.814453125,0.589178521004209,6.33503523665488E-5
3844462447.58,39.9992141723633,34348.98828125,0.594169111263257,5.93082034772698E-5
3844462467.665,40.0001544952393,34650.72265625,0.59921255140513,5.7065345315314E-5
3844462487.676,39.9997081756592,34951.3125,0.60412409373144,5.25865356960725E-5
3844462507.5715,39.9997291564941,35249.28515625,0.609193282564779,5.54206112303382E-5
3844462527.5105,39.9998435974121,35548.5,0.614235738915954,6.15601175955305E-5
3844462547.5235,40.000114440918,35848.5625,0.619271621809992,6.37416102395058E-5
3844462567.5395,39.999059677124,36148.533203125,0.624244508662794,6.06206413776557E-5
3844462587.452,40.00022315979,36447.099609375,0.629146568965135,6.04068862857067E-5
3844462607.674,39.9996166229248,36750.236328125,0.634193091239506,7.05830455987545E-5
3844462627.524,40.0001602172852,37048.62109375,0.639073715838987,6.30845910249277E-5
3844462647.421,40.0003623962402,37347.16015625,0.644078527849366,6.63943657716274E-5
3844462667.424,39.999792098999,37647.0078125,0.649048330687556,6.299066389205E-5
3844462687.4675,39.999662399292,37947.4140625,0.653979936714714,6.41420566931996E-5
3844462707.382,39.9992542266846,38245.83984375,0.6589309371047,6.25799515586749E-5
3844462727.508,40.0001468658447,38548.142578125,0.664007212852927,6.61802923452891E-5
3844462747.369,40.0001468658447,38845.1875,0.668828915820233,6.58236526175215E-5
3844462767.3865,39.9992198944092,39146.123046875,0.673877243375367,6.76138717078187E-5
3844462787.325,39.9996929168701,39445.20703125,0.678854446454625,7.3618625787575E-5
3844462807.369,39.9993152618408,39746.041015625,0.68381050849457,7.50335921803686E-5
3844462827.3635,40.0002002716064,40046.828125,0.688723031151998,6.76136424104397E-5
3844462847.2825,39.9999656677246,40345.2421875,0.693781592747992,7.30789888148687E-5
3844462867.3525,40.0003795623779,40645.091796875,0.698642926592066,7.17166949363104E-5
3844462887.3095,40.0000038146973,40945.095703125,0.703557076582315,6.69654877090435E-5
3844462907.2455,40.0006046295166,41244.76171875,0.708476007432523,7.63913712798776E-5
3844462927.218,39.9993915557861,41544.041015625,0.713452244086538,6.80028490262838E-5
3844462947.185,39.9996109008789,41843.849609375,0.718373092280181,6.98792521911932E-5
3844462967.202,39.9995613098145,42143.896484375,0.723107488549901,6.84849057812675E-5
3844462987.1805,40.0001659393311,42444.22265625,0.728102208980155,7.65862697159306E-5
3844463007.2295,40.0000705718994,42744.328125,0.733022045061289,6.99367044970546E-5
3844463027.376,39.9996948242188,43046.236328125,0.737893882487498,7.96574994838282E-5
3844463047.1285,40.0002708435059,43342.37109375,0.74265474185858,6.86548712617506E-5
3844463067.13,39.999755859375,43642.517578125,0.747674095369174,7.55210981336947E-5
3844463087.1315,40.0006885528564,43942.623046875,0.752445815241216,7.32032275479902E-5
3844463107.195,40.0009117126465,44244.08203125,0.757169414579881,6.85317062306168E-5
3844463127.1875,39.9999160766602,44544.103515625,0.762094179019528,6.71400972081757E-5
3844463147.2275,39.9997215270996,44844.765625,0.766991012737369,7.41133799082543E-5
3844463167.044,40.0006370544434,45142.00390625,0.771758386335295,7.59415350062299E-5
3844463187.0475,39.9995880126953,45442.03515625,0.776675505697807,6.82309337431293E-5
3844463207.037,40.0002422332764,45740.791015625,0.781552773922185,8.92334929960456E-5
3844463227.003,39.999153137207,46040.732421875,0.786294016568524,8.59371008803591E-5
3844463247.031,40.0001182556152,46341.6796875,0.791138564323073,7.82543794217283E-5
3844463267.001,39.9996547698975,46640.96484375,0.795963188335419,8.32212330579875E-5
3844463286.979,40.0002422332764,46941.029296875,0.80073109835397,7.57997931175542E-5
3844463306.935,39.9995136260986,47240.150390625,0.805587465274413,7.89488374346279E-5
3844463327.0465,39.9998645782471,47541.7890625,0.810399775594523,7.94217714630037E-5
3844463346.9465,39.9998912811279,47840.197265625,0.815056497456204,7.12648479382192E-5
3844463366.9455,39.9997177124023,48140.791015625,0.819748335027428,8.06441030965471E-5
3844463386.871,40.0001277923584,48438.892578125,0.824521510541905,7.49001478422553E-5
3844463406.959,39.999906539917,48740.291015625,0.829255137924464,7.8401376494472E-5
3844463426.9635,40.0010261535645,49040.5703125,0.834068948455381,8.15923727176872E-5
3844463446.83,39.9986972808838,49338.912109375,0.838822099258961,7.83555594275376E-5
3844463466.82,39.9983501434326,49638.16015625,0.84352836186517,7.31456833651581E-5
3844463486.967,40.0004749298096,49940.333984375,0.848209562985853,8.02915996356709E-5
3844463506.855,39.99928855896,50239.04296875,0.853045198889495,7.72632934550454E-5
3844463526.955,40.0007495880127,50539.73046875,0.857733396079974,7.0463488225937E-5
3844463546.821,39.9995346069336,50837.845703125,0.862561962510744,8.91099637531401E-5
3844463566.843,39.9996147155762,51138.541015625,0.867380759323902,8.48141169434998E-5
3844463586.814,40.0002460479736,51438.7578125,0.872205238609324,8.40357543875468E-5
3844463606.6975,39.9997634887695,51735.78125,0.876813953380802,9.27981013811522E-5
3844463626.8055,39.9992408752441,52038.201171875,0.881417689750205,8.24948433154325E-5
3844463646.688,40.0004081726074,52336.890625,0.886172605147879,7.6437675202735E-5
3844463666.7435,40.0007476806641,52638.55859375,0.890824510491702,8.31846160387989E-5
3844463686.869,39.9996223449707,52940.40234375,0.895439182858944,8.83855575892457E-5
3844463706.6535,40.0002880096436,53237.3515625,0.900015090115324,8.89098976245513E-5
3844463726.762,39.999813079834,53539.400390625,0.904770406719411,8.86216728467869E-5
3844463746.6335,39.9999122619629,53837.16015625,0.90951003050444,9.32134551911293E-5
3844463766.7795,39.9992961883545,54138.9453125,0.914001352229889,7.92179995260461E-5
3844463786.6,39.9997882843018,54436.560546875,0.918588304960675,7.93947845476777E-5
3844463806.642,39.9996128082275,54737.478515625,0.923404300571592,9.07873495357861E-5
3844463826.546,39.9996356964111,55035.90625,0.927975832745056,9.03229386034388E-5
3844463846.718,40.0000019073486,55338.08984375,0.932364856702689,8.16575564183905E-5
3844463866.63,39.9994277954102,55636.62109375,0.937097039875004,8.6276096826127E-5
3844463886.5685,39.9989566802978,55935.818359375,0.941741926929137,9.08642878277733E-5
3844463906.49,39.9999217987061,56234.767578125,0.946444454978163,9.49598836484779E-5
3844463926.4855,39.9998779296875,56534.73046875,0.950890625556329,7.99411219344475E-5
3844463951.7465,39.9998912811279,56913.525390625,0.956396433265363,0.000101579418826708
3844463971.4475,40.0006370544434,57208.9375,0.960849173936549,8.80125430291776E-5
3844463991.547,39.9995040893555,57510.861328125,0.965328042062821,9.16353346078488E-5
3844464011.5655,40.000171661377,57811.5078125,0.970058562158532,9.72490314252424E-5
3844464031.422,39.9992504119873,58109.5078125,0.974549356307977,9.68999201527217E-5
3844464051.5225,39.9997425079346,58410.779296875,0.979203285704992,8.98369114882843E-5
3844464071.361,40.0001430511475,58707.421875,0.983523666942766,0.000105368395166575
3844464091.422,40.0005359649658,59008.734375,0.988201244387215,0.000101171083691462
3844464111.4435,40.0003204345703,59308.84765625,0.992703642287599,9.20370688585779E-5
3844464131.411,39.9995346069336,59608.736328125,0.997342081052531,9.14154147286327E-5
3844464151.318,39.9994888305664,59907.2421875,1.00178310059618,9.04401341643501E-5
3844464171.303,39.9995193481445,60207.294921875,1.00634128106042,0.000106267514208244
3844464191.332,39.9999046325684,60507.966796875,1.01089933394131,9.51355319852141E-5
3844464211.311,40.0001068115234,60808.294921875,1.01517283607577,0.000107000869163832
3844464231.3585,40.0004024505615,61107.48828125,1.01973496924929,9.84237553363948E-5
3844464251.3715,40.0002174377441,61408.23828125,1.02430685236923,9.62352167611714E-5
3844464271.241,39.9997825622559,61706.84375,1.02878752722735,9.24450783908144E-5
3844464291.1905,40.0000534057617,62005.58984375,1.03318071240096,9.99068011925415E-5
3844464311.265,39.9998035430908,62307.970703125,1.0377969525452,0.000103590937373391
3844464331.1545,40.0005397796631,62605.630859375,1.04198462451999,8.15729532713133E-5
3844464351.2215,39.9984550476074,62906.474609375,1.04665629797625,0.000109646097075575
3844464371.2,40.0001697540283,63206.876953125,1.05099439747033,0.000101106078489737
3844464391.24,39.9993095397949,63507.513671875,1.05543802405739,0.000102283613480998
3844464411.1565,39.9993629455566,63805.80078125,1.05986350097473,0.000104290611359391
3844464431.09,39.9998378753662,64104.841796875,1.0641954146246,0.000109194390577778
3844464451.1265,40.0004444122314,64404.798828125,1.06848091224995,9.53940231223312E-5
3844464471.0795,39.9998569488525,64704.857421875,1.07300379542086,9.79545523079097E-5
3844464491.112,39.9992752075195,65004.89453125,1.07737893444384,0.00010645537390013
3844464511.0555,39.999626159668,65304.81640625,1.08165964909673,0.000101850625138602
3844464531.038,39.9998416900635,65604.02734375,1.08593773509967,9.726560623692E-5
3844464551.1175,39.9999160766602,65905.05859375,1.09030750708708,0.000102916078486811
3844464571.1195,39.9996089935303,66204.92578125,1.09456645916585,8.17148615151724E-5
3844464591.0175,40.0002670288086,66502.93359375,1.09895105644919,0.00010848098227401
3844464611.084,39.9998092651367,66804.40625,1.10318545270592,0.000107271543108709
3844464631.1305,39.9994983673096,67105.8828125,1.10767869680216,0.000107064442860026
3844464651.05,39.9995307922363,67403.54296875,1.11193957184187,9.85089688110631E-5
3844464671.0155,40.0008277893066,67702.8984375,1.1161698442434,0.000106961257304967
3844464690.9965,39.9998817443848,68003.5546875,1.120400211808,9.58638409322771E-5
3844464710.9585,39.9995555877686,68302.87890625,1.12470316442507,9.61915836643809E-5
3844464730.907,40.0000324249268,68602.30859375,1.12908843432592,0.000107193092940974
3844464750.867,39.9995517730713,68901.59375,1.13337550504939,0.000123749820890936
3844464770.859,39.9999523162842,69201.47265625,1.13773267697173,0.000113731435234509
3844464790.8545,40.000072479248,69501.58984375,1.14190164952897,9.90149280056651E-5
3844464810.8905,40.0001564025879,69801.97265625,1.14608675690212,0.000112658080475491
3844464830.8845,40.0000381469727,70102.05859375,1.15033211968514,9.64247646803456E-5
3844464850.966,40.0002746582031,70403.83984375,1.154653927088,0.000111574037073435
3844464870.7705,40.0004119873047,70700.87109375,1.15868916699874,0.000120065385614435
3844464890.772,39.9994735717773,71001.03125,1.16294132466104,0.000101894547446498
3844464910.793,40.0011253356934,71301.1640625,1.16714002603698,9.56270560936088E-5
3844464930.7715,39.999059677124,71601.74609375,1.17153107346792,0.000123733645282282
3844464950.7945,39.9986610412598,71901.51171875,1.17570790943376,0.000122749670999483
3844464970.7695,39.999963760376,72201.359375,1.17958735830841,0.000121401981155138
3844464990.7295,40.0001888275146,72500.8046875,1.18372044516478,0.000117583578596882
3844465010.741,39.9997482299805,72800.75390625,1.18775414940677,0.000108545845846771
3844465030.7275,40.000415802002,73101.6171875,1.19199110401811,9.2955000428453E-5
3844465050.7765,40.000072479248,73402.2890625,1.19634915152741,0.000122475367534898
3844465070.7315,39.9999408721924,73701.76171875,1.20018260230484,0.000105745517924224
3844465090.7775,39.9992961883545,74002.26953125,1.20456231372293,0.000133588812398727
3844465110.7255,40.0001487731934,74301.1484375,1.20861390730399,0.000120794256255212
3844465130.6425,40.0004196166992,74599.3828125,1.21230140914996,0.000100394095354854
3844465150.5845,40.0003204345703,74898.6171875,1.21657561688767,0.000114389502465326
3844465170.5625,40.0002708435059,75197.8984375,1.22063807376566,0.000104993199207026
3844465190.599,39.9999485015869,75498.6328125,1.22477434906606,0.000111543612644218
3844465210.6555,40.0001525878906,75800.3359375,1.22876902910814,0.000105972754537154
3844465230.5195,39.9999904632568,76097.92578125,1.23322718236169,0.000120939816021686
3844465250.58,40.0001773834229,76399.1796875,1.23699766677501,9.66797120193102E-5
3844465270.5325,39.9990177154541,76698.44921875,1.24118996396446,0.000121796966731357
3844465290.48,40.0007724761963,76997.4921875,1.24519461404942,0.000123262033693862
3844465310.544,40.0000801086426,77298.23828125,1.24947412145303,0.000122553051463229
3844465330.4665,39.9996242523193,77597.89453125,1.25342426142205,0.000104784577722482
3844465350.412,40.0009231567383,77897.31640625,1.2572740555319,0.000120419516161877
3844465370.459,39.9994087219238,78198.390625,1.26149681970776,0.000120980546113033
3844465390.47,40.0001735687256,78498.4609375,1.26526736985004,0.000116818224447431
3844465410.453,40.000560760498,78798.6171875,1.26919032689144,0.000114193613791692
3844465430.4675,39.9990863800049,79099.32421875,1.27325001860922,0.000120709058241034
3844465450.3775,39.9992198944092,79396.90234375,1.27736149307571,0.00012278872323282
3844465470.3495,40.0002765655518,79696.53515625,1.28117501662381,0.000125534470537076
3844465490.3705,39.9995365142822,79996.484375,1.28525219661585,0.000119009277696968
3844465510.3215,39.999813079834,80295.984375,1.28901460171714,0.000116593180615787
3844465530.359,39.9998264312744,80596.453125,1.29297790130428,0.000117074594396492
3844465550.3845,40.0002841949463,80896.62890625,1.29673212114866,0.000123986894917063
3844465570.261,39.998851776123,81195.81640625,1.30066081107177,0.000119902714138056
3844465590.3595,40.0001640319824,81496.7109375,1.30469932909316,0.000121554683005349
3844465610.3775,40.0006217956543,81797.23046875,1.30850351305279,0.000115015134566901
3844465630.216,39.9987277984619,82093.7421875,1.31224823415504,0.000120810195594491
3844465650.291,40.000415802002,82395.03125,1.31627578262698,0.000115490469983398
3844465670.1985,40.000825881958,82693.7421875,1.3200987049978,0.000121442641962097
3844465690.171,39.9996776580811,82993.74609375,1.32379678184954,0.000110160910184044
3844465710.2885,40.0007419586182,83295.11328125,1.3277019387047,0.00012026705723247
3844465730.1705,39.9999923706055,83593.9296875,1.33154859155201,0.000121438626001502
3844465750.237,39.9997749328613,83894.6953125,1.33548477826823,0.00012126813825291
3844465770.1395,40.0002288818359,84193.4921875,1.33913416280251,0.000134615620082858
3844465790.19,39.999698638916,84495.328125,1.34290808642607,0.000114755855287255
3844465810.0595,39.9998817443848,84792.8359375,1.3468078050188,0.000108548842219203
3844465830.183,39.9988288879395,85095.1015625,1.35084570497023,0.000135561255083623
3844465850.1105,39.9993953704834,85394.04296875,1.35463658817688,0.000132507976725957
3844465870.1765,39.9999980926514,85694.80078125,1.358086462153,0.000125823003261682
3844465890.016,40.0000782012939,85991.8828125,1.36204590483135,0.000124359508680554
3844465910.0235,39.999963760376,86292.625,1.36573990300096,0.000123518345152948
3844465929.998,39.9998073577881,86591.9609375,1.36970255160714,0.000148531647732974
3844465949.9965,39.9994869232178,86892.765625,1.37335184277684,0.000125115490340549
3844465970.074,39.9996166229248,87194.23046875,1.37708763365952,0.000129785912131457
3844465990.056,39.9995384216309,87492.36328125,1.38062108862085,0.000136464407584227
3844466010.0725,40.0005283355713,87793.609375,1.3844008978007,0.00012099292052084
3844466029.923,39.999547958374,88091.421875,1.38832638356854,0.000128298386184309
3844466049.9015,40.0003967285156,88390.66796875,1.39160920936089,0.000135193449983657
3844466069.982,39.9994888305664,88691.31640625,1.39529466856707,0.000122554167610806
3844466090.0625,39.9996852874756,88992.77734375,1.39911035906869,0.000132367179560301
3844466110.048,39.9994068145752,89293.046875,1.40284918919432,0.000147460929771533
3844466129.8515,40.0008068084717,89589.921875,1.40617737419963,0.00012963027657727
3844466149.9065,39.9992389678955,89891.33203125,1.4101563849769,0.000136080020328199
3844466170.006,40.0002193450928,90191.83984375,1.41362097891916,0.000137981835287759
3844466189.823,39.9989032745361,90489.81640625,1.41710783763893,0.000119414000927142
3844466209.964,40.0004405975342,90791.5703125,1.42073616626568,0.000140310517249249
3844466229.8105,39.9997444152832,91089.38671875,1.42484076681576,0.000138472967214577
3844466249.7835,39.9995059967041,91389.796875,1.42794765911498,0.000122500557098654
3844466269.7565,40.0000038146973,91688.984375,1.43194053667238,0.000139439045081531
3844466289.772,39.9993686676025,91989.4765625,1.43517325351875,0.000126586942492739
3844466309.85,39.9995784759521,92291.17578125,1.43901500416175,0.000144559433954445
3844466329.8255,40.0001125335693,92590.9609375,1.4424349898465,0.000135826828839949
3844466349.848,39.9996719360352,92891.6796875,1.44600102254465,0.000143277068102154
3844466369.782,40.0002059936523,93190.48828125,1.44961976732825,0.000138325674464971
3844466389.6415,39.9994430541992,93488.1640625,1.4532402905776,0.000140538423466937
3844466409.6635,39.9993801116943,93789.24609375,1.45677748579961,0.000134440856440419
3844466429.7635,40.0006542205811,94091.15625,1.46003882462016,0.00013496369641288
3844466449.735,39.9997940063477,94390.28515625,1.46344755872397,0.000131293256806574
3844466469.713,39.9994831085205,94690.44140625,1.46719806977132,0.000142691533908662
3844466489.5895,39.9994201660156,94988.8203125,1.47065328891448,0.000150734613822281
3844466509.7265,39.9996604919434,95289.80859375,1.47375202495302,0.000147938256868439
3844466529.5605,39.9999675750732,95587.453125,1.47732820448684,0.000131787089787771
3844466549.5585,39.9995231628418,95886.60546875,1.48082917899526,0.000134885253409984
3844466569.621,40.0008182525635,96188.0390625,1.48441763405934,0.000138309878545517
3844466589.4845,39.9996738433838,96486.734375,1.48791769545235,0.000156934488467568
3844466609.577,39.99977684021,96787.48046875,1.49121188772766,0.000143419063099243
3844466629.4975,40.0000762939453,97087.06640625,1.49461990185763,0.000143839044814886
3844466649.5265,40.0002117156982,97387.09375,1.49809864567145,0.000127487702593991
3844466669.489,40.0007953643799,97686.08203125,1.501422041016,0.000131474270115035
3844466689.429,40.0002117156982,97985.33203125,1.50454477891247,0.000132047648303404
3844466709.5065,40.0006980895996,98286.765625,1.50799630298828,0.000141495601331597
3844466729.393,40.0003833770752,98585.83984375,1.51142967808411,0.000156117988575772
3844466749.455,39.9999847412109,98886.71484375,1.51507445049808,0.000147798492007133
3844466769.377,39.9998683929443,99186.59765625,1.51845733714061,0.000131416603611364
3844466789.4615,40.0004653930664,99487.58984375,1.52166113954499,0.000142151308489562
3844466809.385,39.9996242523193,99787.2109375,1.52535167706161,0.00015505450639813
3844466829.4335,39.999002456665,100087.80859375,1.52887507825728,0.000151403887901239
3844466849.2945,40.0000076293945,100385.3125,1.531900197529,0.000137751247674587
3844466869.4265,39.9993801116943,100687.33984375,1.53500488375717,0.000139232785517042
3844466889.273,39.9995555877686,100985.1328125,1.53836308979771,0.000151157819406076
3844466909.341,39.9993724822998,101286.51953125,1.54179964937258,0.00016142148470636
3844466929.343,39.9999485015869,101585.8671875,1.54515789287435,0.000159960043451698
3844466949.2695,39.9991931915283,101884.046875,1.54824364627973,0.000165259797549536
3844466969.3535,39.9998683929443,102185.45703125,1.55160418855656,0.000162270904184003
3844466989.3325,40.0000553131103,102485.56640625,1.5547193508719,0.00015942295609209
3844467009.2035,40.0007209777832,102782.921875,1.55802462827004,0.000157779724296886
3844467029.2265,39.9993839263916,103083.3828125,1.56113206345252,0.000154152924367863
3844467049.1645,40.0005722045898,103381.8125,1.5641599721826,0.000156710009998506
3844467069.157,40.000602722168,103682.99609375,1.56712556005038,0.000133128638111737
3844467089.1945,40.0008773803711,103982.87890625,1.57036263453043,0.000129031991763591
3844467109.193,39.9998111724854,104282.84375,1.57362516541363,0.000147918701747866
3844467129.1015,40.0003147125244,104582.2109375,1.57712296610584,0.000158449380818511
3844467149.1595,39.999885559082,104883.32421875,1.58032729372045,0.000147939956306817
3844467169.0615,39.9998035430908,105182.10546875,1.58337575451365,0.000145820248310598
3844467189.163,40.0005645751953,105483.54296875,1.58657052477289,0.000139041935760764
3844467209.0755,39.9991760253906,105781.96875,1.5894146191538,0.000149080091530102
3844467229.031,40.0007705688477,106082.16796875,1.59279451739318,0.000150560388442427
3844467249.0895,40.0000972747803,106382.515625,1.59586520057438,0.000143190370749702
3844467269.0485,40.0002326965332,106682.578125,1.59890680966308,0.000164983404686234
3844467288.985,40.0005645751953,106981.3046875,1.60192395805894,0.000147742434330448
3844467309.0255,39.9994964599609,107281.9453125,1.60522633110773,0.000167967147204453
3844467329.0415,40.000114440918,107583.01953125,1.60850554501447,0.000162786636695147
3844467349.1095,39.9992980957031,107884.33203125,1.61124828927885,0.000151521816662688
3844467368.967,39.9995632171631,108180.87890625,1.61445974117669,0.000150735306348049
3844467388.938,39.9984188079834,108480.8359375,1.61758914035218,0.000155182525619228
3844467409.0235,39.9989681243897,108782.109375,1.62084350395362,0.000183356790294258
3844467428.865,39.9999828338623,109079.12890625,1.6238513892787,0.00017659238936829
3844467448.886,39.9989204406738,109379.5859375,1.62669820541038,0.000143903926845806
3844467468.9665,39.9994812011719,109680.94921875,1.62975273739473,0.000178668063007406
3844467488.8775,39.9992752075195,109978.75,1.63265550613396,0.000186721441809013
3844467508.9185,39.9997253417969,110279.5625,1.63588131474007,0.000168778892638543
3844467528.817,39.9991188049316,110578.85546875,1.63895850452246,0.000164211177185434
3844467548.8395,40.0001430511475,110879.3671875,1.64184325092668,0.000156377785922309
3844467568.878,39.9998359680176,111178.5390625,1.6447706395376,0.00017685736693676
3844467588.926,39.9990825653076,111480.37890625,1.64797803133862,0.000171955200314013
3844467608.793,39.9995098114014,111778.20703125,1.6510613890249,0.0001688635188732
3844467628.8475,39.9998779296875,112079.28125,1.65368147981164,0.000151620229039188
3844467648.944,40.000020980835,112380.83984375,1.65672875071071,0.000163193822653814
3844467668.835,39.9999389648438,112679.44140625,1.65951994538157,0.00016563140795353
3844467688.722,39.9998226165771,112977.421875,1.66202148193984,0.000141004193669487
3844467708.6685,39.9997272491455,113277.6484375,1.6653892425195,0.000163879266064338
3844467728.6525,39.9996967315674,113576.71484375,1.66834005019448,0.000145946934426915
3844467748.7565,39.9996166229248,113879.0234375,1.67113869100788,0.000162082666632527
3844467768.7925,40.0000038146973,114179.4296875,1.67404392838351,0.000173521543743432
3844467788.735,39.999698638916,114478.6875,1.67740155970851,0.000185712144672518
3844467808.732,39.9996547698975,114779.5234375,1.68027535829261,0.000171401037325883
3844467828.66,39.9991722106934,115078.703125,1.68290283816125,0.000172831190678566
3844467848.572,40.0000152587891,115377.08984375,1.68572422174306,0.000178612796326299
3844467868.613,40.0002212524414,115677.79296875,1.68815794646394,0.000171403372693469
3844467888.545,39.9999237060547,115975.86328125,1.69088810195988,0.000182174367569331
3844467908.682,40.000524520874,116277.69140625,1.69357259075281,0.000168876028255909
3844467928.6145,39.9988689422607,116576.90625,1.6966852445052,0.000164056817102482
3844467948.6445,40.0004787445068,116877.50390625,1.69961382017901,0.000183274778584472
3844467968.578,39.9993801116943,117175.82421875,1.70219023731348,0.000165112561726162
3844467988.5155,39.9993152618408,117475.28125,1.70523560529742,0.000164196524942645
3844468008.442,39.9996299743652,117774.34765625,1.70813404256587,0.000194052699776672
3844468028.4745,39.9991512298584,118074.734375,1.71079118530168,0.000167091535266454
3844468048.4255,40.0005645751953,118374.0234375,1.71358269023116,0.000176094517525998
3844468068.4445,39.9988174438477,118674.6484375,1.71636891046056,0.000192471386656342
3844468088.559,39.9997653961182,118975.48828125,1.71918335042401,0.00017138379891841
3844468108.374,40.0000953674316,119273.63671875,1.722226053606,0.000198302278063892
3844468128.531,40.0003509521484,119575.86328125,1.72483526720701,0.00019221025283058
3844468148.342,40.0003318786621,119874.16015625,1.72718532639682,0.000173082141484195
3844468168.488,39.9995994567871,120176.50390625,1.73008454498625,0.000192159426349875
3844468188.3215,39.9986782073975,120473.62109375,1.73269284571272,0.000175844836714493
3844468208.3675,39.9997730255127,120775.33203125,1.73507676860824,0.000166529045661095
3844468228.344,40.0005702972412,121074.640625,1.73779049493757,0.00015245824875135
3844468248.252,39.999927520752,121373,1.74069978131332,0.000174008367005642
3844468268.3075,40.0010147094727,121674.55078125,1.74312218818864,0.000167974934560354
3844468288.2945,40.0001926422119,121974.89453125,1.74570767192438,0.000175943981750725
3844468308.3035,40.000846862793,122274.18359375,1.74806463668417,0.000163093283255539
3844468328.304,40.0007572174072,122574.33984375,1.75109210551266,0.000182279791800041
3844468348.2325,39.9999046325684,122873.2890625,1.75387283427942,0.000184116859132106
3844468368.2895,40.0003280639648,123174.25390625,1.75616640907769,0.000190347952323786
3844468388.164,40.0000095367432,123471.69921875,1.75868939611832,0.000186720713385032
3844468408.145,40.0001659393311,123771.98046875,1.76147603889277,0.000177165487947245
3844468428.163,40.0000095367432,124071.53125,1.76371238083629,0.00017515808289033
3844468448.148,40.0002117156982,124371.37890625,1.76621933569546,0.000169516751982948
3844468468.123,40.0001239776611,124671.1328125,1.76915892241846,0.000168056302409889
3844468488.092,40.0001316070557,124969.609375,1.77188005220262,0.000175206178273817
3844468508.172,39.9996967315674,125271.05078125,1.77412520269615,0.000167779382595667
3844468528.069,39.9997653961182,125569.55078125,1.77685017475596,0.000176091344456851
3844468548.054,39.9998435974121,125869.7734375,1.77934433236448,0.000189901136114995
3844468568.097,40.0003108978271,126170.82421875,1.78165742228519,0.000170031361993102
3844468588.0675,40.000452041626,126469.53515625,1.78410528140473,0.000173363113979879
3844468608.001,39.9988574981689,126768.98046875,1.7872138163301,0.000209030568223539
3844468628.0945,39.999870300293,127070.875,1.78927115257691,0.000164029554706687
3844468648.106,39.9996128082275,127371.33984375,1.79190134009089,0.000162399448205968
3844468668.0525,40.000846862793,127670.66796875,1.79469874849163,0.000164267353628343
3844468687.9295,40.0002536773682,127969.21875,1.79670356374159,0.000177073442544076
3844468708.0315,40.0006332397461,128270.9765625,1.79909363868044,0.000176870840194808
3844468728.031,40.0007877349854,128571.28515625,1.8019329339987,0.000171626388704359
3844468747.9815,40.0004196166992,128869.953125,1.80418710171981,0.00019854475081795
3844468768.091,40,129171.98828125,1.80661847601775,0.000175343267281471
3844468787.938,40.0006504058838,129469.82421875,1.80929884172979,0.000167821827511826
3844468807.8715,39.9994525909424,129768.6875,1.81172286897704,0.000186148142953623
3844468827.8485,39.9998302459717,130068.79296875,1.8139384261401,0.000171056240273211
3844468847.8955,39.999210357666,130369.734375,1.81662409029696,0.000194176565738697
3844468867.8185,39.9998645782471,130668.328125,1.81869044144077,0.000181396250348619
3844468887.969,40.0006504058838,130971.65625,1.82090455515302,0.000167387986843165
3844468907.79,40.0000057220459,131269.3515625,1.82329366632494,0.000179886134874343
3844468927.81,39.9998607635498,131568.9609375,1.82598932203351,0.000154698530015327
3844468947.7545,40.0005588531494,131866.9453125,1.82823419371577,0.00018594443059028
3844468967.8755,40.0006446838379,132168.9453125,1.83028554144135,0.000177522143757201
3844468987.7115,39.9993629455566,132465.828125,1.83295608003919,0.000186321030080091
3844469007.702,40.0002689361572,132766.2890625,1.83491009891536,0.000180901378455965
3844469027.6915,40.0006847381592,133065.359375,1.83741014706419,0.000172214675662742
3844469047.832,39.999439239502,133366.8203125,1.84006802926072,0.000196439710574308
3844469067.783,39.9994430541992,133667.796875,1.84207741773364,0.000175255917122996
3844469087.7575,40.0004577636719,133966.171875,1.84444253433872,0.000188321629529809
3844469107.721,40.0008163452148,134265.9296875,1.84658812077328,0.000169488896197579
3844469127.678,39.9998626708984,134565.234375,1.84910785056788,0.000188594291427259
3844469147.795,40.0000381469727,134867.1484375,1.85154571861541,0.000192203656720474
3844469167.647,39.9996891021729,135165.7265625,1.85370105553403,0.000186570971921551
3844469187.6495,39.9999580383301,135466.2734375,1.85591916144896,0.000172434992157535
3844469207.629,39.9998416900635,135766.6015625,1.85852942087862,0.00018570111417628
3844469227.6365,39.9985885620117,136066.6796875,1.86115556899828,0.000214114325065942
3844469247.5265,39.9993953704834,136364.7890625,1.86335290935332,0.000190546467971111
3844469267.513,39.9992160797119,136664.875,1.86522783023226,0.000208862047240858
3844469287.5795,39.9997482299805,136966.2578125,1.86759090055725,0.000185910126960715
3844469307.5735,39.9990482330322,137265.53125,1.86950424886046,0.000200300403726053
3844469327.5475,40.0001354217529,137565.0859375,1.87161476179211,0.000205123166990091
3844469347.713,40.0000038146973,137868.984375,1.87419998965908,0.000181849883101694
3844469367.6655,40.0000896453857,138167.6484375,1.87600645420246,0.000177291575101165
3844469387.612,39.999979019165,138467.71875,1.87870912765832,0.00021223168221891
3844469407.4335,39.9998416900635,138765.0859375,1.88072859449116,0.000202474280310549
3844469427.463,39.9988422393799,139065.984375,1.88263436641193,0.000198577111164956
3844469447.537,39.9997539520264,139366.59375,1.88535682547719,0.000211004718421538
3844469467.3595,39.9999084472656,139663.4453125,1.88762132190302,0.000185398906041172
3844469487.498,39.9989395141602,139965.6640625,1.88968718439475,0.00020535977525335
3844469507.3075,40.0001430511475,140000.5078125,1.88959040017573,0.000192926327748907