File: MvsH/data/2021-10-25_EROI_34P8MG_MVSH_20P0K.DAT
Time Stamp (sec),Temperature (K),Magnetic Field (Oe),Moment (emu),M. Std. Err. (emu)
3844448137.008,19.986054066656,0.462228029966354,,
3844448233.124,20.0005149841309,-4845.787109375,-0.133236874633633,4.4988261670079E-5
3844448253.2025,20.000129699707,-4544.9912109375,-0.125009406897685,4.48322874552136E-5
3844448273.253,20.0006065368652,-4243.56201171875,-0.116768461816429,4.26087368638709E-5
3844448293.233,20.0000400543213,-3944.52087402344,-0.108587766466777,4.41017496735387E-5
3844448313.0805,20.00075340271,-3647.22131347656,-0.100366328265666,4.26832028564487E-5
3844448333.1655,20.0009365081787,-3345.87878417969,-0.0921754277953215,4.32160577474809E-5
3844448353.2075,19.9996843338013,-3044.97192382812,-0.0839573123474518,4.12259204174656E-5
3844448373.1175,19.999828338623,-2746.74096679687,-0.0757479893272695,4.19958016747411E-5
3844448393.0655,19.9994707107544,-2447.39904785156,-0.067513548040538,4.24493689661949E-5
3844448413.084,20.0001821517944,-2147.46801757813,-0.0593135747725109,4.19414864744555E-5
3844448432.99,19.9997720718384,-1848.91149902344,-0.0511168984728276,4.26433957889299E-5
3844448453.074,20.0004243850708,-1547.53503417969,-0.0428881623091721,4.24335669915753E-5
3844448481.0065,19.9988899230957,-1129.80822753906,-0.0326386837892933,4.15825535165718E-5
3844448497.965,20.0000333786011,-874.875640869141,-0.0244341997009066,4.19121487488705E-5
3844448517.93,20.0003747940063,-574.679870605469,-0.0162196080931149,4.18851665052934E-5
3844448537.921,19.9997987747192,-275.769470214844,-0.00801500760819139,4.20368826152384E-5
3844448565.967,19.999719619751,144.673034667969,0.00227551252551258,4.2079574137943E-5
3844448582.925,20.0004482269287,398.778594970703,0.0105167030918168,4.19030111860846E-5
3844448607.838,19.9997320175171,773.333740234375,0.020828681097039,4.18288998087117E-5
3844448627.924,20.0004386901855,1074.59564208984,0.0290636445875147,4.19352860517409E-5
3844448647.958,20.000057220459,1374.16796875,0.0372886206272695,4.23770108396758E-5
3844448667.8255,19.9999580383301,1671.83087158203,0.0455251386077798,4.20035866548758E-5
3844448688.03,19.9994058609009,1975.79290771484,0.0537570926109395,4.21076186619731E-5
3844448707.785,19.9998235702515,2271.91833496094,0.0619879244402784,4.23839271701909E-5
3844448727.759,20.0006399154663,2571.09790039062,0.070228303875989,4.31469780750847E-5
3844448747.8075,19.9999151229858,2871.75695800781,0.0784664082759813,4.34450564440812E-5
3844448767.814,20.0001125335693,3172.40771484375,0.0866904535635892,4.16850899895764E-5
3844448787.7095,19.9999675750732,3470.32482910156,0.0949012233434064,4.28723011008976E-5
3844448812.808,20.0002241134644,3846.61779785156,0.10520058953046,4.28994321499525E-5
3844448832.6695,20.0001888275146,4143.84033203125,0.1133778062847,4.38152829084968E-5
3844448852.808,19.9994649887085,4446.07983398438,0.121591589770672,4.26916660644854E-5
3844448872.841,20.0002613067627,4746.93823242188,0.1297888947256,4.414619621641E-5
3844448892.7635,19.9996852874756,5046.1240234375,0.13800208622594,4.38229059622727E-5
3844448912.637,20.0001134872437,5344.00561523438,0.146183291435062,4.17522561383238E-5
3844448932.684,19.9996957778931,5645.29711914063,0.15439460115388,4.49183862680861E-5
3844448952.623,19.9997205734253,5943.94384765625,0.162573001299524,4.26969964329285E-5
3844448972.621,19.9997272491455,6243.84814453125,0.170750902403144,4.57010427796407E-5
3844448992.694,20.000093460083,6544.88256835938,0.178949119855617,4.63146116507042E-5
3844449012.539,19.9994745254517,6841.82153320312,0.187109028707187,4.68796787250694E-5
3844449032.595,20.0003442764282,7142.44360351562,0.195319742640096,4.71145592190494E-5
3844449052.5455,19.9993705749512,7441.77954101562,0.203531252701755,4.87412594047137E-5
3844449072.495,20.0000600814819,7741.63989257812,0.211631312417492,4.9462223687679E-5
3844449092.4975,19.9993782043457,8040.99658203125,0.219793657632959,4.44552835283969E-5
3844449112.546,20.0005168914795,8342.34619140625,0.227953874173852,4.74805104694394E-5
3844449132.66,19.9999265670776,8644.0234375,0.236145526750201,4.91057425432338E-5
3844449152.571,20.0005807876587,8942.439453125,0.244275741579939,4.7783638491214E-5
3844449172.483,20.0002145767212,9240.4375,0.252444713185825,4.73864742177921E-5
3844449192.43,19.9998617172241,9539.6416015625,0.260560762047931,4.6236171981399E-5
3844449212.382,20.0005598068237,9839.8359375,0.268687117816866,4.7638348235989E-5
3844449232.543,19.9997615814209,10141.93359375,0.276805498285118,4.89552610702132E-5
3844449252.4215,19.9999361038208,10441.2998046875,0.285049010157922,5.16133918481127E-5
3844449272.432,19.9996194839478,10741.212890625,0.293153830921257,5.37798522462453E-5
3844449292.5175,19.9996156692505,11042.0297851562,0.301313754699793,5.36306381818135E-5
3844449312.361,20.0000333786011,11339.8452148438,0.309396192452734,5.2319153204515E-5
3844449332.4005,20.0001134872437,11640.5288085938,0.317471614357554,5.20876749728413E-5
3844449352.304,20.0003328323364,11938.5668945313,0.325562802878284,4.8846932405618E-5
3844449372.3105,20.0000877380371,12238.5415039062,0.333642519614383,5.0566426175022E-5
3844449392.435,20.0002212524414,12540.9658203125,0.341750275899124,5.09505637660123E-5
3844449412.253,20.0002918243408,12837.1499023437,0.349907336175149,5.78684406428292E-5
3844449432.305,20.0004529953003,13138.666015625,0.357915359976484,5.28159892481887E-5
3844449452.356,19.9999322891235,13439.3295898438,0.366053898471202,5.61092142032194E-5
3844449472.257,20.0000200271606,13737.9345703125,0.374145824483637,5.8144166204633E-5
3844449492.3655,20.0000247955322,14040.0952148438,0.382226925609578,5.86868553226018E-5
3844449512.178,20.0001068115234,14336.7504882812,0.390224767843283,5.49796870358133E-5
3844449532.183,19.999683380127,14636.4926757813,0.398249232881553,6.10333439894576E-5
3844449552.218,19.9999942779541,14937.2724609375,0.40623669665185,5.46337224475188E-5
3844449572.2645,19.9994192123413,15237.3120117188,0.414305466207889,5.17624131036949E-5
3844449592.2325,20.0005321502686,15537.2446289062,0.422267307404008,5.44606087159776E-5
3844449612.108,19.9999074935913,15836.1220703125,0.430350390403127,5.69776127620389E-5
3844449632.1225,20.0000734329224,16136.0288085938,0.438348177525429,6.0397063382688E-5
3844449652.284,19.9996366500854,16439.25390625,0.446445520870638,5.52814714614923E-5
3844449672.1485,20.0003862380981,16736.7333984375,0.454309005197224,5.62226295733414E-5
3844449692.044,19.9993934631348,17034.958984375,0.462340943524907,6.65108298403662E-5
3844449712.061,20.0002727508545,17334.697265625,0.470357628313639,6.11919825779461E-5
3844449732.1765,19.9999828338623,17636.4521484375,0.478355559316654,6.4592076957547E-5
3844449752.0295,20.0002660751343,17934.775390625,0.486308505946605,5.80532964245998E-5
3844449772.0955,20.0000247955322,18235.5673828125,0.494166918120329,6.29493834905061E-5
3844449792.067,19.999568939209,18534.859375,0.502232549746099,6.38104194289441E-5
3844449811.9385,20.0000829696655,18833.1318359375,0.510086974572118,6.42627654744487E-5
3844449832.0345,19.9999685287476,19134.7099609375,0.518006799857058,6.14908627209197E-5
3844449851.9385,20.0001440048218,19433.0380859375,0.526086787783896,7.46653049834333E-5
3844449872.0505,20.0004835128784,19734.2919921875,0.533770704143028,6.35267635873634E-5
3844449891.9005,19.9998960494995,20031.1533203125,0.541772028090744,6.98891806696152E-5
3844449911.912,20.0000467300415,20332.1708984375,0.549662062347484,7.17351361069704E-5
3844449931.983,20.0005321502686,20633.423828125,0.557546788575076,6.54756361885057E-5
3844449951.904,19.9998893737793,20931.685546875,0.565400261040726,6.61055322897879E-5
3844449971.8355,19.9998064041138,21230.8671875,0.573219259404687,6.36584110168513E-5
3844449991.835,19.9993782043457,21531.1162109375,0.58116331235139,6.97031613586877E-5
3844450011.858,20.0001583099365,21831.03515625,0.589020558692031,7.05037641898745E-5
3844450031.8025,19.9995813369751,22130.0849609375,0.596785652816809,7.0166766364199E-5
3844450051.78,19.9998340606689,22428.9912109375,0.604596124773299,6.55503378148345E-5
3844450071.8655,20.0002174377441,22730.4365234375,0.612416543564096,7.11196333412166E-5
3844450092.0055,20.0003499984741,23032.966796875,0.620180343831545,6.9472310804373E-5
3844450111.849,19.9999303817749,23330.5205078125,0.627985687590431,7.75244779924396E-5
3844450131.832,20.0001020431519,23630.5576171875,0.635763620086177,7.47419756512572E-5
3844450151.8515,20.0002222061157,23930.3310546875,0.643500283113721,6.94789351058756E-5
3844450171.701,19.9997720718384,24229.1669921875,0.651298979248237,7.79205031197668E-5
3844450191.797,19.9996137619019,24529.779296875,0.659172174349079,7.55078726041195E-5
3844450211.74,20.0002031326294,24828.46875,0.666720172238953,8.06948368030462E-5
3844450231.6515,19.9998006820679,25127.7509765625,0.67450157299336,8.29294972818685E-5
3844450251.743,20.0007181167603,25428.6943359375,0.682222545466413,8.52418470129834E-5
3844450271.739,19.999659538269,25729.3447265625,0.689904436661296,7.4382250138466E-5
3844450291.7215,20.0002002716064,26028.62890625,0.697541411522997,8.15075476550342E-5
3844450311.605,20.0002698898315,26327.0986328125,0.705132799129266,8.11840689576301E-5
3844450331.706,19.9999742507935,26628.4970703125,0.712810432584209,7.5522263007735E-5
3844450351.726,19.999608039856,26928.634765625,0.720529826514273,8.06143964190997E-5
3844450371.6005,19.9999046325684,27227.05078125,0.72816779885696,7.64939583202846E-5
3844450391.608,20.0004501342773,27525.896484375,0.735805493947111,8.01322042170058E-5
3844450411.506,19.9997110366821,27825.0751953125,0.743368703631814,7.99119456903811E-5
3844450431.507,20.0003528594971,28125.265625,0.750903191173523,7.92071976678077E-5
3844450451.4695,20.0005931854248,28425.138671875,0.758442587274005,8.28217755270414E-5
3844450471.636,20.0001850128174,28727.4716796875,0.766134296746074,8.77239107078994E-5
3844450491.516,20.0004577636719,29025.92578125,0.773675599608399,7.96889359886685E-5
3844450511.565,20.0000648498535,29325.8994140625,0.781365687686033,8.60779511002272E-5
3844450531.4115,20.0004835128784,29623.6611328125,0.788754654834223,8.99623714777479E-5
3844450551.5375,19.9999408721924,29925.576171875,0.796213682253563,7.74600821609798E-5
3844450571.492,19.9997711181641,30224.576171875,0.803700834302897,8.71493666238994E-5
3844450591.479,20.0002965927124,30523.748046875,0.811254458287349,9.05751035717016E-5
3844450611.3545,20.0000696182251,30823.05078125,0.818710867612996,9.37096111008213E-5
3844450631.532,20.0004377365112,31125.330078125,0.826092308520632,8.55354611964057E-5
3844450651.3245,20.0001373291016,31423.3193359375,0.833639009159942,9.01818063698065E-5
3844450671.439,19.9999074935913,31724.662109375,0.841224359364581,9.16971365074661E-5
3844450691.3135,19.9997434616089,32023.3271484375,0.848444127254475,9.4886998813038E-5
3844450711.3675,20.0008249282837,32323.9794921875,0.855708240975982,8.34497989760858E-5
3844450731.2865,19.9999256134033,32622.1328125,0.863124347159322,8.004970106021E-5
3844450751.364,20.0000219345093,32922.791015625,0.870480981906137,8.65102444852838E-5
3844450771.283,19.9998006820679,33222.03515625,0.877722679936178,8.86893523826819E-5
3844450791.355,19.9993963241577,33522.830078125,0.885242305586976,0.000100316704457495
3844450811.363,20.0000400543213,33823.533203125,0.892469686522663,0.000101740602433685
3844450831.29,19.999963760376,34122.12109375,0.899832216623791,9.84921868887233E-5
3844450851.361,20.0000352859497,34423.236328125,0.90693681416736,8.07861400019005E-5
3844450871.225,19.9998445510864,34721.271484375,0.91445486951683,9.07486069441948E-5
3844450891.244,20.0002765655518,35021.9921875,0.921808906616401,9.89148596526243E-5
3844450911.1925,19.9999904632568,35320.1015625,0.928925049282265,9.82989364706461E-5
3844450931.1535,19.9999408721924,35619.3203125,0.936168327079325,9.30961166414462E-5
3844450951.1955,19.9998092651367,35920.076171875,0.943482330997261,9.86262731510606E-5
3844450971.2115,19.9997930526733,36220.7890625,0.950500655284235,9.60494322956847E-5
3844450999.1445,19.999662399292,36640.21875,0.95926244241728,0.000105037483226147
3844451016.069,19.9993553161621,36893.646484375,0.966512695214211,9.83042344506234E-5
3844451036.183,19.9999628067017,37196.115234375,0.973507627168022,0.00011406951164233
3844451056.035,19.9998531341553,37493.0703125,0.980514112601125,9.52770851712983E-5
3844451076.045,20.0000600814819,37792.638671875,0.98753431703925,0.000102516150967807
3844451096.0955,19.9999094009399,38093.837890625,0.994890819790765,0.000102737494414644
3844451116.0135,19.9999475479126,38392.470703125,1.00191297713501,0.000121564378234762
3844451135.998,19.9994974136353,38692.400390625,1.00895442723333,0.000107310199530724
3844451156.043,20.000693321228,38993.0078125,1.01584133713272,0.000105535169803934
3844451176.074,19.9996604919434,39294.009765625,1.02310540378505,0.000111175186391268
3844451195.9285,20.0004396438599,39591.458984375,1.03003275890449,0.000108210023751109
3844451216.127,20.0004291534424,39894.775390625,1.03700906711161,0.000103219044220884
3844451235.91,20.0002336502075,40191.6328125,1.04392875459949,0.00010285433058517
3844451255.9825,19.9999237060547,40492.1640625,1.05090723521138,0.000103077541709457
3844451275.965,19.9998264312744,40792.19921875,1.05769788064944,9.35603058390722E-5
3844451295.8975,20.0000133514404,41091.001953125,1.0646921199339,0.000106549292463215
3844451315.9495,19.9999885559082,41391.072265625,1.07163159439151,9.94740490713421E-5
3844451336.002,19.9999408721924,41692.56640625,1.07868858503599,0.000119969586635702
3844451355.9405,19.9999361038208,41991.755859375,1.08544902011442,0.000109390162978212
3844451375.7945,20.000096321106,42289.71875,1.09229110235179,9.60552878628445E-5
3844451395.829,20.0007162094116,42589.794921875,1.09905360466811,0.000117406116863556
3844451415.791,19.9998121261597,42889.865234375,1.10583407361421,0.000110940064495108
3844451435.745,20.0001573562622,43188.7265625,1.112441131949,0.000110706836614466
3844451455.9615,20.0001449584961,43492.4453125,1.11940223356362,0.000116801013882524
3844451475.76,20.0004987716675,43789.689453125,1.12621079369099,0.000112349185388431
3844451495.8095,19.9999008178711,44090.26953125,1.13273321490807,0.000119689436665192
3844451515.697,20.0001649856567,44388.830078125,1.13926335630545,0.000116363026652032
3844451535.8125,19.9999856948853,44689.548828125,1.14605971857635,0.000101990457462623
3844451555.692,19.9999103546143,44988.337890625,1.15271278410104,0.000117664851149893
3844451575.6415,19.999683380127,45288.36328125,1.15944830411669,0.00012244301445483
3844451596.1565,20.0002784729004,45595.509765625,1.16608435068996,0.000129215558706621
3844451615.7465,20.0000896453857,45889.451171875,1.17237574581034,0.000110464163517957
3844451635.782,19.9998931884766,46189.34375,1.17906598116868,0.000116773687025418
3844451655.5805,20.0000696182251,46487.283203125,1.18565205435853,0.000115609452804326
3844451675.786,20.0002059936523,46789.447265625,1.19217939656817,0.000121727296215708
3844451695.5735,20.0001039505005,47086.423828125,1.19872456380936,0.000117852259785425
3844451715.5775,19.999981880188,47386.435546875,1.20504024139461,0.000123693280392063
3844451735.529,19.99964427948,47686.583984375,1.21163241987737,0.000124337062021302
3844451755.66,20.0004005432129,47987.95703125,1.21809415498701,0.000125005573690781
3844451775.51,19.9992113113403,48285.306640625,1.22451657032619,0.000110208662081697
3844451795.6585,20.0003433227539,48587.552734375,1.23090593433207,0.000123260874927864
3844451815.5365,19.9998245239258,48886.263671875,1.23714551595621,0.00012599086274915
3844451835.543,20.0004196166992,49185.3359375,1.24368717553436,0.000131534962404973
3844451855.4895,20.0000667572021,49485.283203125,1.25002341185632,0.000122205874919538
3844451875.6115,19.9999799728394,49786.779296875,1.2564230942561,0.000134948678655554
3844451895.4705,19.9998683929443,50085.18359375,1.26278712080304,0.000129215964001867
3844451915.439,20.0005378723145,50384.736328125,1.26890398550757,0.000122290261641632
3844451935.4335,20.0004243850708,50684.576171875,1.27517824708685,0.000126290039050286
3844451955.481,19.999400138855,50985.005859375,1.28173037011091,0.00011767111804315
3844451975.449,19.9997863769531,51284.904296875,1.2877710571151,0.000122630958205163
3844451995.3565,20.0007047653198,51583.8828125,1.2939117209229,0.000127095990758637
3844452015.317,19.9998369216919,51883.09765625,1.30022577493703,0.000140394960729992
3844452035.486,20.0005941390991,52187.30078125,1.30638329443767,0.000128261351985906
3844452055.424,19.9996709823608,52485.794921875,1.31256724823729,0.000132421172456854
3844452075.3875,20.0001277923584,52785.59765625,1.31876094435499,0.000125140439415617
3844452095.2835,19.9996557235718,53084.2109375,1.3250289596523,0.00015500274320611
3844452115.3775,19.9999017715454,53385.59765625,1.33086932247902,0.000145680440653235
3844452135.3445,19.9998865127563,53684.552734375,1.33709850933697,0.000149344045652554
3844452155.2215,19.9997529983521,53983.69921875,1.34294687975126,0.000134959357832328
3844452175.207,19.9998054504395,54282.5390625,1.34888456886791,0.000139418055653649
3844452195.211,20.0000715255737,54583.318359375,1.35485279348564,0.000136718122663431
3844452215.335,20.0000171661377,54884.982421875,1.36103189626961,0.000138535552001997
3844452235.235,19.9996652603149,55183.396484375,1.36665311688064,0.000137299675767336
3844452255.1695,20.000147819519,55482.84375,1.37264625444326,0.000128705040270105
3844452275.236,19.9997854232788,55783.55859375,1.37852272344734,0.000131845697508975
3844452295.12,19.9994068145752,56081.662109375,1.38444595637907,0.000135624919019955
3844452315.157,20.0001850128174,56382.326171875,1.39008557355905,0.000132781827720963
3844452335.23,19.9999475479126,56684.099609375,1.39602799871454,0.000135806961835908
3844452355.1715,20.0002384185791,56982.4921875,1.40170097517324,0.000137835729709102
3844452375.498,19.9999513626099,57287.7890625,1.40768830871214,0.000150308155768667
3844452395.1215,20.0004138946533,57582.646484375,1.41346926430699,0.000138389717634287
3844452415.207,20.0003662109375,57884.056640625,1.41919168452499,0.000137035840418688
3844452435.1635,19.9999675750732,58182.701171875,1.42494573771756,0.000146303285678543
3844452455.098,19.9997243881226,58481.86328125,1.43050882208839,0.000132473881417004
3844452474.9855,20.0002279281616,58779.29296875,1.43594739889241,0.000136967919583337
3844452495.0015,19.9997863769531,59079.802734375,1.44189572434542,0.000143087927558969
3844452514.9965,20.0001039505005,59379.96875,1.44731596908925,0.000132249641919664
3844452535.095,19.9998292922974,59681.2265625,1.45306919902084,0.000153792949343567
3844452554.97,19.9994602203369,59979.794921875,1.45875066126876,0.00014548185911765
3844452575.146,19.9998989105225,60281.93359375,1.46412603729328,0.000151232291234744
3844452594.8845,19.9996547698975,60578.470703125,1.46956121880056,0.000143662745067355
3844452614.988,20.0001831054687,60880.08984375,1.47508173483232,0.0001500923214143
3844452635.0105,19.9998273849487,61180.701171875,1.48074188630628,0.000141350075270187
3844452654.9525,19.9998359680176,61479.828125,1.48666808352452,0.000161157952905506
3844452674.839,20.0001449584961,61777.61328125,1.49155001698977,0.000125046630041591
3844452694.9085,20.0002183914185,62079.408203125,1.49726748429247,0.000142623224696858
3844452714.859,19.9997282028198,62378.890625,1.50262077911335,0.000149164062178039
3844452734.882,20.0001983642578,62678.775390625,1.5075852078957,0.000138270074037546
3844452754.799,19.9996252059937,62977.923828125,1.51296705808895,0.000140569187281092
3844452774.853,19.9999809265137,63278.212890625,1.51837736195149,0.000151260598395375
3844452794.7595,19.9995803833008,63577.294921875,1.52398716801959,0.000164146108677592
3844452814.757,19.9998989105225,63877,1.52904622366464,0.000148254230178333
3844452834.765,19.9997081756592,64177.087890625,1.53428139032322,0.000157123130229887
3844452854.861,20.0005912780762,64478.671875,1.53957362874286,0.00016000105409047
3844452874.6895,19.9996681213379,64776.294921875,1.54471197634681,0.000147369839565227
3844452894.7045,20.0007915496826,65076.375,1.54994042389344,0.000150158134156022
3844452914.6615,19.9998683929443,65376.376953125,1.55502555940275,0.000152460202926959
3844452934.634,20.0002117156982,65675.4765625,1.56025020808202,0.000150852135714449
3844452954.8115,20.0003004074097,65977.91796875,1.56522050251298,0.000143389403578573
3844452974.621,19.9999599456787,66274.78125,1.5704391632735,0.000155656016139609
3844452994.726,20.000415802002,66576.7109375,1.57528600356961,0.00015818158347092
3844453014.608,20.0001382827759,66875.1796875,1.58062233754533,0.000162533422916931
3844453034.6875,20.0007047653198,67175.23828125,1.58552987319559,0.000147701137070769
3844453054.702,20.0006036758423,67475.9140625,1.59036461041568,0.00015862462038788
3844453074.615,20.000020980835,67774.4765625,1.59549506004575,0.000145926721408676
3844453094.6545,19.9996576309204,68075.12890625,1.60046849540406,0.000164031253372004
3844453114.5075,20.0006723403931,68373.08984375,1.60539589428367,0.000156600434478429
3844453134.494,20.0001668930054,68673.171875,1.61024544487357,0.000157012426608533
3844453154.488,19.9997653961182,68973.2109375,1.61524378590556,0.000160829754326708
3844453174.5925,20.0001811981201,69274.453125,1.62001887872976,0.000167000769569019
3844453194.441,19.9997072219849,69573.09375,1.62501234353992,0.000160138353050382
3844453214.5795,19.9997053146362,69874.21875,1.63027428957402,0.000171814707667498
3844453234.4015,19.9998350143433,70172.12890625,1.63461700529781,0.00015309949972513
3844453254.501,20.000093460083,70474.7265625,1.63976087783385,0.000171139048264182
3844453274.3945,19.9996242523193,70772.55078125,1.64426306096175,0.000155328421034441
3844453294.4515,19.9999923706055,71073.625,1.64903836536972,0.000174750387892992
3844453314.422,20.0002708435059,71373.63671875,1.65334567791015,0.000160580615410734
3844453334.4075,20.0002899169922,71672.37890625,1.65822386010157,0.000167980385675969
3844453354.498,20.0000905990601,71973.84765625,1.66286524958445,0.000155032562661955
3844453374.3275,19.9999952316284,72271.67578125,1.66745927027271,0.000178720365816622
3844453394.4935,19.999927520752,72574.02734375,1.67217276202867,0.000163841957821887
3844453414.365,19.9996471405029,72872.37890625,1.6768464229307,0.00016736574766422
3844453434.2735,20.0001840591431,73171.71484375,1.68120480618089,0.00016061291874358
3844453454.2925,19.999267578125,73472.4296875,1.68591487605525,0.000162399199879831
3844453474.2255,20.0001544952393,73771.88671875,1.69048883060307,0.000169044226322522
3844453494.347,20.0002365112305,74073.30078125,1.6947539013424,0.000161751464391498
3844453514.222,20.0000886917114,74371.28515625,1.69920835107202,0.00017031247637056
3844453534.3165,20,74672.6171875,1.70378413573257,0.000178928751784869
3844453554.226,20.0001668930054,74970.6328125,1.70791924705951,0.000161988976481335
3844453574.168,19.9998416900635,75269.5703125,1.71238851674716,0.000156668642814545
3844453594.161,20.0004024505615,75569.70703125,1.7167458774214,0.00015920748380722
3844453614.242,20.0002717971802,75871.43359375,1.72107877008799,0.000174770143270595
3844453634.2075,19.9999189376831,76169.98828125,1.72545035045398,0.000172892244790418
3844453654.0995,20.0002470016479,76469.38671875,1.72996318274613,0.000164448723333592
3844453674.0895,19.9998531341553,76769.359375,1.73440604693425,0.000186403037359438
3844453694.127,19.9999742507935,77069.98828125,1.73847818487307,0.000178090092872252
3844453714.067,20.0000581741333,77368.66015625,1.74282091362325,0.000175078623183326
3844453734.0875,19.9993877410889,77669.69921875,1.74700384869264,0.000177997774072797
3844453754.2125,20.0002279281616,77971.3671875,1.75110792747706,0.00017466494825715
3844453774.2465,19.9998188018799,78271.734375,1.75503573186278,0.000180319261643353
3844453794.045,20.0006170272827,78569.578125,1.75945494731166,0.000169095731506311
3844453814.0975,20.000039100647,78870.59375,1.76378614729186,0.000181941572467368
3844453834.0785,19.9998874664307,79170.3671875,1.76740493036675,0.000175829489469584
3844453853.964,19.9996776580811,79468.640625,1.7716542161805,0.000171665180198087
3844453873.967,20.0003309249878,79768.41796875,1.77593426768106,0.000176171629354241
3844453894.0385,20.0002946853638,80069.14453125,1.77991826765552,0.000181216705731215
3844453913.991,19.999828338623,80368.3671875,1.78362836091264,0.000153221675634278
3844453933.987,19.9994049072266,80668.1640625,1.78816523137025,0.000187251291373638
3844453953.9605,20.0000600814819,80967.4921875,1.79179827597871,0.000175377539707437
3844453974.025,20.0004081726074,81268.828125,1.79578960042687,0.0001826203659518
3844453993.8975,19.9998064041138,81566.8046875,1.79966531648861,0.000186709857125786
3844454013.8975,19.9998683929443,81867.3671875,1.80387858639993,0.000185785218925274
3844454033.923,19.999719619751,82167.12109375,1.80738694729136,0.000178514622445222
3844454053.923,20.0000400543213,82466.0234375,1.81137465344156,0.000184538925401917
3844454073.7965,19.9996156692505,82765.4609375,1.81530808255053,0.000201526281112658
3844454093.771,19.9996280670166,83064.7578125,1.81908577964977,0.000196343012251641
3844454113.8835,20.0003232955933,83366.203125,1.82315789119696,0.000205709355216112
3844454133.74,19.9997730255127,83664.87109375,1.82682063658405,0.000162201057331418
3844454153.7375,20.0000076293945,83965.09765625,1.83059799283678,0.000195292261213199
3844454173.818,19.9993858337402,84266.15625,1.83429608631119,0.000183963625086124
3844454193.7055,20.0005884170532,84564.82421875,1.83798464860157,0.000177128582877496
3844454213.7945,20.000039100647,84866.06640625,1.84162834190657,0.000190857804252275
3844454233.6955,20.0003566741943,85164.6796875,1.84519027912377,0.000201644645894057
3844454253.754,20,85466.57421875,1.84909668630391,0.000201949000010428
3844454273.65,19.9999647140503,85764.5,1.85245111579815,0.000190620536081811
3844454293.664,20.0007696151733,86065.30078125,1.85585712344877,0.000184456485577216
3844454313.787,19.999960899353,86366.6328125,1.8598694661542,0.000201080741125325
3844454333.5935,20.0000925064087,86663.86328125,1.8631620241789,0.000188611572600421
3844454353.694,19.9996852874756,86965.27734375,1.86715620619338,0.000204749863380611
3844454373.7245,19.9998817443848,87264.84765625,1.87038269010666,0.000178363728021027
3844454393.5895,19.9998655319214,87563.28125,1.87352106190214,0.000169123710655471
3844454413.593,19.9998226165771,87863.16015625,1.87737454492472,0.000191366827176349
3844454433.663,19.9999694824219,88164.0703125,1.88074857547179,0.000219161635891022
3844454453.509,20.0002098083496,88461.65625,1.88442596672138,0.000176218006026344
3844454473.568,20.0001106262207,88763.25,1.88800485129258,0.000189905653785298
3844454493.5285,19.9994468688965,89062.19140625,1.89137253417888,0.000202206433455201
3844454513.5175,20.0002746582031,89362.35546875,1.89453024739312,0.00018981279533789
3844454533.5,19.9998512268066,89661.69921875,1.89807682351845,0.000195632073319003
3844454553.469,19.9998121261597,89961.55078125,1.90156896794361,0.000177283410527218
3844454573.4425,19.9990539550781,90260.73828125,1.90494199773292,0.000193386907447425
3844454593.5215,20.0001525878906,90562.62109375,1.90797278334767,0.000185761890471389
3844454613.3745,20.0006284713745,90860.484375,1.9114617652617,0.000203698999839411
3844454633.536,20.000337600708,91162.98828125,1.91449241769866,0.000188419610261608
3844454653.38,20.0001392364502,91460.984375,1.91773754831224,0.000184226392137711
3844454673.441,20.0006704330444,91762.62890625,1.92133576263696,0.000198681795779774
3844454693.418,20.0001916885376,92062.375,1.92412387259151,0.000208082596793122
3844454713.3405,20.0001459121704,92361.61328125,1.92744033574936,0.00019983231684244
3844454733.3095,20.0000314712524,92660.69921875,1.93102548270348,0.000207789895434458
3844454753.3295,20.0000104904175,92960.640625,1.9339864102197,0.000189059784519725
3844454773.301,19.9997253417969,93260.08984375,1.93731387728719,0.000190401753316438
3844454793.3785,20.0002460479736,93561.5390625,1.94026089268409,0.000189368312309954
3844454813.371,19.9998588562012,93863.23828125,1.94319053084287,0.000190652880948169
3844454833.3205,19.9999618530273,94161.59765625,1.9464103620453,0.000197954412360555
3844454853.3045,19.999979019165,94461.6640625,1.94961013661118,0.000186801740206688
3844454873.233,19.999568939209,94761.00390625,1.95281000250672,0.000197273304152846
3844454893.236,20.0001010894775,95060.76171875,1.95536341403045,0.000185675515300454
3844454913.2145,20.0002202987671,95359.62890625,1.95854886354844,0.000162896346004505
3844454933.1455,19.9992904663086,95658.6953125,1.96143476742987,0.000186523662788358
3844454953.1285,19.9998607635498,95958.86328125,1.96493803017275,0.000190184147625392
3844454973.263,20.0000352859497,96259.9609375,1.96771595856028,0.000164145204173442
3844454993.3645,19.9999923706055,96561.6953125,1.97027578483668,0.000197173435743582
3844455013.08,19.9998054504395,96857.98046875,1.9733219527403,0.000188666480747541
3844455033.076,20.0000782012939,97158.34375,1.97616572403141,0.00019588782587075
3844455053.1275,20.0007848739624,97459.3046875,1.97954752522173,0.000190534901739428
3844455073.164,19.9999895095825,97759.12890625,1.98205085930767,0.000194731057567724
3844455093.0775,20.0002508163452,98058.43359375,1.98521904581833,0.000197965542250933
3844455113.0555,20.0000295639038,98358,1.98805819581106,0.000179481574046211
3844455133.0635,20.0000352859497,98658.3125,1.99089907788225,0.000175667155086366
3844455152.978,20.0000219345093,98958.47265625,1.99368096679159,0.000195705870144548
3844455173.033,20.0002737045288,99258.84375,1.99627160194801,0.00017488460836901
3844455193.06,20.0009078979492,99559.0390625,1.99898454739139,0.000178394401588182
3844455213.106,20.0001373291016,99860.12109375,2.00202341565007,0.000168309723260685
3844455232.942,19.9992723464966,100157.8671875,2.0047264889229,0.00018781255350238
3844455252.9375,19.9999122619629,100458.1328125,2.0073475255768,0.000192530650897377
3844455272.986,19.9994773864746,100757.9921875,2.01048175517602,0.000191058104395245
3844455292.893,20.0003252029419,101057.453125,2.0126713375036,0.000198040837681409
3844455312.8865,20.000678062439,101356.38671875,2.0151963424343,0.000183982708334757
3844455332.9555,20.0006694793701,101657.3125,2.01803539118633,0.000178565893425248
3844455352.9035,20.0000228881836,101957.18359375,2.02059802495775,0.000206911282252752
3844455372.9745,20.0003900527954,102257.80078125,2.02361287493328,0.000194309721983367
3844455392.812,19.9997663497925,102555.58984375,2.0261215497035,0.000207867851132773
3844455412.9385,20.0000267028809,102857.4296875,2.02902563666079,0.000176595958763956
3844455432.937,20.0000715255737,103157.04296875,2.03098858518909,0.00019824620123671
3844455452.786,20.0002107620239,103454.06640625,2.03390598686462,0.000182730017624488
3844455472.9075,20.0000705718994,103756.7265625,2.03630636052451,0.000204878339642476
3844455492.7455,19.9996509552002,104054.53515625,2.03878062958066,0.000189005068550086
3844455512.87,20.0002479553223,104355.90625,2.04189158143067,0.000173924951963475
3844455532.703,20.0005388259888,104653.74609375,2.04410934737773,0.000185646407503751
3844455552.841,20.000171661377,104956.40625,2.04672420657073,0.000209346593787126
3844455572.746,20.0003614425659,105254.98046875,2.04891275735949,0.000203277999055823
3844455592.8,20.000039100647,105555.60546875,2.05153791281577,0.000195380161395879
3844455612.669,19.9997806549072,105854.3046875,2.05425383660337,0.000212473676844074
3844455632.805,19.9999723434448,106155.32421875,2.05647707275905,0.000195333785486695
3844455652.7355,19.9999313354492,106455.4609375,2.0587432746091,0.000188959698698176
3844455672.7325,19.9998769760132,106754.8984375,2.06163036142582,0.000196646645158278
3844455692.5905,20.0000848770142,107054.32421875,2.06354593206787,0.00022012718955778
3844455712.6135,20.0000686645508,107354.21484375,2.06604656290589,0.000204969568327028
3844455732.5875,19.9996366500854,107653.67578125,2.06803185755762,0.000196382262613077
3844455752.6155,19.9993743896484,107954.26171875,2.07048941946799,0.000186506649165713
3844455772.5495,20.0004014968872,108252.29296875,2.07271613666037,0.00018853709511706
3844455792.586,20.0002994537354,108552.875,2.07556621320089,0.000187566778558813
3844455812.576,19.9997291564941,108852.89453125,2.07765813150293,0.000203102473889028
3844455832.6275,19.9999141693115,109153.53515625,2.08031340041112,0.000225106123386603
3844455852.5645,20.0001535415649,109452.6953125,2.08257996084266,0.000203002109015745
3844455872.4485,20.0001125335693,109751.078125,2.08488601421236,0.000205139775293302
3844455892.613,20.0007801055908,110053.47265625,2.08692677617115,0.000164723057582464
3844455912.5275,19.999885559082,110351.98046875,2.08911701152451,0.000194958738241405
3844455932.507,20.000825881958,110652.078125,2.09144122222906,0.000205626014511923
3844455952.478,20.0003566741943,110951.07421875,2.0934513864065,0.00017556868308541
3844455972.4355,19.9995460510254,111250.41015625,2.09567094914554,0.000183204474647281
3844455992.381,20.0006504058838,111549.99609375,2.0981762378729,0.000221124890931223
3844456012.349,19.9993705749512,111849.46875,2.0999466488146,0.000182888684512914
3844456032.4005,20.0004816055298,112150.42578125,2.10230299141168,0.000196378596510838
3844456052.34,19.9987564086914,112450.33203125,2.10472532292787,0.000175944890853486
3844456072.351,20.0006132125854,112750.140625,2.10625772310973,0.000200119856644039
3844456092.435,20.0001926422119,113051.73046875,2.10868067152245,0.00021076614386032
3844456112.355,20.0013456344604,113350.9453125,2.11078302122766,0.000189939397917356
3844456132.2615,20.0004329681396,113649.51953125,2.11300323796369,0.000185294142296864
3844456152.355,20.0006990432739,113951.08984375,2.11469103231748,0.000208058895091006
3844456172.246,19.9990854263306,114249.16796875,2.11708044391378,0.000196856429089873
3844456192.365,19.9989290237427,114551.2578125,2.11925770329039,0.000211068879253536
3844456212.252,20.0007944107056,114850.6796875,2.12110714752438,0.000180408086985483
3844456232.351,19.9984369277954,115151.97265625,2.12327822900059,0.00018918009655273
3844456252.4045,19.9993486404419,115453.671875,2.12520364050639,0.000206209873658277
3844456272.273,19.9991445541382,115751.2421875,2.12700613463542,0.000186964838239319
3844456292.1635,20.0019550323486,116048.51171875,2.12906067505122,0.000199159071008782
3844456312.236,20.000394821167,116349.64453125,2.1310300308049,0.00019783003373517
3844456332.209,19.9992008209229,116648.98046875,2.13329105735521,0.000191362650336106
3844456352.2335,20.0040731430054,116949.52734375,2.13488714394677,0.000179376730648423
3844456372.1675,19.9988632202148,117247.99609375,2.13691613883275,0.000208614777457441
3844456392.1005,19.9957666397095,117547.35546875,2.13928338516517,0.000185405033358968
3844456412.199,20.0016899108887,117848.99609375,2.14033618155592,0.000164604753786898
3844456432.044,20.0010013580322,118146.875,2.14315571784557,0.000186477172516378
3844456452.12,20.0014047622681,118447.58984375,2.14457560390458,0.00020358026597084
3844456472.041,20.0037651062012,118746.76953125,2.14609360192212,0.000185877242835223
3844456492.0165,20.0016937255859,119046.69921875,2.14889540332992,0.000185071844280712
3844456512.024,20.0003747940063,119347.06640625,2.1502439735237,0.000174707682394165
3844456532.092,19.9977979660034,119647.82421875,2.15288936157933,0.000185492324266486
3844456552.239,20.0021390914917,119950.671875,2.15426375604213,0.000203197229710063
3844456572.0925,19.9984121322632,120248.5546875,2.15565999553464,0.000191077650877527
3844456591.9675,19.9990329742432,120547.33203125,2.15832117209738,0.000180494827305102
3844456611.911,20.002742767334,120845.78125,2.15990589464913,0.000161120013146224
3844456631.9185,20.0000772476196,121146.421875,2.16184113146837,0.000196626618410568
3844456651.8785,19.9992437362671,121446.42578125,2.1632822878558,0.00020893601904724
3844456672.075,19.9990663528442,121749.59375,2.16526949185266,0.000184686062867761
3844456691.867,19.9992008209229,122046.43359375,2.16728308688616,0.000205623884486126
3844456711.9015,20.0007104873657,122346.53125,2.16889895608313,0.000180414966778103
3844456731.9475,20.0000553131104,122647.37109375,2.17026852859095,0.000180533584497929
3844456751.8185,19.9993658065796,122945.04296875,2.17238569071364,0.000223031082161668
3844456771.8335,19.9960308074951,123245.921875,2.17436314272846,0.000196539146843681
3844456791.7915,19.9986743927002,123544.91015625,2.17593812912658,0.000194846957415208
3844456811.871,19.99889087677,123846.01953125,2.17737136025208,0.00018985812854033
3844456831.887,19.9982271194458,124145.53515625,2.17972942706131,0.000204262804147103
3844456851.7295,19.9986734390259,124443.30078125,2.18135427585612,0.000191397512885806
3844456871.7975,19.9994211196899,124743.765625,2.18289685414421,0.000189545617793779
3844456891.788,19.9993648529053,125043.65234375,2.18431640968114,0.000214253810993448
3844456911.7715,19.9992122650146,125343.74609375,2.18587435268472,0.000201854223752836
3844456931.7925,20.0000810623169,125643.87890625,2.18778797125012,0.000205689408785856
3844456951.719,19.9993906021118,125942.62109375,2.18920408484874,0.000196702879682622
3844456971.671,20.0004377365112,126242.03515625,2.19137655393604,0.000200681710351383
3844456991.7675,20.0003318786621,126543.36328125,2.19264035151467,0.000205564871744109
3844457011.7185,19.9994926452637,126843.28125,2.19428815676328,0.000204011128138947
3844457031.6225,20.0002412796021,127142.36328125,2.19583315664335,0.000206785557322286
3844457051.6945,19.9996585845947,127443.859375,2.19780514525042,0.000183000409133592
3844457071.581,19.9997529983521,127741.9140625,2.19918829154424,0.00021341416842121
3844457091.6135,20.0006446838379,128042.85546875,2.20104419084599,0.00020302647095041
3844457111.7415,19.9999723434448,128344.640625,2.20212192897884,0.00019519945798801
3844457131.5825,20.0001707077026,128642.3515625,2.2039262867169,0.0002245172329433
3844457151.503,20.0008497238159,128941.46484375,2.20520916558026,0.000194174470553776
3844457171.506,20.0002784729004,129240.54296875,2.20711655713535,0.000197801094056618
3844457191.4665,20.000280380249,129540.7109375,2.20837932159958,0.000229649292014102
3844457211.499,19.9995250701904,129841.80859375,2.20992189145191,0.0002178640319494
3844457231.5395,20.0007848739624,130142.609375,2.21154766340196,0.000208706716990091
3844457251.4575,20.0010251998901,130441.18359375,2.21303851403368,0.000184491098048526
3844457271.467,20.0006818771362,130741.33984375,2.21417186315571,0.000185823051567266
3844457291.4025,19.997857093811,131039.9296875,2.21588494543813,0.000223331949587069
3844457311.559,19.9991397857666,131342.7109375,2.21762427123194,0.000191372474537758
3844457331.4045,19.9999771118164,131639.890625,2.2189256702414,0.00018761296580787
3844457351.446,20.0030689239502,131940.4140625,2.22023256415437,0.000197808216723209
3844457371.52,20.0016279220581,132241.1328125,2.2215707583346,0.000199699127053839
3844457391.3315,20.0018062591553,132538.65625,2.22332751279895,0.000194948634966022
3844457411.395,19.9984712600708,132838.4609375,2.22487432585375,0.00020355893716462
3844457431.4665,20.0009002685547,133140.6484375,2.22588056257081,0.000190929137852313
3844457451.421,20.0016860961914,133439.3671875,2.22734258588672,0.000190954605713349
3844457471.288,19.9973335266113,133737.71875,2.22892134186114,0.000227421714611659
3844457491.2805,19.9982233047485,134037.65625,2.23083776972702,0.000198156258000152
3844457511.2615,20.0005359649658,134337.4453125,2.23206598068958,0.000203247984084133
3844457531.4115,19.9973449707031,134639.7734375,2.23328411831667,0.000206908307208015
3844457551.257,19.9988861083984,134937.0078125,2.23451979067515,0.000227304808044205
3844457571.297,19.9982233047485,135237.765625,2.23643889832753,0.00020122071345802
3844457591.311,19.9985694885254,135539.7890625,2.23781450550872,0.000218727922684438
3844457611.2845,19.9991035461426,135839.1171875,2.23882429433697,0.000219913430030438
3844457631.1495,19.9993705749512,136137.03125,2.2407535091005,0.000208546173678497
3844457651.2465,20.0006866455078,136438.75,2.24139538689389,0.000236367445281978
3844457671.1535,20.0007400512695,136738.0078125,2.24300453211248,0.000248975042790152
3844457691.159,20.0020294189453,137037.765625,2.24419116321698,0.000223121180036556
3844457711.2155,20.0014638900757,137338.5859375,2.24552670321503,0.000203066129316419
3844457731.0895,19.9979944229126,137636.671875,2.24686265382614,0.000228278346156212
3844457751.1095,20.0024290084839,137937.6171875,2.24817923770855,0.000183542220364005
3844457771.0545,20.0016374588013,138237.1484375,2.249468735819,0.000217795434055004
3844457791.2275,19.9995155334473,138539.375,2.25064530931853,0.00021368100479287
3844457811.0975,19.9988327026367,138838.1953125,2.25241681531653,0.000208140487619037
3844457831.21,19.997802734375,139139.7890625,2.25392926590478,0.000199572657741757
3844457850.9995,19.9989948272705,139435.9296875,2.25480281422856,0.000205401498048632
3844457870.971,19.9988126754761,139736.6328125,2.25644385657232,0.000196894668183327
3844457905.953,19.9991340637207,140000.2890625,2.25763734158614,0.000201706028123888